<?xml version="1.0" encoding="UTF-8"?>
<testsuite name="Factorial Test"
           tests="91"
           failures="89"
           errors="0"
           skipped="0"
           time="0.459">
    <properties></properties>

            <testcase
                name="testFactorial"
                time="0.001"
                classname="FacturialTest">

            <failure type="java.lang.AssertionError" message="expected [4] but found [2]">
                <![CDATA[java.lang.AssertionError: expected [4] but found [2]
                org.testng.Assert.fail(Assert.java:110)org.testng.Assert.failNotEquals(Assert.java:1577)org.testng.Assert.assertEqualsImpl(Assert.java:149)org.testng.Assert.assertEquals(Assert.java:131)org.testng.Assert.assertEquals(Assert.java:1418)org.testng.Assert.assertEquals(Assert.java:1382)org.testng.Assert.assertEquals(Assert.java:1428)FacturialTest.testFactorial(FacturialTest.java:110)java.base/jdk.internal.reflect.DirectMethodHandleAccessor.invoke(DirectMethodHandleAccessor.java:104)java.base/java.lang.reflect.Method.invoke(Method.java:578)org.testng.internal.invokers.MethodInvocationHelper.invokeMethod(MethodInvocationHelper.java:139)org.testng.internal.invokers.TestInvoker.invokeMethod(TestInvoker.java:677)org.testng.internal.invokers.TestInvoker.invokeTestMethod(TestInvoker.java:221)org.testng.internal.invokers.MethodRunner.runInSequence(MethodRunner.java:50)org.testng.internal.invokers.TestInvoker$MethodInvocationAgent.invoke(TestInvoker.java:969)org.testng.internal.invokers.TestInvoker.invokeTestMethods(TestInvoker.java:194)org.testng.internal.invokers.TestMethodWorker.invokeTestMethods(TestMethodWorker.java:148)org.testng.internal.invokers.TestMethodWorker.run(TestMethodWorker.java:128)java.base/java.util.ArrayList.forEach(ArrayList.java:1511)org.testng.TestRunner.privateRun(TestRunner.java:829)org.testng.TestRunner.run(TestRunner.java:602)org.testng.SuiteRunner.runTest(SuiteRunner.java:437)org.testng.SuiteRunner$SuiteWorker.run(SuiteRunner.java:475)org.testng.internal.thread.ThreadUtil.lambda$execute$0(ThreadUtil.java:58)java.base/java.util.concurrent.FutureTask.run(FutureTask.java:317)java.base/java.util.concurrent.ThreadPoolExecutor.runWorker(ThreadPoolExecutor.java:1144)java.base/java.util.concurrent.ThreadPoolExecutor$Worker.run(ThreadPoolExecutor.java:642)java.base/java.lang.Thread.run(Thread.java:1623)
]]>
            </failure>
    </testcase>
            <testcase
                name="testFactorial"
                time="0.001"
                classname="FacturialTest">

            <failure type="java.lang.AssertionError" message="expected [4] but found [2]">
                <![CDATA[java.lang.AssertionError: expected [4] but found [2]
                org.testng.Assert.fail(Assert.java:110)org.testng.Assert.failNotEquals(Assert.java:1577)org.testng.Assert.assertEqualsImpl(Assert.java:149)org.testng.Assert.assertEquals(Assert.java:131)org.testng.Assert.assertEquals(Assert.java:1418)org.testng.Assert.assertEquals(Assert.java:1382)org.testng.Assert.assertEquals(Assert.java:1428)FacturialTest.testFactorial(FacturialTest.java:110)java.base/jdk.internal.reflect.DirectMethodHandleAccessor.invoke(DirectMethodHandleAccessor.java:104)java.base/java.lang.reflect.Method.invoke(Method.java:578)org.testng.internal.invokers.MethodInvocationHelper.invokeMethod(MethodInvocationHelper.java:139)org.testng.internal.invokers.TestInvoker.invokeMethod(TestInvoker.java:677)org.testng.internal.invokers.TestInvoker.invokeTestMethod(TestInvoker.java:221)org.testng.internal.invokers.MethodRunner.runInSequence(MethodRunner.java:50)org.testng.internal.invokers.TestInvoker$MethodInvocationAgent.invoke(TestInvoker.java:969)org.testng.internal.invokers.TestInvoker.invokeTestMethods(TestInvoker.java:194)org.testng.internal.invokers.TestMethodWorker.invokeTestMethods(TestMethodWorker.java:148)org.testng.internal.invokers.TestMethodWorker.run(TestMethodWorker.java:128)java.base/java.util.ArrayList.forEach(ArrayList.java:1511)org.testng.TestRunner.privateRun(TestRunner.java:829)org.testng.TestRunner.run(TestRunner.java:602)org.testng.SuiteRunner.runTest(SuiteRunner.java:437)org.testng.SuiteRunner$SuiteWorker.run(SuiteRunner.java:475)org.testng.internal.thread.ThreadUtil.lambda$execute$0(ThreadUtil.java:58)java.base/java.util.concurrent.FutureTask.run(FutureTask.java:317)java.base/java.util.concurrent.ThreadPoolExecutor.runWorker(ThreadPoolExecutor.java:1144)java.base/java.util.concurrent.ThreadPoolExecutor$Worker.run(ThreadPoolExecutor.java:642)java.base/java.lang.Thread.run(Thread.java:1623)
]]>
            </failure>
    </testcase>
            <testcase
                name="testFactorial"
                time="0.002"
                classname="FacturialTest">

            <failure type="java.lang.AssertionError" message="expected [4] but found [2]">
                <![CDATA[java.lang.AssertionError: expected [4] but found [2]
                org.testng.Assert.fail(Assert.java:110)org.testng.Assert.failNotEquals(Assert.java:1577)org.testng.Assert.assertEqualsImpl(Assert.java:149)org.testng.Assert.assertEquals(Assert.java:131)org.testng.Assert.assertEquals(Assert.java:1418)org.testng.Assert.assertEquals(Assert.java:1382)org.testng.Assert.assertEquals(Assert.java:1428)FacturialTest.testFactorial(FacturialTest.java:110)java.base/jdk.internal.reflect.DirectMethodHandleAccessor.invoke(DirectMethodHandleAccessor.java:104)java.base/java.lang.reflect.Method.invoke(Method.java:578)org.testng.internal.invokers.MethodInvocationHelper.invokeMethod(MethodInvocationHelper.java:139)org.testng.internal.invokers.TestInvoker.invokeMethod(TestInvoker.java:677)org.testng.internal.invokers.TestInvoker.invokeTestMethod(TestInvoker.java:221)org.testng.internal.invokers.MethodRunner.runInSequence(MethodRunner.java:50)org.testng.internal.invokers.TestInvoker$MethodInvocationAgent.invoke(TestInvoker.java:969)org.testng.internal.invokers.TestInvoker.invokeTestMethods(TestInvoker.java:194)org.testng.internal.invokers.TestMethodWorker.invokeTestMethods(TestMethodWorker.java:148)org.testng.internal.invokers.TestMethodWorker.run(TestMethodWorker.java:128)java.base/java.util.ArrayList.forEach(ArrayList.java:1511)org.testng.TestRunner.privateRun(TestRunner.java:829)org.testng.TestRunner.run(TestRunner.java:602)org.testng.SuiteRunner.runTest(SuiteRunner.java:437)org.testng.SuiteRunner$SuiteWorker.run(SuiteRunner.java:475)org.testng.internal.thread.ThreadUtil.lambda$execute$0(ThreadUtil.java:58)java.base/java.util.concurrent.FutureTask.run(FutureTask.java:317)java.base/java.util.concurrent.ThreadPoolExecutor.runWorker(ThreadPoolExecutor.java:1144)java.base/java.util.concurrent.ThreadPoolExecutor$Worker.run(ThreadPoolExecutor.java:642)java.base/java.lang.Thread.run(Thread.java:1623)
]]>
            </failure>
    </testcase>
            <testcase
                name="testFactorial"
                time="0.037"
                classname="FacturialTest">

            <failure type="java.lang.AssertionError" message="expected [4] but found [2]">
                <![CDATA[java.lang.AssertionError: expected [4] but found [2]
                org.testng.Assert.fail(Assert.java:110)org.testng.Assert.failNotEquals(Assert.java:1577)org.testng.Assert.assertEqualsImpl(Assert.java:149)org.testng.Assert.assertEquals(Assert.java:131)org.testng.Assert.assertEquals(Assert.java:1418)org.testng.Assert.assertEquals(Assert.java:1382)org.testng.Assert.assertEquals(Assert.java:1428)FacturialTest.testFactorial(FacturialTest.java:110)java.base/jdk.internal.reflect.DirectMethodHandleAccessor.invoke(DirectMethodHandleAccessor.java:104)java.base/java.lang.reflect.Method.invoke(Method.java:578)org.testng.internal.invokers.MethodInvocationHelper.invokeMethod(MethodInvocationHelper.java:139)org.testng.internal.invokers.TestInvoker.invokeMethod(TestInvoker.java:677)org.testng.internal.invokers.TestInvoker.invokeTestMethod(TestInvoker.java:221)org.testng.internal.invokers.MethodRunner.runInSequence(MethodRunner.java:50)org.testng.internal.invokers.TestInvoker$MethodInvocationAgent.invoke(TestInvoker.java:969)org.testng.internal.invokers.TestInvoker.invokeTestMethods(TestInvoker.java:194)org.testng.internal.invokers.TestMethodWorker.invokeTestMethods(TestMethodWorker.java:148)org.testng.internal.invokers.TestMethodWorker.run(TestMethodWorker.java:128)java.base/java.util.ArrayList.forEach(ArrayList.java:1511)org.testng.TestRunner.privateRun(TestRunner.java:829)org.testng.TestRunner.run(TestRunner.java:602)org.testng.SuiteRunner.runTest(SuiteRunner.java:437)org.testng.SuiteRunner$SuiteWorker.run(SuiteRunner.java:475)org.testng.internal.thread.ThreadUtil.lambda$execute$0(ThreadUtil.java:58)java.base/java.util.concurrent.FutureTask.run(FutureTask.java:317)java.base/java.util.concurrent.ThreadPoolExecutor.runWorker(ThreadPoolExecutor.java:1144)java.base/java.util.concurrent.ThreadPoolExecutor$Worker.run(ThreadPoolExecutor.java:642)java.base/java.lang.Thread.run(Thread.java:1623)
]]>
            </failure>
    </testcase>
            <testcase
                name="testFactorial"
                time="0.000"
                classname="FacturialTest">

            <failure type="java.lang.AssertionError" message="expected [4] but found [2]">
                <![CDATA[java.lang.AssertionError: expected [4] but found [2]
                org.testng.Assert.fail(Assert.java:110)org.testng.Assert.failNotEquals(Assert.java:1577)org.testng.Assert.assertEqualsImpl(Assert.java:149)org.testng.Assert.assertEquals(Assert.java:131)org.testng.Assert.assertEquals(Assert.java:1418)org.testng.Assert.assertEquals(Assert.java:1382)org.testng.Assert.assertEquals(Assert.java:1428)FacturialTest.testFactorial(FacturialTest.java:110)java.base/jdk.internal.reflect.DirectMethodHandleAccessor.invoke(DirectMethodHandleAccessor.java:104)java.base/java.lang.reflect.Method.invoke(Method.java:578)org.testng.internal.invokers.MethodInvocationHelper.invokeMethod(MethodInvocationHelper.java:139)org.testng.internal.invokers.TestInvoker.invokeMethod(TestInvoker.java:677)org.testng.internal.invokers.TestInvoker.invokeTestMethod(TestInvoker.java:221)org.testng.internal.invokers.MethodRunner.runInSequence(MethodRunner.java:50)org.testng.internal.invokers.TestInvoker$MethodInvocationAgent.invoke(TestInvoker.java:969)org.testng.internal.invokers.TestInvoker.invokeTestMethods(TestInvoker.java:194)org.testng.internal.invokers.TestMethodWorker.invokeTestMethods(TestMethodWorker.java:148)org.testng.internal.invokers.TestMethodWorker.run(TestMethodWorker.java:128)java.base/java.util.ArrayList.forEach(ArrayList.java:1511)org.testng.TestRunner.privateRun(TestRunner.java:829)org.testng.TestRunner.run(TestRunner.java:602)org.testng.SuiteRunner.runTest(SuiteRunner.java:437)org.testng.SuiteRunner$SuiteWorker.run(SuiteRunner.java:475)org.testng.internal.thread.ThreadUtil.lambda$execute$0(ThreadUtil.java:58)java.base/java.util.concurrent.FutureTask.run(FutureTask.java:317)java.base/java.util.concurrent.ThreadPoolExecutor.runWorker(ThreadPoolExecutor.java:1144)java.base/java.util.concurrent.ThreadPoolExecutor$Worker.run(ThreadPoolExecutor.java:642)java.base/java.lang.Thread.run(Thread.java:1623)
]]>
            </failure>
    </testcase>
            <testcase
                name="testFactorial"
                time="0.001"
                classname="FacturialTest">

            <failure type="java.lang.AssertionError" message="expected [4] but found [2]">
                <![CDATA[java.lang.AssertionError: expected [4] but found [2]
                org.testng.Assert.fail(Assert.java:110)org.testng.Assert.failNotEquals(Assert.java:1577)org.testng.Assert.assertEqualsImpl(Assert.java:149)org.testng.Assert.assertEquals(Assert.java:131)org.testng.Assert.assertEquals(Assert.java:1418)org.testng.Assert.assertEquals(Assert.java:1382)org.testng.Assert.assertEquals(Assert.java:1428)FacturialTest.testFactorial(FacturialTest.java:110)java.base/jdk.internal.reflect.DirectMethodHandleAccessor.invoke(DirectMethodHandleAccessor.java:104)java.base/java.lang.reflect.Method.invoke(Method.java:578)org.testng.internal.invokers.MethodInvocationHelper.invokeMethod(MethodInvocationHelper.java:139)org.testng.internal.invokers.TestInvoker.invokeMethod(TestInvoker.java:677)org.testng.internal.invokers.TestInvoker.invokeTestMethod(TestInvoker.java:221)org.testng.internal.invokers.MethodRunner.runInSequence(MethodRunner.java:50)org.testng.internal.invokers.TestInvoker$MethodInvocationAgent.invoke(TestInvoker.java:969)org.testng.internal.invokers.TestInvoker.invokeTestMethods(TestInvoker.java:194)org.testng.internal.invokers.TestMethodWorker.invokeTestMethods(TestMethodWorker.java:148)org.testng.internal.invokers.TestMethodWorker.run(TestMethodWorker.java:128)java.base/java.util.ArrayList.forEach(ArrayList.java:1511)org.testng.TestRunner.privateRun(TestRunner.java:829)org.testng.TestRunner.run(TestRunner.java:602)org.testng.SuiteRunner.runTest(SuiteRunner.java:437)org.testng.SuiteRunner$SuiteWorker.run(SuiteRunner.java:475)org.testng.internal.thread.ThreadUtil.lambda$execute$0(ThreadUtil.java:58)java.base/java.util.concurrent.FutureTask.run(FutureTask.java:317)java.base/java.util.concurrent.ThreadPoolExecutor.runWorker(ThreadPoolExecutor.java:1144)java.base/java.util.concurrent.ThreadPoolExecutor$Worker.run(ThreadPoolExecutor.java:642)java.base/java.lang.Thread.run(Thread.java:1623)
]]>
            </failure>
    </testcase>
            <testcase
                name="testFactorial"
                time="0.001"
                classname="FacturialTest">

            <failure type="java.lang.AssertionError" message="expected [4] but found [2]">
                <![CDATA[java.lang.AssertionError: expected [4] but found [2]
                org.testng.Assert.fail(Assert.java:110)org.testng.Assert.failNotEquals(Assert.java:1577)org.testng.Assert.assertEqualsImpl(Assert.java:149)org.testng.Assert.assertEquals(Assert.java:131)org.testng.Assert.assertEquals(Assert.java:1418)org.testng.Assert.assertEquals(Assert.java:1382)org.testng.Assert.assertEquals(Assert.java:1428)FacturialTest.testFactorial(FacturialTest.java:110)java.base/jdk.internal.reflect.DirectMethodHandleAccessor.invoke(DirectMethodHandleAccessor.java:104)java.base/java.lang.reflect.Method.invoke(Method.java:578)org.testng.internal.invokers.MethodInvocationHelper.invokeMethod(MethodInvocationHelper.java:139)org.testng.internal.invokers.TestInvoker.invokeMethod(TestInvoker.java:677)org.testng.internal.invokers.TestInvoker.invokeTestMethod(TestInvoker.java:221)org.testng.internal.invokers.MethodRunner.runInSequence(MethodRunner.java:50)org.testng.internal.invokers.TestInvoker$MethodInvocationAgent.invoke(TestInvoker.java:969)org.testng.internal.invokers.TestInvoker.invokeTestMethods(TestInvoker.java:194)org.testng.internal.invokers.TestMethodWorker.invokeTestMethods(TestMethodWorker.java:148)org.testng.internal.invokers.TestMethodWorker.run(TestMethodWorker.java:128)java.base/java.util.ArrayList.forEach(ArrayList.java:1511)org.testng.TestRunner.privateRun(TestRunner.java:829)org.testng.TestRunner.run(TestRunner.java:602)org.testng.SuiteRunner.runTest(SuiteRunner.java:437)org.testng.SuiteRunner$SuiteWorker.run(SuiteRunner.java:475)org.testng.internal.thread.ThreadUtil.lambda$execute$0(ThreadUtil.java:58)java.base/java.util.concurrent.FutureTask.run(FutureTask.java:317)java.base/java.util.concurrent.ThreadPoolExecutor.runWorker(ThreadPoolExecutor.java:1144)java.base/java.util.concurrent.ThreadPoolExecutor$Worker.run(ThreadPoolExecutor.java:642)java.base/java.lang.Thread.run(Thread.java:1623)
]]>
            </failure>
    </testcase>
            <testcase
                name="testFactorial"
                time="0.002"
                classname="FacturialTest">

            <failure type="java.lang.AssertionError" message="expected [4] but found [2]">
                <![CDATA[java.lang.AssertionError: expected [4] but found [2]
                org.testng.Assert.fail(Assert.java:110)org.testng.Assert.failNotEquals(Assert.java:1577)org.testng.Assert.assertEqualsImpl(Assert.java:149)org.testng.Assert.assertEquals(Assert.java:131)org.testng.Assert.assertEquals(Assert.java:1418)org.testng.Assert.assertEquals(Assert.java:1382)org.testng.Assert.assertEquals(Assert.java:1428)FacturialTest.testFactorial(FacturialTest.java:110)java.base/jdk.internal.reflect.DirectMethodHandleAccessor.invoke(DirectMethodHandleAccessor.java:104)java.base/java.lang.reflect.Method.invoke(Method.java:578)org.testng.internal.invokers.MethodInvocationHelper.invokeMethod(MethodInvocationHelper.java:139)org.testng.internal.invokers.TestInvoker.invokeMethod(TestInvoker.java:677)org.testng.internal.invokers.TestInvoker.invokeTestMethod(TestInvoker.java:221)org.testng.internal.invokers.MethodRunner.runInSequence(MethodRunner.java:50)org.testng.internal.invokers.TestInvoker$MethodInvocationAgent.invoke(TestInvoker.java:969)org.testng.internal.invokers.TestInvoker.invokeTestMethods(TestInvoker.java:194)org.testng.internal.invokers.TestMethodWorker.invokeTestMethods(TestMethodWorker.java:148)org.testng.internal.invokers.TestMethodWorker.run(TestMethodWorker.java:128)java.base/java.util.ArrayList.forEach(ArrayList.java:1511)org.testng.TestRunner.privateRun(TestRunner.java:829)org.testng.TestRunner.run(TestRunner.java:602)org.testng.SuiteRunner.runTest(SuiteRunner.java:437)org.testng.SuiteRunner$SuiteWorker.run(SuiteRunner.java:475)org.testng.internal.thread.ThreadUtil.lambda$execute$0(ThreadUtil.java:58)java.base/java.util.concurrent.FutureTask.run(FutureTask.java:317)java.base/java.util.concurrent.ThreadPoolExecutor.runWorker(ThreadPoolExecutor.java:1144)java.base/java.util.concurrent.ThreadPoolExecutor$Worker.run(ThreadPoolExecutor.java:642)java.base/java.lang.Thread.run(Thread.java:1623)
]]>
            </failure>
    </testcase>
            <testcase
                name="testFactorial"
                time="0.001"
                classname="FacturialTest">

            <failure type="java.lang.AssertionError" message="expected [4] but found [2]">
                <![CDATA[java.lang.AssertionError: expected [4] but found [2]
                org.testng.Assert.fail(Assert.java:110)org.testng.Assert.failNotEquals(Assert.java:1577)org.testng.Assert.assertEqualsImpl(Assert.java:149)org.testng.Assert.assertEquals(Assert.java:131)org.testng.Assert.assertEquals(Assert.java:1418)org.testng.Assert.assertEquals(Assert.java:1382)org.testng.Assert.assertEquals(Assert.java:1428)FacturialTest.testFactorial(FacturialTest.java:110)java.base/jdk.internal.reflect.DirectMethodHandleAccessor.invoke(DirectMethodHandleAccessor.java:104)java.base/java.lang.reflect.Method.invoke(Method.java:578)org.testng.internal.invokers.MethodInvocationHelper.invokeMethod(MethodInvocationHelper.java:139)org.testng.internal.invokers.TestInvoker.invokeMethod(TestInvoker.java:677)org.testng.internal.invokers.TestInvoker.invokeTestMethod(TestInvoker.java:221)org.testng.internal.invokers.MethodRunner.runInSequence(MethodRunner.java:50)org.testng.internal.invokers.TestInvoker$MethodInvocationAgent.invoke(TestInvoker.java:969)org.testng.internal.invokers.TestInvoker.invokeTestMethods(TestInvoker.java:194)org.testng.internal.invokers.TestMethodWorker.invokeTestMethods(TestMethodWorker.java:148)org.testng.internal.invokers.TestMethodWorker.run(TestMethodWorker.java:128)java.base/java.util.ArrayList.forEach(ArrayList.java:1511)org.testng.TestRunner.privateRun(TestRunner.java:829)org.testng.TestRunner.run(TestRunner.java:602)org.testng.SuiteRunner.runTest(SuiteRunner.java:437)org.testng.SuiteRunner$SuiteWorker.run(SuiteRunner.java:475)org.testng.internal.thread.ThreadUtil.lambda$execute$0(ThreadUtil.java:58)java.base/java.util.concurrent.FutureTask.run(FutureTask.java:317)java.base/java.util.concurrent.ThreadPoolExecutor.runWorker(ThreadPoolExecutor.java:1144)java.base/java.util.concurrent.ThreadPoolExecutor$Worker.run(ThreadPoolExecutor.java:642)java.base/java.lang.Thread.run(Thread.java:1623)
]]>
            </failure>
    </testcase>
            <testcase
                name="testFactorial"
                time="0.001"
                classname="FacturialTest">

            <failure type="java.lang.AssertionError" message="expected [4] but found [2]">
                <![CDATA[java.lang.AssertionError: expected [4] but found [2]
                org.testng.Assert.fail(Assert.java:110)org.testng.Assert.failNotEquals(Assert.java:1577)org.testng.Assert.assertEqualsImpl(Assert.java:149)org.testng.Assert.assertEquals(Assert.java:131)org.testng.Assert.assertEquals(Assert.java:1418)org.testng.Assert.assertEquals(Assert.java:1382)org.testng.Assert.assertEquals(Assert.java:1428)FacturialTest.testFactorial(FacturialTest.java:110)java.base/jdk.internal.reflect.DirectMethodHandleAccessor.invoke(DirectMethodHandleAccessor.java:104)java.base/java.lang.reflect.Method.invoke(Method.java:578)org.testng.internal.invokers.MethodInvocationHelper.invokeMethod(MethodInvocationHelper.java:139)org.testng.internal.invokers.TestInvoker.invokeMethod(TestInvoker.java:677)org.testng.internal.invokers.TestInvoker.invokeTestMethod(TestInvoker.java:221)org.testng.internal.invokers.MethodRunner.runInSequence(MethodRunner.java:50)org.testng.internal.invokers.TestInvoker$MethodInvocationAgent.invoke(TestInvoker.java:969)org.testng.internal.invokers.TestInvoker.invokeTestMethods(TestInvoker.java:194)org.testng.internal.invokers.TestMethodWorker.invokeTestMethods(TestMethodWorker.java:148)org.testng.internal.invokers.TestMethodWorker.run(TestMethodWorker.java:128)java.base/java.util.ArrayList.forEach(ArrayList.java:1511)org.testng.TestRunner.privateRun(TestRunner.java:829)org.testng.TestRunner.run(TestRunner.java:602)org.testng.SuiteRunner.runTest(SuiteRunner.java:437)org.testng.SuiteRunner$SuiteWorker.run(SuiteRunner.java:475)org.testng.internal.thread.ThreadUtil.lambda$execute$0(ThreadUtil.java:58)java.base/java.util.concurrent.FutureTask.run(FutureTask.java:317)java.base/java.util.concurrent.ThreadPoolExecutor.runWorker(ThreadPoolExecutor.java:1144)java.base/java.util.concurrent.ThreadPoolExecutor$Worker.run(ThreadPoolExecutor.java:642)java.base/java.lang.Thread.run(Thread.java:1623)
]]>
            </failure>
    </testcase>
            <testcase
                name="testFactorial"
                time="0.001"
                classname="FacturialTest">

            <failure type="java.lang.AssertionError" message="expected [4] but found [2]">
                <![CDATA[java.lang.AssertionError: expected [4] but found [2]
                org.testng.Assert.fail(Assert.java:110)org.testng.Assert.failNotEquals(Assert.java:1577)org.testng.Assert.assertEqualsImpl(Assert.java:149)org.testng.Assert.assertEquals(Assert.java:131)org.testng.Assert.assertEquals(Assert.java:1418)org.testng.Assert.assertEquals(Assert.java:1382)org.testng.Assert.assertEquals(Assert.java:1428)FacturialTest.testFactorial(FacturialTest.java:110)java.base/jdk.internal.reflect.DirectMethodHandleAccessor.invoke(DirectMethodHandleAccessor.java:104)java.base/java.lang.reflect.Method.invoke(Method.java:578)org.testng.internal.invokers.MethodInvocationHelper.invokeMethod(MethodInvocationHelper.java:139)org.testng.internal.invokers.TestInvoker.invokeMethod(TestInvoker.java:677)org.testng.internal.invokers.TestInvoker.invokeTestMethod(TestInvoker.java:221)org.testng.internal.invokers.MethodRunner.runInSequence(MethodRunner.java:50)org.testng.internal.invokers.TestInvoker$MethodInvocationAgent.invoke(TestInvoker.java:969)org.testng.internal.invokers.TestInvoker.invokeTestMethods(TestInvoker.java:194)org.testng.internal.invokers.TestMethodWorker.invokeTestMethods(TestMethodWorker.java:148)org.testng.internal.invokers.TestMethodWorker.run(TestMethodWorker.java:128)java.base/java.util.ArrayList.forEach(ArrayList.java:1511)org.testng.TestRunner.privateRun(TestRunner.java:829)org.testng.TestRunner.run(TestRunner.java:602)org.testng.SuiteRunner.runTest(SuiteRunner.java:437)org.testng.SuiteRunner$SuiteWorker.run(SuiteRunner.java:475)org.testng.internal.thread.ThreadUtil.lambda$execute$0(ThreadUtil.java:58)java.base/java.util.concurrent.FutureTask.run(FutureTask.java:317)java.base/java.util.concurrent.ThreadPoolExecutor.runWorker(ThreadPoolExecutor.java:1144)java.base/java.util.concurrent.ThreadPoolExecutor$Worker.run(ThreadPoolExecutor.java:642)java.base/java.lang.Thread.run(Thread.java:1623)
]]>
            </failure>
    </testcase>
            <testcase
                name="testFactorial"
                time="0.001"
                classname="FacturialTest">

            <failure type="java.lang.AssertionError" message="expected [4] but found [2]">
                <![CDATA[java.lang.AssertionError: expected [4] but found [2]
                org.testng.Assert.fail(Assert.java:110)org.testng.Assert.failNotEquals(Assert.java:1577)org.testng.Assert.assertEqualsImpl(Assert.java:149)org.testng.Assert.assertEquals(Assert.java:131)org.testng.Assert.assertEquals(Assert.java:1418)org.testng.Assert.assertEquals(Assert.java:1382)org.testng.Assert.assertEquals(Assert.java:1428)FacturialTest.testFactorial(FacturialTest.java:110)java.base/jdk.internal.reflect.DirectMethodHandleAccessor.invoke(DirectMethodHandleAccessor.java:104)java.base/java.lang.reflect.Method.invoke(Method.java:578)org.testng.internal.invokers.MethodInvocationHelper.invokeMethod(MethodInvocationHelper.java:139)org.testng.internal.invokers.TestInvoker.invokeMethod(TestInvoker.java:677)org.testng.internal.invokers.TestInvoker.invokeTestMethod(TestInvoker.java:221)org.testng.internal.invokers.MethodRunner.runInSequence(MethodRunner.java:50)org.testng.internal.invokers.TestInvoker$MethodInvocationAgent.invoke(TestInvoker.java:969)org.testng.internal.invokers.TestInvoker.invokeTestMethods(TestInvoker.java:194)org.testng.internal.invokers.TestMethodWorker.invokeTestMethods(TestMethodWorker.java:148)org.testng.internal.invokers.TestMethodWorker.run(TestMethodWorker.java:128)java.base/java.util.ArrayList.forEach(ArrayList.java:1511)org.testng.TestRunner.privateRun(TestRunner.java:829)org.testng.TestRunner.run(TestRunner.java:602)org.testng.SuiteRunner.runTest(SuiteRunner.java:437)org.testng.SuiteRunner$SuiteWorker.run(SuiteRunner.java:475)org.testng.internal.thread.ThreadUtil.lambda$execute$0(ThreadUtil.java:58)java.base/java.util.concurrent.FutureTask.run(FutureTask.java:317)java.base/java.util.concurrent.ThreadPoolExecutor.runWorker(ThreadPoolExecutor.java:1144)java.base/java.util.concurrent.ThreadPoolExecutor$Worker.run(ThreadPoolExecutor.java:642)java.base/java.lang.Thread.run(Thread.java:1623)
]]>
            </failure>
    </testcase>
            <testcase
                name="testFactorial"
                time="0.002"
                classname="FacturialTest">

            <failure type="java.lang.AssertionError" message="expected [4] but found [2]">
                <![CDATA[java.lang.AssertionError: expected [4] but found [2]
                org.testng.Assert.fail(Assert.java:110)org.testng.Assert.failNotEquals(Assert.java:1577)org.testng.Assert.assertEqualsImpl(Assert.java:149)org.testng.Assert.assertEquals(Assert.java:131)org.testng.Assert.assertEquals(Assert.java:1418)org.testng.Assert.assertEquals(Assert.java:1382)org.testng.Assert.assertEquals(Assert.java:1428)FacturialTest.testFactorial(FacturialTest.java:110)java.base/jdk.internal.reflect.DirectMethodHandleAccessor.invoke(DirectMethodHandleAccessor.java:104)java.base/java.lang.reflect.Method.invoke(Method.java:578)org.testng.internal.invokers.MethodInvocationHelper.invokeMethod(MethodInvocationHelper.java:139)org.testng.internal.invokers.TestInvoker.invokeMethod(TestInvoker.java:677)org.testng.internal.invokers.TestInvoker.invokeTestMethod(TestInvoker.java:221)org.testng.internal.invokers.MethodRunner.runInSequence(MethodRunner.java:50)org.testng.internal.invokers.TestInvoker$MethodInvocationAgent.invoke(TestInvoker.java:969)org.testng.internal.invokers.TestInvoker.invokeTestMethods(TestInvoker.java:194)org.testng.internal.invokers.TestMethodWorker.invokeTestMethods(TestMethodWorker.java:148)org.testng.internal.invokers.TestMethodWorker.run(TestMethodWorker.java:128)java.base/java.util.ArrayList.forEach(ArrayList.java:1511)org.testng.TestRunner.privateRun(TestRunner.java:829)org.testng.TestRunner.run(TestRunner.java:602)org.testng.SuiteRunner.runTest(SuiteRunner.java:437)org.testng.SuiteRunner$SuiteWorker.run(SuiteRunner.java:475)org.testng.internal.thread.ThreadUtil.lambda$execute$0(ThreadUtil.java:58)java.base/java.util.concurrent.FutureTask.run(FutureTask.java:317)java.base/java.util.concurrent.ThreadPoolExecutor.runWorker(ThreadPoolExecutor.java:1144)java.base/java.util.concurrent.ThreadPoolExecutor$Worker.run(ThreadPoolExecutor.java:642)java.base/java.lang.Thread.run(Thread.java:1623)
]]>
            </failure>
    </testcase>
            <testcase
                name="testFactorial"
                time="0.001"
                classname="FacturialTest">

            <failure type="java.lang.AssertionError" message="expected [4] but found [2]">
                <![CDATA[java.lang.AssertionError: expected [4] but found [2]
                org.testng.Assert.fail(Assert.java:110)org.testng.Assert.failNotEquals(Assert.java:1577)org.testng.Assert.assertEqualsImpl(Assert.java:149)org.testng.Assert.assertEquals(Assert.java:131)org.testng.Assert.assertEquals(Assert.java:1418)org.testng.Assert.assertEquals(Assert.java:1382)org.testng.Assert.assertEquals(Assert.java:1428)FacturialTest.testFactorial(FacturialTest.java:110)java.base/jdk.internal.reflect.DirectMethodHandleAccessor.invoke(DirectMethodHandleAccessor.java:104)java.base/java.lang.reflect.Method.invoke(Method.java:578)org.testng.internal.invokers.MethodInvocationHelper.invokeMethod(MethodInvocationHelper.java:139)org.testng.internal.invokers.TestInvoker.invokeMethod(TestInvoker.java:677)org.testng.internal.invokers.TestInvoker.invokeTestMethod(TestInvoker.java:221)org.testng.internal.invokers.MethodRunner.runInSequence(MethodRunner.java:50)org.testng.internal.invokers.TestInvoker$MethodInvocationAgent.invoke(TestInvoker.java:969)org.testng.internal.invokers.TestInvoker.invokeTestMethods(TestInvoker.java:194)org.testng.internal.invokers.TestMethodWorker.invokeTestMethods(TestMethodWorker.java:148)org.testng.internal.invokers.TestMethodWorker.run(TestMethodWorker.java:128)java.base/java.util.ArrayList.forEach(ArrayList.java:1511)org.testng.TestRunner.privateRun(TestRunner.java:829)org.testng.TestRunner.run(TestRunner.java:602)org.testng.SuiteRunner.runTest(SuiteRunner.java:437)org.testng.SuiteRunner$SuiteWorker.run(SuiteRunner.java:475)org.testng.internal.thread.ThreadUtil.lambda$execute$0(ThreadUtil.java:58)java.base/java.util.concurrent.FutureTask.run(FutureTask.java:317)java.base/java.util.concurrent.ThreadPoolExecutor.runWorker(ThreadPoolExecutor.java:1144)java.base/java.util.concurrent.ThreadPoolExecutor$Worker.run(ThreadPoolExecutor.java:642)java.base/java.lang.Thread.run(Thread.java:1623)
]]>
            </failure>
    </testcase>
            <testcase
                name="testFactorial"
                time="0.002"
                classname="FacturialTest">

            <failure type="java.lang.AssertionError" message="expected [4] but found [2]">
                <![CDATA[java.lang.AssertionError: expected [4] but found [2]
                org.testng.Assert.fail(Assert.java:110)org.testng.Assert.failNotEquals(Assert.java:1577)org.testng.Assert.assertEqualsImpl(Assert.java:149)org.testng.Assert.assertEquals(Assert.java:131)org.testng.Assert.assertEquals(Assert.java:1418)org.testng.Assert.assertEquals(Assert.java:1382)org.testng.Assert.assertEquals(Assert.java:1428)FacturialTest.testFactorial(FacturialTest.java:110)java.base/jdk.internal.reflect.DirectMethodHandleAccessor.invoke(DirectMethodHandleAccessor.java:104)java.base/java.lang.reflect.Method.invoke(Method.java:578)org.testng.internal.invokers.MethodInvocationHelper.invokeMethod(MethodInvocationHelper.java:139)org.testng.internal.invokers.TestInvoker.invokeMethod(TestInvoker.java:677)org.testng.internal.invokers.TestInvoker.invokeTestMethod(TestInvoker.java:221)org.testng.internal.invokers.MethodRunner.runInSequence(MethodRunner.java:50)org.testng.internal.invokers.TestInvoker$MethodInvocationAgent.invoke(TestInvoker.java:969)org.testng.internal.invokers.TestInvoker.invokeTestMethods(TestInvoker.java:194)org.testng.internal.invokers.TestMethodWorker.invokeTestMethods(TestMethodWorker.java:148)org.testng.internal.invokers.TestMethodWorker.run(TestMethodWorker.java:128)java.base/java.util.ArrayList.forEach(ArrayList.java:1511)org.testng.TestRunner.privateRun(TestRunner.java:829)org.testng.TestRunner.run(TestRunner.java:602)org.testng.SuiteRunner.runTest(SuiteRunner.java:437)org.testng.SuiteRunner$SuiteWorker.run(SuiteRunner.java:475)org.testng.internal.thread.ThreadUtil.lambda$execute$0(ThreadUtil.java:58)java.base/java.util.concurrent.FutureTask.run(FutureTask.java:317)java.base/java.util.concurrent.ThreadPoolExecutor.runWorker(ThreadPoolExecutor.java:1144)java.base/java.util.concurrent.ThreadPoolExecutor$Worker.run(ThreadPoolExecutor.java:642)java.base/java.lang.Thread.run(Thread.java:1623)
]]>
            </failure>
    </testcase>
            <testcase
                name="testFactorial"
                time="0.001"
                classname="FacturialTest">

            <failure type="java.lang.AssertionError" message="expected [4] but found [2]">
                <![CDATA[java.lang.AssertionError: expected [4] but found [2]
                org.testng.Assert.fail(Assert.java:110)org.testng.Assert.failNotEquals(Assert.java:1577)org.testng.Assert.assertEqualsImpl(Assert.java:149)org.testng.Assert.assertEquals(Assert.java:131)org.testng.Assert.assertEquals(Assert.java:1418)org.testng.Assert.assertEquals(Assert.java:1382)org.testng.Assert.assertEquals(Assert.java:1428)FacturialTest.testFactorial(FacturialTest.java:110)java.base/jdk.internal.reflect.DirectMethodHandleAccessor.invoke(DirectMethodHandleAccessor.java:104)java.base/java.lang.reflect.Method.invoke(Method.java:578)org.testng.internal.invokers.MethodInvocationHelper.invokeMethod(MethodInvocationHelper.java:139)org.testng.internal.invokers.TestInvoker.invokeMethod(TestInvoker.java:677)org.testng.internal.invokers.TestInvoker.invokeTestMethod(TestInvoker.java:221)org.testng.internal.invokers.MethodRunner.runInSequence(MethodRunner.java:50)org.testng.internal.invokers.TestInvoker$MethodInvocationAgent.invoke(TestInvoker.java:969)org.testng.internal.invokers.TestInvoker.invokeTestMethods(TestInvoker.java:194)org.testng.internal.invokers.TestMethodWorker.invokeTestMethods(TestMethodWorker.java:148)org.testng.internal.invokers.TestMethodWorker.run(TestMethodWorker.java:128)java.base/java.util.ArrayList.forEach(ArrayList.java:1511)org.testng.TestRunner.privateRun(TestRunner.java:829)org.testng.TestRunner.run(TestRunner.java:602)org.testng.SuiteRunner.runTest(SuiteRunner.java:437)org.testng.SuiteRunner$SuiteWorker.run(SuiteRunner.java:475)org.testng.internal.thread.ThreadUtil.lambda$execute$0(ThreadUtil.java:58)java.base/java.util.concurrent.FutureTask.run(FutureTask.java:317)java.base/java.util.concurrent.ThreadPoolExecutor.runWorker(ThreadPoolExecutor.java:1144)java.base/java.util.concurrent.ThreadPoolExecutor$Worker.run(ThreadPoolExecutor.java:642)java.base/java.lang.Thread.run(Thread.java:1623)
]]>
            </failure>
    </testcase>
            <testcase
                name="testFactorial"
                time="0.002"
                classname="FacturialTest">

            <failure type="java.lang.AssertionError" message="expected [4] but found [2]">
                <![CDATA[java.lang.AssertionError: expected [4] but found [2]
                org.testng.Assert.fail(Assert.java:110)org.testng.Assert.failNotEquals(Assert.java:1577)org.testng.Assert.assertEqualsImpl(Assert.java:149)org.testng.Assert.assertEquals(Assert.java:131)org.testng.Assert.assertEquals(Assert.java:1418)org.testng.Assert.assertEquals(Assert.java:1382)org.testng.Assert.assertEquals(Assert.java:1428)FacturialTest.testFactorial(FacturialTest.java:110)java.base/jdk.internal.reflect.DirectMethodHandleAccessor.invoke(DirectMethodHandleAccessor.java:104)java.base/java.lang.reflect.Method.invoke(Method.java:578)org.testng.internal.invokers.MethodInvocationHelper.invokeMethod(MethodInvocationHelper.java:139)org.testng.internal.invokers.TestInvoker.invokeMethod(TestInvoker.java:677)org.testng.internal.invokers.TestInvoker.invokeTestMethod(TestInvoker.java:221)org.testng.internal.invokers.MethodRunner.runInSequence(MethodRunner.java:50)org.testng.internal.invokers.TestInvoker$MethodInvocationAgent.invoke(TestInvoker.java:969)org.testng.internal.invokers.TestInvoker.invokeTestMethods(TestInvoker.java:194)org.testng.internal.invokers.TestMethodWorker.invokeTestMethods(TestMethodWorker.java:148)org.testng.internal.invokers.TestMethodWorker.run(TestMethodWorker.java:128)java.base/java.util.ArrayList.forEach(ArrayList.java:1511)org.testng.TestRunner.privateRun(TestRunner.java:829)org.testng.TestRunner.run(TestRunner.java:602)org.testng.SuiteRunner.runTest(SuiteRunner.java:437)org.testng.SuiteRunner$SuiteWorker.run(SuiteRunner.java:475)org.testng.internal.thread.ThreadUtil.lambda$execute$0(ThreadUtil.java:58)java.base/java.util.concurrent.FutureTask.run(FutureTask.java:317)java.base/java.util.concurrent.ThreadPoolExecutor.runWorker(ThreadPoolExecutor.java:1144)java.base/java.util.concurrent.ThreadPoolExecutor$Worker.run(ThreadPoolExecutor.java:642)java.base/java.lang.Thread.run(Thread.java:1623)
]]>
            </failure>
    </testcase>
            <testcase
                name="testFactorial"
                time="0.001"
                classname="FacturialTest">

            <failure type="java.lang.AssertionError" message="expected [4] but found [2]">
                <![CDATA[java.lang.AssertionError: expected [4] but found [2]
                org.testng.Assert.fail(Assert.java:110)org.testng.Assert.failNotEquals(Assert.java:1577)org.testng.Assert.assertEqualsImpl(Assert.java:149)org.testng.Assert.assertEquals(Assert.java:131)org.testng.Assert.assertEquals(Assert.java:1418)org.testng.Assert.assertEquals(Assert.java:1382)org.testng.Assert.assertEquals(Assert.java:1428)FacturialTest.testFactorial(FacturialTest.java:110)java.base/jdk.internal.reflect.DirectMethodHandleAccessor.invoke(DirectMethodHandleAccessor.java:104)java.base/java.lang.reflect.Method.invoke(Method.java:578)org.testng.internal.invokers.MethodInvocationHelper.invokeMethod(MethodInvocationHelper.java:139)org.testng.internal.invokers.TestInvoker.invokeMethod(TestInvoker.java:677)org.testng.internal.invokers.TestInvoker.invokeTestMethod(TestInvoker.java:221)org.testng.internal.invokers.MethodRunner.runInSequence(MethodRunner.java:50)org.testng.internal.invokers.TestInvoker$MethodInvocationAgent.invoke(TestInvoker.java:969)org.testng.internal.invokers.TestInvoker.invokeTestMethods(TestInvoker.java:194)org.testng.internal.invokers.TestMethodWorker.invokeTestMethods(TestMethodWorker.java:148)org.testng.internal.invokers.TestMethodWorker.run(TestMethodWorker.java:128)java.base/java.util.ArrayList.forEach(ArrayList.java:1511)org.testng.TestRunner.privateRun(TestRunner.java:829)org.testng.TestRunner.run(TestRunner.java:602)org.testng.SuiteRunner.runTest(SuiteRunner.java:437)org.testng.SuiteRunner$SuiteWorker.run(SuiteRunner.java:475)org.testng.internal.thread.ThreadUtil.lambda$execute$0(ThreadUtil.java:58)java.base/java.util.concurrent.FutureTask.run(FutureTask.java:317)java.base/java.util.concurrent.ThreadPoolExecutor.runWorker(ThreadPoolExecutor.java:1144)java.base/java.util.concurrent.ThreadPoolExecutor$Worker.run(ThreadPoolExecutor.java:642)java.base/java.lang.Thread.run(Thread.java:1623)
]]>
            </failure>
    </testcase>
            <testcase
                name="testFactorial"
                time="0.003"
                classname="FacturialTest">

            <failure type="java.lang.AssertionError" message="expected [4] but found [2]">
                <![CDATA[java.lang.AssertionError: expected [4] but found [2]
                org.testng.Assert.fail(Assert.java:110)org.testng.Assert.failNotEquals(Assert.java:1577)org.testng.Assert.assertEqualsImpl(Assert.java:149)org.testng.Assert.assertEquals(Assert.java:131)org.testng.Assert.assertEquals(Assert.java:1418)org.testng.Assert.assertEquals(Assert.java:1382)org.testng.Assert.assertEquals(Assert.java:1428)FacturialTest.testFactorial(FacturialTest.java:110)java.base/jdk.internal.reflect.DirectMethodHandleAccessor.invoke(DirectMethodHandleAccessor.java:104)java.base/java.lang.reflect.Method.invoke(Method.java:578)org.testng.internal.invokers.MethodInvocationHelper.invokeMethod(MethodInvocationHelper.java:139)org.testng.internal.invokers.TestInvoker.invokeMethod(TestInvoker.java:677)org.testng.internal.invokers.TestInvoker.invokeTestMethod(TestInvoker.java:221)org.testng.internal.invokers.MethodRunner.runInSequence(MethodRunner.java:50)org.testng.internal.invokers.TestInvoker$MethodInvocationAgent.invoke(TestInvoker.java:969)org.testng.internal.invokers.TestInvoker.invokeTestMethods(TestInvoker.java:194)org.testng.internal.invokers.TestMethodWorker.invokeTestMethods(TestMethodWorker.java:148)org.testng.internal.invokers.TestMethodWorker.run(TestMethodWorker.java:128)java.base/java.util.ArrayList.forEach(ArrayList.java:1511)org.testng.TestRunner.privateRun(TestRunner.java:829)org.testng.TestRunner.run(TestRunner.java:602)org.testng.SuiteRunner.runTest(SuiteRunner.java:437)org.testng.SuiteRunner$SuiteWorker.run(SuiteRunner.java:475)org.testng.internal.thread.ThreadUtil.lambda$execute$0(ThreadUtil.java:58)java.base/java.util.concurrent.FutureTask.run(FutureTask.java:317)java.base/java.util.concurrent.ThreadPoolExecutor.runWorker(ThreadPoolExecutor.java:1144)java.base/java.util.concurrent.ThreadPoolExecutor$Worker.run(ThreadPoolExecutor.java:642)java.base/java.lang.Thread.run(Thread.java:1623)
]]>
            </failure>
    </testcase>
            <testcase
                name="testFactorial"
                time="0.002"
                classname="FacturialTest">

            <failure type="java.lang.AssertionError" message="expected [4] but found [2]">
                <![CDATA[java.lang.AssertionError: expected [4] but found [2]
                org.testng.Assert.fail(Assert.java:110)org.testng.Assert.failNotEquals(Assert.java:1577)org.testng.Assert.assertEqualsImpl(Assert.java:149)org.testng.Assert.assertEquals(Assert.java:131)org.testng.Assert.assertEquals(Assert.java:1418)org.testng.Assert.assertEquals(Assert.java:1382)org.testng.Assert.assertEquals(Assert.java:1428)FacturialTest.testFactorial(FacturialTest.java:110)java.base/jdk.internal.reflect.DirectMethodHandleAccessor.invoke(DirectMethodHandleAccessor.java:104)java.base/java.lang.reflect.Method.invoke(Method.java:578)org.testng.internal.invokers.MethodInvocationHelper.invokeMethod(MethodInvocationHelper.java:139)org.testng.internal.invokers.TestInvoker.invokeMethod(TestInvoker.java:677)org.testng.internal.invokers.TestInvoker.invokeTestMethod(TestInvoker.java:221)org.testng.internal.invokers.MethodRunner.runInSequence(MethodRunner.java:50)org.testng.internal.invokers.TestInvoker$MethodInvocationAgent.invoke(TestInvoker.java:969)org.testng.internal.invokers.TestInvoker.invokeTestMethods(TestInvoker.java:194)org.testng.internal.invokers.TestMethodWorker.invokeTestMethods(TestMethodWorker.java:148)org.testng.internal.invokers.TestMethodWorker.run(TestMethodWorker.java:128)java.base/java.util.ArrayList.forEach(ArrayList.java:1511)org.testng.TestRunner.privateRun(TestRunner.java:829)org.testng.TestRunner.run(TestRunner.java:602)org.testng.SuiteRunner.runTest(SuiteRunner.java:437)org.testng.SuiteRunner$SuiteWorker.run(SuiteRunner.java:475)org.testng.internal.thread.ThreadUtil.lambda$execute$0(ThreadUtil.java:58)java.base/java.util.concurrent.FutureTask.run(FutureTask.java:317)java.base/java.util.concurrent.ThreadPoolExecutor.runWorker(ThreadPoolExecutor.java:1144)java.base/java.util.concurrent.ThreadPoolExecutor$Worker.run(ThreadPoolExecutor.java:642)java.base/java.lang.Thread.run(Thread.java:1623)
]]>
            </failure>
    </testcase>
            <testcase
                name="testFactorial"
                time="0.005"
                classname="FacturialTest">

            <failure type="java.lang.AssertionError" message="expected [4] but found [2]">
                <![CDATA[java.lang.AssertionError: expected [4] but found [2]
                org.testng.Assert.fail(Assert.java:110)org.testng.Assert.failNotEquals(Assert.java:1577)org.testng.Assert.assertEqualsImpl(Assert.java:149)org.testng.Assert.assertEquals(Assert.java:131)org.testng.Assert.assertEquals(Assert.java:1418)org.testng.Assert.assertEquals(Assert.java:1382)org.testng.Assert.assertEquals(Assert.java:1428)FacturialTest.testFactorial(FacturialTest.java:110)java.base/jdk.internal.reflect.DirectMethodHandleAccessor.invoke(DirectMethodHandleAccessor.java:104)java.base/java.lang.reflect.Method.invoke(Method.java:578)org.testng.internal.invokers.MethodInvocationHelper.invokeMethod(MethodInvocationHelper.java:139)org.testng.internal.invokers.TestInvoker.invokeMethod(TestInvoker.java:677)org.testng.internal.invokers.TestInvoker.invokeTestMethod(TestInvoker.java:221)org.testng.internal.invokers.MethodRunner.runInSequence(MethodRunner.java:50)org.testng.internal.invokers.TestInvoker$MethodInvocationAgent.invoke(TestInvoker.java:969)org.testng.internal.invokers.TestInvoker.invokeTestMethods(TestInvoker.java:194)org.testng.internal.invokers.TestMethodWorker.invokeTestMethods(TestMethodWorker.java:148)org.testng.internal.invokers.TestMethodWorker.run(TestMethodWorker.java:128)java.base/java.util.ArrayList.forEach(ArrayList.java:1511)org.testng.TestRunner.privateRun(TestRunner.java:829)org.testng.TestRunner.run(TestRunner.java:602)org.testng.SuiteRunner.runTest(SuiteRunner.java:437)org.testng.SuiteRunner$SuiteWorker.run(SuiteRunner.java:475)org.testng.internal.thread.ThreadUtil.lambda$execute$0(ThreadUtil.java:58)java.base/java.util.concurrent.FutureTask.run(FutureTask.java:317)java.base/java.util.concurrent.ThreadPoolExecutor.runWorker(ThreadPoolExecutor.java:1144)java.base/java.util.concurrent.ThreadPoolExecutor$Worker.run(ThreadPoolExecutor.java:642)java.base/java.lang.Thread.run(Thread.java:1623)
]]>
            </failure>
    </testcase>
            <testcase
                name="testFactorial"
                time="0.001"
                classname="FacturialTest">

            <failure type="java.lang.AssertionError" message="expected [4] but found [2]">
                <![CDATA[java.lang.AssertionError: expected [4] but found [2]
                org.testng.Assert.fail(Assert.java:110)org.testng.Assert.failNotEquals(Assert.java:1577)org.testng.Assert.assertEqualsImpl(Assert.java:149)org.testng.Assert.assertEquals(Assert.java:131)org.testng.Assert.assertEquals(Assert.java:1418)org.testng.Assert.assertEquals(Assert.java:1382)org.testng.Assert.assertEquals(Assert.java:1428)FacturialTest.testFactorial(FacturialTest.java:110)java.base/jdk.internal.reflect.DirectMethodHandleAccessor.invoke(DirectMethodHandleAccessor.java:104)java.base/java.lang.reflect.Method.invoke(Method.java:578)org.testng.internal.invokers.MethodInvocationHelper.invokeMethod(MethodInvocationHelper.java:139)org.testng.internal.invokers.TestInvoker.invokeMethod(TestInvoker.java:677)org.testng.internal.invokers.TestInvoker.invokeTestMethod(TestInvoker.java:221)org.testng.internal.invokers.MethodRunner.runInSequence(MethodRunner.java:50)org.testng.internal.invokers.TestInvoker$MethodInvocationAgent.invoke(TestInvoker.java:969)org.testng.internal.invokers.TestInvoker.invokeTestMethods(TestInvoker.java:194)org.testng.internal.invokers.TestMethodWorker.invokeTestMethods(TestMethodWorker.java:148)org.testng.internal.invokers.TestMethodWorker.run(TestMethodWorker.java:128)java.base/java.util.ArrayList.forEach(ArrayList.java:1511)org.testng.TestRunner.privateRun(TestRunner.java:829)org.testng.TestRunner.run(TestRunner.java:602)org.testng.SuiteRunner.runTest(SuiteRunner.java:437)org.testng.SuiteRunner$SuiteWorker.run(SuiteRunner.java:475)org.testng.internal.thread.ThreadUtil.lambda$execute$0(ThreadUtil.java:58)java.base/java.util.concurrent.FutureTask.run(FutureTask.java:317)java.base/java.util.concurrent.ThreadPoolExecutor.runWorker(ThreadPoolExecutor.java:1144)java.base/java.util.concurrent.ThreadPoolExecutor$Worker.run(ThreadPoolExecutor.java:642)java.base/java.lang.Thread.run(Thread.java:1623)
]]>
            </failure>
    </testcase>
            <testcase
                name="testFactorial"
                time="0.078"
                classname="FacturialTest">

            <failure type="java.lang.AssertionError" message="expected [4] but found [2]">
                <![CDATA[java.lang.AssertionError: expected [4] but found [2]
                org.testng.Assert.fail(Assert.java:110)org.testng.Assert.failNotEquals(Assert.java:1577)org.testng.Assert.assertEqualsImpl(Assert.java:149)org.testng.Assert.assertEquals(Assert.java:131)org.testng.Assert.assertEquals(Assert.java:1418)org.testng.Assert.assertEquals(Assert.java:1382)org.testng.Assert.assertEquals(Assert.java:1428)FacturialTest.testFactorial(FacturialTest.java:110)java.base/jdk.internal.reflect.DirectMethodHandleAccessor.invoke(DirectMethodHandleAccessor.java:104)java.base/java.lang.reflect.Method.invoke(Method.java:578)org.testng.internal.invokers.MethodInvocationHelper.invokeMethod(MethodInvocationHelper.java:139)org.testng.internal.invokers.TestInvoker.invokeMethod(TestInvoker.java:677)org.testng.internal.invokers.TestInvoker.invokeTestMethod(TestInvoker.java:221)org.testng.internal.invokers.MethodRunner.runInSequence(MethodRunner.java:50)org.testng.internal.invokers.TestInvoker$MethodInvocationAgent.invoke(TestInvoker.java:969)org.testng.internal.invokers.TestInvoker.invokeTestMethods(TestInvoker.java:194)org.testng.internal.invokers.TestMethodWorker.invokeTestMethods(TestMethodWorker.java:148)org.testng.internal.invokers.TestMethodWorker.run(TestMethodWorker.java:128)java.base/java.util.ArrayList.forEach(ArrayList.java:1511)org.testng.TestRunner.privateRun(TestRunner.java:829)org.testng.TestRunner.run(TestRunner.java:602)org.testng.SuiteRunner.runTest(SuiteRunner.java:437)org.testng.SuiteRunner$SuiteWorker.run(SuiteRunner.java:475)org.testng.internal.thread.ThreadUtil.lambda$execute$0(ThreadUtil.java:58)java.base/java.util.concurrent.FutureTask.run(FutureTask.java:317)java.base/java.util.concurrent.ThreadPoolExecutor.runWorker(ThreadPoolExecutor.java:1144)java.base/java.util.concurrent.ThreadPoolExecutor$Worker.run(ThreadPoolExecutor.java:642)java.base/java.lang.Thread.run(Thread.java:1623)
]]>
            </failure>
    </testcase>
            <testcase
                name="testFactorial"
                time="0.028"
                classname="FacturialTest">

            <failure type="java.lang.AssertionError" message="expected [4] but found [2]">
                <![CDATA[java.lang.AssertionError: expected [4] but found [2]
                org.testng.Assert.fail(Assert.java:110)org.testng.Assert.failNotEquals(Assert.java:1577)org.testng.Assert.assertEqualsImpl(Assert.java:149)org.testng.Assert.assertEquals(Assert.java:131)org.testng.Assert.assertEquals(Assert.java:1418)org.testng.Assert.assertEquals(Assert.java:1382)org.testng.Assert.assertEquals(Assert.java:1428)FacturialTest.testFactorial(FacturialTest.java:110)java.base/jdk.internal.reflect.DirectMethodHandleAccessor.invoke(DirectMethodHandleAccessor.java:104)java.base/java.lang.reflect.Method.invoke(Method.java:578)org.testng.internal.invokers.MethodInvocationHelper.invokeMethod(MethodInvocationHelper.java:139)org.testng.internal.invokers.TestInvoker.invokeMethod(TestInvoker.java:677)org.testng.internal.invokers.TestInvoker.invokeTestMethod(TestInvoker.java:221)org.testng.internal.invokers.MethodRunner.runInSequence(MethodRunner.java:50)org.testng.internal.invokers.TestInvoker$MethodInvocationAgent.invoke(TestInvoker.java:969)org.testng.internal.invokers.TestInvoker.invokeTestMethods(TestInvoker.java:194)org.testng.internal.invokers.TestMethodWorker.invokeTestMethods(TestMethodWorker.java:148)org.testng.internal.invokers.TestMethodWorker.run(TestMethodWorker.java:128)java.base/java.util.ArrayList.forEach(ArrayList.java:1511)org.testng.TestRunner.privateRun(TestRunner.java:829)org.testng.TestRunner.run(TestRunner.java:602)org.testng.SuiteRunner.runTest(SuiteRunner.java:437)org.testng.SuiteRunner$SuiteWorker.run(SuiteRunner.java:475)org.testng.internal.thread.ThreadUtil.lambda$execute$0(ThreadUtil.java:58)java.base/java.util.concurrent.FutureTask.run(FutureTask.java:317)java.base/java.util.concurrent.ThreadPoolExecutor.runWorker(ThreadPoolExecutor.java:1144)java.base/java.util.concurrent.ThreadPoolExecutor$Worker.run(ThreadPoolExecutor.java:642)java.base/java.lang.Thread.run(Thread.java:1623)
]]>
            </failure>
    </testcase>
            <testcase
                name="testFactorial"
                time="0.064"
                classname="FacturialTest">

            <failure type="java.lang.AssertionError" message="expected [4] but found [2]">
                <![CDATA[java.lang.AssertionError: expected [4] but found [2]
                org.testng.Assert.fail(Assert.java:110)org.testng.Assert.failNotEquals(Assert.java:1577)org.testng.Assert.assertEqualsImpl(Assert.java:149)org.testng.Assert.assertEquals(Assert.java:131)org.testng.Assert.assertEquals(Assert.java:1418)org.testng.Assert.assertEquals(Assert.java:1382)org.testng.Assert.assertEquals(Assert.java:1428)FacturialTest.testFactorial(FacturialTest.java:110)java.base/jdk.internal.reflect.DirectMethodHandleAccessor.invoke(DirectMethodHandleAccessor.java:104)java.base/java.lang.reflect.Method.invoke(Method.java:578)org.testng.internal.invokers.MethodInvocationHelper.invokeMethod(MethodInvocationHelper.java:139)org.testng.internal.invokers.TestInvoker.invokeMethod(TestInvoker.java:677)org.testng.internal.invokers.TestInvoker.invokeTestMethod(TestInvoker.java:221)org.testng.internal.invokers.MethodRunner.runInSequence(MethodRunner.java:50)org.testng.internal.invokers.TestInvoker$MethodInvocationAgent.invoke(TestInvoker.java:969)org.testng.internal.invokers.TestInvoker.invokeTestMethods(TestInvoker.java:194)org.testng.internal.invokers.TestMethodWorker.invokeTestMethods(TestMethodWorker.java:148)org.testng.internal.invokers.TestMethodWorker.run(TestMethodWorker.java:128)java.base/java.util.ArrayList.forEach(ArrayList.java:1511)org.testng.TestRunner.privateRun(TestRunner.java:829)org.testng.TestRunner.run(TestRunner.java:602)org.testng.SuiteRunner.runTest(SuiteRunner.java:437)org.testng.SuiteRunner$SuiteWorker.run(SuiteRunner.java:475)org.testng.internal.thread.ThreadUtil.lambda$execute$0(ThreadUtil.java:58)java.base/java.util.concurrent.FutureTask.run(FutureTask.java:317)java.base/java.util.concurrent.ThreadPoolExecutor.runWorker(ThreadPoolExecutor.java:1144)java.base/java.util.concurrent.ThreadPoolExecutor$Worker.run(ThreadPoolExecutor.java:642)java.base/java.lang.Thread.run(Thread.java:1623)
]]>
            </failure>
    </testcase>
            <testcase
                name="testFactorial"
                time="0.001"
                classname="FacturialTest">

            <failure type="java.lang.AssertionError" message="expected [4] but found [2]">
                <![CDATA[java.lang.AssertionError: expected [4] but found [2]
                org.testng.Assert.fail(Assert.java:110)org.testng.Assert.failNotEquals(Assert.java:1577)org.testng.Assert.assertEqualsImpl(Assert.java:149)org.testng.Assert.assertEquals(Assert.java:131)org.testng.Assert.assertEquals(Assert.java:1418)org.testng.Assert.assertEquals(Assert.java:1382)org.testng.Assert.assertEquals(Assert.java:1428)FacturialTest.testFactorial(FacturialTest.java:110)java.base/jdk.internal.reflect.DirectMethodHandleAccessor.invoke(DirectMethodHandleAccessor.java:104)java.base/java.lang.reflect.Method.invoke(Method.java:578)org.testng.internal.invokers.MethodInvocationHelper.invokeMethod(MethodInvocationHelper.java:139)org.testng.internal.invokers.TestInvoker.invokeMethod(TestInvoker.java:677)org.testng.internal.invokers.TestInvoker.invokeTestMethod(TestInvoker.java:221)org.testng.internal.invokers.MethodRunner.runInSequence(MethodRunner.java:50)org.testng.internal.invokers.TestInvoker$MethodInvocationAgent.invoke(TestInvoker.java:969)org.testng.internal.invokers.TestInvoker.invokeTestMethods(TestInvoker.java:194)org.testng.internal.invokers.TestMethodWorker.invokeTestMethods(TestMethodWorker.java:148)org.testng.internal.invokers.TestMethodWorker.run(TestMethodWorker.java:128)java.base/java.util.ArrayList.forEach(ArrayList.java:1511)org.testng.TestRunner.privateRun(TestRunner.java:829)org.testng.TestRunner.run(TestRunner.java:602)org.testng.SuiteRunner.runTest(SuiteRunner.java:437)org.testng.SuiteRunner$SuiteWorker.run(SuiteRunner.java:475)org.testng.internal.thread.ThreadUtil.lambda$execute$0(ThreadUtil.java:58)java.base/java.util.concurrent.FutureTask.run(FutureTask.java:317)java.base/java.util.concurrent.ThreadPoolExecutor.runWorker(ThreadPoolExecutor.java:1144)java.base/java.util.concurrent.ThreadPoolExecutor$Worker.run(ThreadPoolExecutor.java:642)java.base/java.lang.Thread.run(Thread.java:1623)
]]>
            </failure>
    </testcase>
            <testcase
                name="testFactorial"
                time="0.001"
                classname="FacturialTest">

            <failure type="java.lang.AssertionError" message="expected [4] but found [2]">
                <![CDATA[java.lang.AssertionError: expected [4] but found [2]
                org.testng.Assert.fail(Assert.java:110)org.testng.Assert.failNotEquals(Assert.java:1577)org.testng.Assert.assertEqualsImpl(Assert.java:149)org.testng.Assert.assertEquals(Assert.java:131)org.testng.Assert.assertEquals(Assert.java:1418)org.testng.Assert.assertEquals(Assert.java:1382)org.testng.Assert.assertEquals(Assert.java:1428)FacturialTest.testFactorial(FacturialTest.java:110)java.base/jdk.internal.reflect.DirectMethodHandleAccessor.invoke(DirectMethodHandleAccessor.java:104)java.base/java.lang.reflect.Method.invoke(Method.java:578)org.testng.internal.invokers.MethodInvocationHelper.invokeMethod(MethodInvocationHelper.java:139)org.testng.internal.invokers.TestInvoker.invokeMethod(TestInvoker.java:677)org.testng.internal.invokers.TestInvoker.invokeTestMethod(TestInvoker.java:221)org.testng.internal.invokers.MethodRunner.runInSequence(MethodRunner.java:50)org.testng.internal.invokers.TestInvoker$MethodInvocationAgent.invoke(TestInvoker.java:969)org.testng.internal.invokers.TestInvoker.invokeTestMethods(TestInvoker.java:194)org.testng.internal.invokers.TestMethodWorker.invokeTestMethods(TestMethodWorker.java:148)org.testng.internal.invokers.TestMethodWorker.run(TestMethodWorker.java:128)java.base/java.util.ArrayList.forEach(ArrayList.java:1511)org.testng.TestRunner.privateRun(TestRunner.java:829)org.testng.TestRunner.run(TestRunner.java:602)org.testng.SuiteRunner.runTest(SuiteRunner.java:437)org.testng.SuiteRunner$SuiteWorker.run(SuiteRunner.java:475)org.testng.internal.thread.ThreadUtil.lambda$execute$0(ThreadUtil.java:58)java.base/java.util.concurrent.FutureTask.run(FutureTask.java:317)java.base/java.util.concurrent.ThreadPoolExecutor.runWorker(ThreadPoolExecutor.java:1144)java.base/java.util.concurrent.ThreadPoolExecutor$Worker.run(ThreadPoolExecutor.java:642)java.base/java.lang.Thread.run(Thread.java:1623)
]]>
            </failure>
    </testcase>
            <testcase
                name="testFactorial"
                time="0.001"
                classname="FacturialTest">

            <failure type="java.lang.AssertionError" message="expected [4] but found [2]">
                <![CDATA[java.lang.AssertionError: expected [4] but found [2]
                org.testng.Assert.fail(Assert.java:110)org.testng.Assert.failNotEquals(Assert.java:1577)org.testng.Assert.assertEqualsImpl(Assert.java:149)org.testng.Assert.assertEquals(Assert.java:131)org.testng.Assert.assertEquals(Assert.java:1418)org.testng.Assert.assertEquals(Assert.java:1382)org.testng.Assert.assertEquals(Assert.java:1428)FacturialTest.testFactorial(FacturialTest.java:110)java.base/jdk.internal.reflect.DirectMethodHandleAccessor.invoke(DirectMethodHandleAccessor.java:104)java.base/java.lang.reflect.Method.invoke(Method.java:578)org.testng.internal.invokers.MethodInvocationHelper.invokeMethod(MethodInvocationHelper.java:139)org.testng.internal.invokers.TestInvoker.invokeMethod(TestInvoker.java:677)org.testng.internal.invokers.TestInvoker.invokeTestMethod(TestInvoker.java:221)org.testng.internal.invokers.MethodRunner.runInSequence(MethodRunner.java:50)org.testng.internal.invokers.TestInvoker$MethodInvocationAgent.invoke(TestInvoker.java:969)org.testng.internal.invokers.TestInvoker.invokeTestMethods(TestInvoker.java:194)org.testng.internal.invokers.TestMethodWorker.invokeTestMethods(TestMethodWorker.java:148)org.testng.internal.invokers.TestMethodWorker.run(TestMethodWorker.java:128)java.base/java.util.ArrayList.forEach(ArrayList.java:1511)org.testng.TestRunner.privateRun(TestRunner.java:829)org.testng.TestRunner.run(TestRunner.java:602)org.testng.SuiteRunner.runTest(SuiteRunner.java:437)org.testng.SuiteRunner$SuiteWorker.run(SuiteRunner.java:475)org.testng.internal.thread.ThreadUtil.lambda$execute$0(ThreadUtil.java:58)java.base/java.util.concurrent.FutureTask.run(FutureTask.java:317)java.base/java.util.concurrent.ThreadPoolExecutor.runWorker(ThreadPoolExecutor.java:1144)java.base/java.util.concurrent.ThreadPoolExecutor$Worker.run(ThreadPoolExecutor.java:642)java.base/java.lang.Thread.run(Thread.java:1623)
]]>
            </failure>
    </testcase>
            <testcase
                name="testFactorial"
                time="0.001"
                classname="FacturialTest">

            <failure type="java.lang.AssertionError" message="expected [4] but found [2]">
                <![CDATA[java.lang.AssertionError: expected [4] but found [2]
                org.testng.Assert.fail(Assert.java:110)org.testng.Assert.failNotEquals(Assert.java:1577)org.testng.Assert.assertEqualsImpl(Assert.java:149)org.testng.Assert.assertEquals(Assert.java:131)org.testng.Assert.assertEquals(Assert.java:1418)org.testng.Assert.assertEquals(Assert.java:1382)org.testng.Assert.assertEquals(Assert.java:1428)FacturialTest.testFactorial(FacturialTest.java:110)java.base/jdk.internal.reflect.DirectMethodHandleAccessor.invoke(DirectMethodHandleAccessor.java:104)java.base/java.lang.reflect.Method.invoke(Method.java:578)org.testng.internal.invokers.MethodInvocationHelper.invokeMethod(MethodInvocationHelper.java:139)org.testng.internal.invokers.TestInvoker.invokeMethod(TestInvoker.java:677)org.testng.internal.invokers.TestInvoker.invokeTestMethod(TestInvoker.java:221)org.testng.internal.invokers.MethodRunner.runInSequence(MethodRunner.java:50)org.testng.internal.invokers.TestInvoker$MethodInvocationAgent.invoke(TestInvoker.java:969)org.testng.internal.invokers.TestInvoker.invokeTestMethods(TestInvoker.java:194)org.testng.internal.invokers.TestMethodWorker.invokeTestMethods(TestMethodWorker.java:148)org.testng.internal.invokers.TestMethodWorker.run(TestMethodWorker.java:128)java.base/java.util.ArrayList.forEach(ArrayList.java:1511)org.testng.TestRunner.privateRun(TestRunner.java:829)org.testng.TestRunner.run(TestRunner.java:602)org.testng.SuiteRunner.runTest(SuiteRunner.java:437)org.testng.SuiteRunner$SuiteWorker.run(SuiteRunner.java:475)org.testng.internal.thread.ThreadUtil.lambda$execute$0(ThreadUtil.java:58)java.base/java.util.concurrent.FutureTask.run(FutureTask.java:317)java.base/java.util.concurrent.ThreadPoolExecutor.runWorker(ThreadPoolExecutor.java:1144)java.base/java.util.concurrent.ThreadPoolExecutor$Worker.run(ThreadPoolExecutor.java:642)java.base/java.lang.Thread.run(Thread.java:1623)
]]>
            </failure>
    </testcase>
            <testcase
                name="testFactorial"
                time="0.001"
                classname="FacturialTest">

            <failure type="java.lang.AssertionError" message="expected [4] but found [2]">
                <![CDATA[java.lang.AssertionError: expected [4] but found [2]
                org.testng.Assert.fail(Assert.java:110)org.testng.Assert.failNotEquals(Assert.java:1577)org.testng.Assert.assertEqualsImpl(Assert.java:149)org.testng.Assert.assertEquals(Assert.java:131)org.testng.Assert.assertEquals(Assert.java:1418)org.testng.Assert.assertEquals(Assert.java:1382)org.testng.Assert.assertEquals(Assert.java:1428)FacturialTest.testFactorial(FacturialTest.java:110)java.base/jdk.internal.reflect.DirectMethodHandleAccessor.invoke(DirectMethodHandleAccessor.java:104)java.base/java.lang.reflect.Method.invoke(Method.java:578)org.testng.internal.invokers.MethodInvocationHelper.invokeMethod(MethodInvocationHelper.java:139)org.testng.internal.invokers.TestInvoker.invokeMethod(TestInvoker.java:677)org.testng.internal.invokers.TestInvoker.invokeTestMethod(TestInvoker.java:221)org.testng.internal.invokers.MethodRunner.runInSequence(MethodRunner.java:50)org.testng.internal.invokers.TestInvoker$MethodInvocationAgent.invoke(TestInvoker.java:969)org.testng.internal.invokers.TestInvoker.invokeTestMethods(TestInvoker.java:194)org.testng.internal.invokers.TestMethodWorker.invokeTestMethods(TestMethodWorker.java:148)org.testng.internal.invokers.TestMethodWorker.run(TestMethodWorker.java:128)java.base/java.util.ArrayList.forEach(ArrayList.java:1511)org.testng.TestRunner.privateRun(TestRunner.java:829)org.testng.TestRunner.run(TestRunner.java:602)org.testng.SuiteRunner.runTest(SuiteRunner.java:437)org.testng.SuiteRunner$SuiteWorker.run(SuiteRunner.java:475)org.testng.internal.thread.ThreadUtil.lambda$execute$0(ThreadUtil.java:58)java.base/java.util.concurrent.FutureTask.run(FutureTask.java:317)java.base/java.util.concurrent.ThreadPoolExecutor.runWorker(ThreadPoolExecutor.java:1144)java.base/java.util.concurrent.ThreadPoolExecutor$Worker.run(ThreadPoolExecutor.java:642)java.base/java.lang.Thread.run(Thread.java:1623)
]]>
            </failure>
    </testcase>
            <testcase
                name="testFactorial"
                time="0.001"
                classname="FacturialTest">

            <failure type="java.lang.AssertionError" message="expected [4] but found [2]">
                <![CDATA[java.lang.AssertionError: expected [4] but found [2]
                org.testng.Assert.fail(Assert.java:110)org.testng.Assert.failNotEquals(Assert.java:1577)org.testng.Assert.assertEqualsImpl(Assert.java:149)org.testng.Assert.assertEquals(Assert.java:131)org.testng.Assert.assertEquals(Assert.java:1418)org.testng.Assert.assertEquals(Assert.java:1382)org.testng.Assert.assertEquals(Assert.java:1428)FacturialTest.testFactorial(FacturialTest.java:110)java.base/jdk.internal.reflect.DirectMethodHandleAccessor.invoke(DirectMethodHandleAccessor.java:104)java.base/java.lang.reflect.Method.invoke(Method.java:578)org.testng.internal.invokers.MethodInvocationHelper.invokeMethod(MethodInvocationHelper.java:139)org.testng.internal.invokers.TestInvoker.invokeMethod(TestInvoker.java:677)org.testng.internal.invokers.TestInvoker.invokeTestMethod(TestInvoker.java:221)org.testng.internal.invokers.MethodRunner.runInSequence(MethodRunner.java:50)org.testng.internal.invokers.TestInvoker$MethodInvocationAgent.invoke(TestInvoker.java:969)org.testng.internal.invokers.TestInvoker.invokeTestMethods(TestInvoker.java:194)org.testng.internal.invokers.TestMethodWorker.invokeTestMethods(TestMethodWorker.java:148)org.testng.internal.invokers.TestMethodWorker.run(TestMethodWorker.java:128)java.base/java.util.ArrayList.forEach(ArrayList.java:1511)org.testng.TestRunner.privateRun(TestRunner.java:829)org.testng.TestRunner.run(TestRunner.java:602)org.testng.SuiteRunner.runTest(SuiteRunner.java:437)org.testng.SuiteRunner$SuiteWorker.run(SuiteRunner.java:475)org.testng.internal.thread.ThreadUtil.lambda$execute$0(ThreadUtil.java:58)java.base/java.util.concurrent.FutureTask.run(FutureTask.java:317)java.base/java.util.concurrent.ThreadPoolExecutor.runWorker(ThreadPoolExecutor.java:1144)java.base/java.util.concurrent.ThreadPoolExecutor$Worker.run(ThreadPoolExecutor.java:642)java.base/java.lang.Thread.run(Thread.java:1623)
]]>
            </failure>
    </testcase>
            <testcase
                name="testFactorial"
                time="0.001"
                classname="FacturialTest">

            <failure type="java.lang.AssertionError" message="expected [4] but found [2]">
                <![CDATA[java.lang.AssertionError: expected [4] but found [2]
                org.testng.Assert.fail(Assert.java:110)org.testng.Assert.failNotEquals(Assert.java:1577)org.testng.Assert.assertEqualsImpl(Assert.java:149)org.testng.Assert.assertEquals(Assert.java:131)org.testng.Assert.assertEquals(Assert.java:1418)org.testng.Assert.assertEquals(Assert.java:1382)org.testng.Assert.assertEquals(Assert.java:1428)FacturialTest.testFactorial(FacturialTest.java:110)java.base/jdk.internal.reflect.DirectMethodHandleAccessor.invoke(DirectMethodHandleAccessor.java:104)java.base/java.lang.reflect.Method.invoke(Method.java:578)org.testng.internal.invokers.MethodInvocationHelper.invokeMethod(MethodInvocationHelper.java:139)org.testng.internal.invokers.TestInvoker.invokeMethod(TestInvoker.java:677)org.testng.internal.invokers.TestInvoker.invokeTestMethod(TestInvoker.java:221)org.testng.internal.invokers.MethodRunner.runInSequence(MethodRunner.java:50)org.testng.internal.invokers.TestInvoker$MethodInvocationAgent.invoke(TestInvoker.java:969)org.testng.internal.invokers.TestInvoker.invokeTestMethods(TestInvoker.java:194)org.testng.internal.invokers.TestMethodWorker.invokeTestMethods(TestMethodWorker.java:148)org.testng.internal.invokers.TestMethodWorker.run(TestMethodWorker.java:128)java.base/java.util.ArrayList.forEach(ArrayList.java:1511)org.testng.TestRunner.privateRun(TestRunner.java:829)org.testng.TestRunner.run(TestRunner.java:602)org.testng.SuiteRunner.runTest(SuiteRunner.java:437)org.testng.SuiteRunner$SuiteWorker.run(SuiteRunner.java:475)org.testng.internal.thread.ThreadUtil.lambda$execute$0(ThreadUtil.java:58)java.base/java.util.concurrent.FutureTask.run(FutureTask.java:317)java.base/java.util.concurrent.ThreadPoolExecutor.runWorker(ThreadPoolExecutor.java:1144)java.base/java.util.concurrent.ThreadPoolExecutor$Worker.run(ThreadPoolExecutor.java:642)java.base/java.lang.Thread.run(Thread.java:1623)
]]>
            </failure>
    </testcase>
            <testcase
                name="testFactorial"
                time="0.001"
                classname="FacturialTest">

            <failure type="java.lang.AssertionError" message="expected [4] but found [2]">
                <![CDATA[java.lang.AssertionError: expected [4] but found [2]
                org.testng.Assert.fail(Assert.java:110)org.testng.Assert.failNotEquals(Assert.java:1577)org.testng.Assert.assertEqualsImpl(Assert.java:149)org.testng.Assert.assertEquals(Assert.java:131)org.testng.Assert.assertEquals(Assert.java:1418)org.testng.Assert.assertEquals(Assert.java:1382)org.testng.Assert.assertEquals(Assert.java:1428)FacturialTest.testFactorial(FacturialTest.java:110)java.base/jdk.internal.reflect.DirectMethodHandleAccessor.invoke(DirectMethodHandleAccessor.java:104)java.base/java.lang.reflect.Method.invoke(Method.java:578)org.testng.internal.invokers.MethodInvocationHelper.invokeMethod(MethodInvocationHelper.java:139)org.testng.internal.invokers.TestInvoker.invokeMethod(TestInvoker.java:677)org.testng.internal.invokers.TestInvoker.invokeTestMethod(TestInvoker.java:221)org.testng.internal.invokers.MethodRunner.runInSequence(MethodRunner.java:50)org.testng.internal.invokers.TestInvoker$MethodInvocationAgent.invoke(TestInvoker.java:969)org.testng.internal.invokers.TestInvoker.invokeTestMethods(TestInvoker.java:194)org.testng.internal.invokers.TestMethodWorker.invokeTestMethods(TestMethodWorker.java:148)org.testng.internal.invokers.TestMethodWorker.run(TestMethodWorker.java:128)java.base/java.util.ArrayList.forEach(ArrayList.java:1511)org.testng.TestRunner.privateRun(TestRunner.java:829)org.testng.TestRunner.run(TestRunner.java:602)org.testng.SuiteRunner.runTest(SuiteRunner.java:437)org.testng.SuiteRunner$SuiteWorker.run(SuiteRunner.java:475)org.testng.internal.thread.ThreadUtil.lambda$execute$0(ThreadUtil.java:58)java.base/java.util.concurrent.FutureTask.run(FutureTask.java:317)java.base/java.util.concurrent.ThreadPoolExecutor.runWorker(ThreadPoolExecutor.java:1144)java.base/java.util.concurrent.ThreadPoolExecutor$Worker.run(ThreadPoolExecutor.java:642)java.base/java.lang.Thread.run(Thread.java:1623)
]]>
            </failure>
    </testcase>
            <testcase
                name="testFactorial"
                time="0.000"
                classname="FacturialTest">

            <failure type="java.lang.AssertionError" message="expected [4] but found [2]">
                <![CDATA[java.lang.AssertionError: expected [4] but found [2]
                org.testng.Assert.fail(Assert.java:110)org.testng.Assert.failNotEquals(Assert.java:1577)org.testng.Assert.assertEqualsImpl(Assert.java:149)org.testng.Assert.assertEquals(Assert.java:131)org.testng.Assert.assertEquals(Assert.java:1418)org.testng.Assert.assertEquals(Assert.java:1382)org.testng.Assert.assertEquals(Assert.java:1428)FacturialTest.testFactorial(FacturialTest.java:110)java.base/jdk.internal.reflect.DirectMethodHandleAccessor.invoke(DirectMethodHandleAccessor.java:104)java.base/java.lang.reflect.Method.invoke(Method.java:578)org.testng.internal.invokers.MethodInvocationHelper.invokeMethod(MethodInvocationHelper.java:139)org.testng.internal.invokers.TestInvoker.invokeMethod(TestInvoker.java:677)org.testng.internal.invokers.TestInvoker.invokeTestMethod(TestInvoker.java:221)org.testng.internal.invokers.MethodRunner.runInSequence(MethodRunner.java:50)org.testng.internal.invokers.TestInvoker$MethodInvocationAgent.invoke(TestInvoker.java:969)org.testng.internal.invokers.TestInvoker.invokeTestMethods(TestInvoker.java:194)org.testng.internal.invokers.TestMethodWorker.invokeTestMethods(TestMethodWorker.java:148)org.testng.internal.invokers.TestMethodWorker.run(TestMethodWorker.java:128)java.base/java.util.ArrayList.forEach(ArrayList.java:1511)org.testng.TestRunner.privateRun(TestRunner.java:829)org.testng.TestRunner.run(TestRunner.java:602)org.testng.SuiteRunner.runTest(SuiteRunner.java:437)org.testng.SuiteRunner$SuiteWorker.run(SuiteRunner.java:475)org.testng.internal.thread.ThreadUtil.lambda$execute$0(ThreadUtil.java:58)java.base/java.util.concurrent.FutureTask.run(FutureTask.java:317)java.base/java.util.concurrent.ThreadPoolExecutor.runWorker(ThreadPoolExecutor.java:1144)java.base/java.util.concurrent.ThreadPoolExecutor$Worker.run(ThreadPoolExecutor.java:642)java.base/java.lang.Thread.run(Thread.java:1623)
]]>
            </failure>
    </testcase>
            <testcase
                name="testFactorial"
                time="0.001"
                classname="FacturialTest">

            <failure type="java.lang.AssertionError" message="expected [4] but found [2]">
                <![CDATA[java.lang.AssertionError: expected [4] but found [2]
                org.testng.Assert.fail(Assert.java:110)org.testng.Assert.failNotEquals(Assert.java:1577)org.testng.Assert.assertEqualsImpl(Assert.java:149)org.testng.Assert.assertEquals(Assert.java:131)org.testng.Assert.assertEquals(Assert.java:1418)org.testng.Assert.assertEquals(Assert.java:1382)org.testng.Assert.assertEquals(Assert.java:1428)FacturialTest.testFactorial(FacturialTest.java:110)java.base/jdk.internal.reflect.DirectMethodHandleAccessor.invoke(DirectMethodHandleAccessor.java:104)java.base/java.lang.reflect.Method.invoke(Method.java:578)org.testng.internal.invokers.MethodInvocationHelper.invokeMethod(MethodInvocationHelper.java:139)org.testng.internal.invokers.TestInvoker.invokeMethod(TestInvoker.java:677)org.testng.internal.invokers.TestInvoker.invokeTestMethod(TestInvoker.java:221)org.testng.internal.invokers.MethodRunner.runInSequence(MethodRunner.java:50)org.testng.internal.invokers.TestInvoker$MethodInvocationAgent.invoke(TestInvoker.java:969)org.testng.internal.invokers.TestInvoker.invokeTestMethods(TestInvoker.java:194)org.testng.internal.invokers.TestMethodWorker.invokeTestMethods(TestMethodWorker.java:148)org.testng.internal.invokers.TestMethodWorker.run(TestMethodWorker.java:128)java.base/java.util.ArrayList.forEach(ArrayList.java:1511)org.testng.TestRunner.privateRun(TestRunner.java:829)org.testng.TestRunner.run(TestRunner.java:602)org.testng.SuiteRunner.runTest(SuiteRunner.java:437)org.testng.SuiteRunner$SuiteWorker.run(SuiteRunner.java:475)org.testng.internal.thread.ThreadUtil.lambda$execute$0(ThreadUtil.java:58)java.base/java.util.concurrent.FutureTask.run(FutureTask.java:317)java.base/java.util.concurrent.ThreadPoolExecutor.runWorker(ThreadPoolExecutor.java:1144)java.base/java.util.concurrent.ThreadPoolExecutor$Worker.run(ThreadPoolExecutor.java:642)java.base/java.lang.Thread.run(Thread.java:1623)
]]>
            </failure>
    </testcase>
            <testcase
                name="testFactorial"
                time="0.001"
                classname="FacturialTest">

            <failure type="java.lang.AssertionError" message="expected [4] but found [2]">
                <![CDATA[java.lang.AssertionError: expected [4] but found [2]
                org.testng.Assert.fail(Assert.java:110)org.testng.Assert.failNotEquals(Assert.java:1577)org.testng.Assert.assertEqualsImpl(Assert.java:149)org.testng.Assert.assertEquals(Assert.java:131)org.testng.Assert.assertEquals(Assert.java:1418)org.testng.Assert.assertEquals(Assert.java:1382)org.testng.Assert.assertEquals(Assert.java:1428)FacturialTest.testFactorial(FacturialTest.java:110)java.base/jdk.internal.reflect.DirectMethodHandleAccessor.invoke(DirectMethodHandleAccessor.java:104)java.base/java.lang.reflect.Method.invoke(Method.java:578)org.testng.internal.invokers.MethodInvocationHelper.invokeMethod(MethodInvocationHelper.java:139)org.testng.internal.invokers.TestInvoker.invokeMethod(TestInvoker.java:677)org.testng.internal.invokers.TestInvoker.invokeTestMethod(TestInvoker.java:221)org.testng.internal.invokers.MethodRunner.runInSequence(MethodRunner.java:50)org.testng.internal.invokers.TestInvoker$MethodInvocationAgent.invoke(TestInvoker.java:969)org.testng.internal.invokers.TestInvoker.invokeTestMethods(TestInvoker.java:194)org.testng.internal.invokers.TestMethodWorker.invokeTestMethods(TestMethodWorker.java:148)org.testng.internal.invokers.TestMethodWorker.run(TestMethodWorker.java:128)java.base/java.util.ArrayList.forEach(ArrayList.java:1511)org.testng.TestRunner.privateRun(TestRunner.java:829)org.testng.TestRunner.run(TestRunner.java:602)org.testng.SuiteRunner.runTest(SuiteRunner.java:437)org.testng.SuiteRunner$SuiteWorker.run(SuiteRunner.java:475)org.testng.internal.thread.ThreadUtil.lambda$execute$0(ThreadUtil.java:58)java.base/java.util.concurrent.FutureTask.run(FutureTask.java:317)java.base/java.util.concurrent.ThreadPoolExecutor.runWorker(ThreadPoolExecutor.java:1144)java.base/java.util.concurrent.ThreadPoolExecutor$Worker.run(ThreadPoolExecutor.java:642)java.base/java.lang.Thread.run(Thread.java:1623)
]]>
            </failure>
    </testcase>
            <testcase
                name="testFactorial"
                time="0.001"
                classname="FacturialTest">

            <failure type="java.lang.AssertionError" message="expected [4] but found [2]">
                <![CDATA[java.lang.AssertionError: expected [4] but found [2]
                org.testng.Assert.fail(Assert.java:110)org.testng.Assert.failNotEquals(Assert.java:1577)org.testng.Assert.assertEqualsImpl(Assert.java:149)org.testng.Assert.assertEquals(Assert.java:131)org.testng.Assert.assertEquals(Assert.java:1418)org.testng.Assert.assertEquals(Assert.java:1382)org.testng.Assert.assertEquals(Assert.java:1428)FacturialTest.testFactorial(FacturialTest.java:110)java.base/jdk.internal.reflect.DirectMethodHandleAccessor.invoke(DirectMethodHandleAccessor.java:104)java.base/java.lang.reflect.Method.invoke(Method.java:578)org.testng.internal.invokers.MethodInvocationHelper.invokeMethod(MethodInvocationHelper.java:139)org.testng.internal.invokers.TestInvoker.invokeMethod(TestInvoker.java:677)org.testng.internal.invokers.TestInvoker.invokeTestMethod(TestInvoker.java:221)org.testng.internal.invokers.MethodRunner.runInSequence(MethodRunner.java:50)org.testng.internal.invokers.TestInvoker$MethodInvocationAgent.invoke(TestInvoker.java:969)org.testng.internal.invokers.TestInvoker.invokeTestMethods(TestInvoker.java:194)org.testng.internal.invokers.TestMethodWorker.invokeTestMethods(TestMethodWorker.java:148)org.testng.internal.invokers.TestMethodWorker.run(TestMethodWorker.java:128)java.base/java.util.ArrayList.forEach(ArrayList.java:1511)org.testng.TestRunner.privateRun(TestRunner.java:829)org.testng.TestRunner.run(TestRunner.java:602)org.testng.SuiteRunner.runTest(SuiteRunner.java:437)org.testng.SuiteRunner$SuiteWorker.run(SuiteRunner.java:475)org.testng.internal.thread.ThreadUtil.lambda$execute$0(ThreadUtil.java:58)java.base/java.util.concurrent.FutureTask.run(FutureTask.java:317)java.base/java.util.concurrent.ThreadPoolExecutor.runWorker(ThreadPoolExecutor.java:1144)java.base/java.util.concurrent.ThreadPoolExecutor$Worker.run(ThreadPoolExecutor.java:642)java.base/java.lang.Thread.run(Thread.java:1623)
]]>
            </failure>
    </testcase>
            <testcase
                name="testFactorial"
                time="0.001"
                classname="FacturialTest">

            <failure type="java.lang.AssertionError" message="expected [4] but found [2]">
                <![CDATA[java.lang.AssertionError: expected [4] but found [2]
                org.testng.Assert.fail(Assert.java:110)org.testng.Assert.failNotEquals(Assert.java:1577)org.testng.Assert.assertEqualsImpl(Assert.java:149)org.testng.Assert.assertEquals(Assert.java:131)org.testng.Assert.assertEquals(Assert.java:1418)org.testng.Assert.assertEquals(Assert.java:1382)org.testng.Assert.assertEquals(Assert.java:1428)FacturialTest.testFactorial(FacturialTest.java:110)java.base/jdk.internal.reflect.DirectMethodHandleAccessor.invoke(DirectMethodHandleAccessor.java:104)java.base/java.lang.reflect.Method.invoke(Method.java:578)org.testng.internal.invokers.MethodInvocationHelper.invokeMethod(MethodInvocationHelper.java:139)org.testng.internal.invokers.TestInvoker.invokeMethod(TestInvoker.java:677)org.testng.internal.invokers.TestInvoker.invokeTestMethod(TestInvoker.java:221)org.testng.internal.invokers.MethodRunner.runInSequence(MethodRunner.java:50)org.testng.internal.invokers.TestInvoker$MethodInvocationAgent.invoke(TestInvoker.java:969)org.testng.internal.invokers.TestInvoker.invokeTestMethods(TestInvoker.java:194)org.testng.internal.invokers.TestMethodWorker.invokeTestMethods(TestMethodWorker.java:148)org.testng.internal.invokers.TestMethodWorker.run(TestMethodWorker.java:128)java.base/java.util.ArrayList.forEach(ArrayList.java:1511)org.testng.TestRunner.privateRun(TestRunner.java:829)org.testng.TestRunner.run(TestRunner.java:602)org.testng.SuiteRunner.runTest(SuiteRunner.java:437)org.testng.SuiteRunner$SuiteWorker.run(SuiteRunner.java:475)org.testng.internal.thread.ThreadUtil.lambda$execute$0(ThreadUtil.java:58)java.base/java.util.concurrent.FutureTask.run(FutureTask.java:317)java.base/java.util.concurrent.ThreadPoolExecutor.runWorker(ThreadPoolExecutor.java:1144)java.base/java.util.concurrent.ThreadPoolExecutor$Worker.run(ThreadPoolExecutor.java:642)java.base/java.lang.Thread.run(Thread.java:1623)
]]>
            </failure>
    </testcase>
            <testcase
                name="testFactorial"
                time="0.001"
                classname="FacturialTest">

            <failure type="java.lang.AssertionError" message="expected [4] but found [2]">
                <![CDATA[java.lang.AssertionError: expected [4] but found [2]
                org.testng.Assert.fail(Assert.java:110)org.testng.Assert.failNotEquals(Assert.java:1577)org.testng.Assert.assertEqualsImpl(Assert.java:149)org.testng.Assert.assertEquals(Assert.java:131)org.testng.Assert.assertEquals(Assert.java:1418)org.testng.Assert.assertEquals(Assert.java:1382)org.testng.Assert.assertEquals(Assert.java:1428)FacturialTest.testFactorial(FacturialTest.java:110)java.base/jdk.internal.reflect.DirectMethodHandleAccessor.invoke(DirectMethodHandleAccessor.java:104)java.base/java.lang.reflect.Method.invoke(Method.java:578)org.testng.internal.invokers.MethodInvocationHelper.invokeMethod(MethodInvocationHelper.java:139)org.testng.internal.invokers.TestInvoker.invokeMethod(TestInvoker.java:677)org.testng.internal.invokers.TestInvoker.invokeTestMethod(TestInvoker.java:221)org.testng.internal.invokers.MethodRunner.runInSequence(MethodRunner.java:50)org.testng.internal.invokers.TestInvoker$MethodInvocationAgent.invoke(TestInvoker.java:969)org.testng.internal.invokers.TestInvoker.invokeTestMethods(TestInvoker.java:194)org.testng.internal.invokers.TestMethodWorker.invokeTestMethods(TestMethodWorker.java:148)org.testng.internal.invokers.TestMethodWorker.run(TestMethodWorker.java:128)java.base/java.util.ArrayList.forEach(ArrayList.java:1511)org.testng.TestRunner.privateRun(TestRunner.java:829)org.testng.TestRunner.run(TestRunner.java:602)org.testng.SuiteRunner.runTest(SuiteRunner.java:437)org.testng.SuiteRunner$SuiteWorker.run(SuiteRunner.java:475)org.testng.internal.thread.ThreadUtil.lambda$execute$0(ThreadUtil.java:58)java.base/java.util.concurrent.FutureTask.run(FutureTask.java:317)java.base/java.util.concurrent.ThreadPoolExecutor.runWorker(ThreadPoolExecutor.java:1144)java.base/java.util.concurrent.ThreadPoolExecutor$Worker.run(ThreadPoolExecutor.java:642)java.base/java.lang.Thread.run(Thread.java:1623)
]]>
            </failure>
    </testcase>
            <testcase
                name="testFactorial"
                time="0.000"
                classname="FacturialTest">

            <failure type="java.lang.AssertionError" message="expected [4] but found [2]">
                <![CDATA[java.lang.AssertionError: expected [4] but found [2]
                org.testng.Assert.fail(Assert.java:110)org.testng.Assert.failNotEquals(Assert.java:1577)org.testng.Assert.assertEqualsImpl(Assert.java:149)org.testng.Assert.assertEquals(Assert.java:131)org.testng.Assert.assertEquals(Assert.java:1418)org.testng.Assert.assertEquals(Assert.java:1382)org.testng.Assert.assertEquals(Assert.java:1428)FacturialTest.testFactorial(FacturialTest.java:110)java.base/jdk.internal.reflect.DirectMethodHandleAccessor.invoke(DirectMethodHandleAccessor.java:104)java.base/java.lang.reflect.Method.invoke(Method.java:578)org.testng.internal.invokers.MethodInvocationHelper.invokeMethod(MethodInvocationHelper.java:139)org.testng.internal.invokers.TestInvoker.invokeMethod(TestInvoker.java:677)org.testng.internal.invokers.TestInvoker.invokeTestMethod(TestInvoker.java:221)org.testng.internal.invokers.MethodRunner.runInSequence(MethodRunner.java:50)org.testng.internal.invokers.TestInvoker$MethodInvocationAgent.invoke(TestInvoker.java:969)org.testng.internal.invokers.TestInvoker.invokeTestMethods(TestInvoker.java:194)org.testng.internal.invokers.TestMethodWorker.invokeTestMethods(TestMethodWorker.java:148)org.testng.internal.invokers.TestMethodWorker.run(TestMethodWorker.java:128)java.base/java.util.ArrayList.forEach(ArrayList.java:1511)org.testng.TestRunner.privateRun(TestRunner.java:829)org.testng.TestRunner.run(TestRunner.java:602)org.testng.SuiteRunner.runTest(SuiteRunner.java:437)org.testng.SuiteRunner$SuiteWorker.run(SuiteRunner.java:475)org.testng.internal.thread.ThreadUtil.lambda$execute$0(ThreadUtil.java:58)java.base/java.util.concurrent.FutureTask.run(FutureTask.java:317)java.base/java.util.concurrent.ThreadPoolExecutor.runWorker(ThreadPoolExecutor.java:1144)java.base/java.util.concurrent.ThreadPoolExecutor$Worker.run(ThreadPoolExecutor.java:642)java.base/java.lang.Thread.run(Thread.java:1623)
]]>
            </failure>
    </testcase>
            <testcase
                name="testFactorial"
                time="0.001"
                classname="FacturialTest">

            <failure type="java.lang.AssertionError" message="expected [4] but found [2]">
                <![CDATA[java.lang.AssertionError: expected [4] but found [2]
                org.testng.Assert.fail(Assert.java:110)org.testng.Assert.failNotEquals(Assert.java:1577)org.testng.Assert.assertEqualsImpl(Assert.java:149)org.testng.Assert.assertEquals(Assert.java:131)org.testng.Assert.assertEquals(Assert.java:1418)org.testng.Assert.assertEquals(Assert.java:1382)org.testng.Assert.assertEquals(Assert.java:1428)FacturialTest.testFactorial(FacturialTest.java:110)java.base/jdk.internal.reflect.DirectMethodHandleAccessor.invoke(DirectMethodHandleAccessor.java:104)java.base/java.lang.reflect.Method.invoke(Method.java:578)org.testng.internal.invokers.MethodInvocationHelper.invokeMethod(MethodInvocationHelper.java:139)org.testng.internal.invokers.TestInvoker.invokeMethod(TestInvoker.java:677)org.testng.internal.invokers.TestInvoker.invokeTestMethod(TestInvoker.java:221)org.testng.internal.invokers.MethodRunner.runInSequence(MethodRunner.java:50)org.testng.internal.invokers.TestInvoker$MethodInvocationAgent.invoke(TestInvoker.java:969)org.testng.internal.invokers.TestInvoker.invokeTestMethods(TestInvoker.java:194)org.testng.internal.invokers.TestMethodWorker.invokeTestMethods(TestMethodWorker.java:148)org.testng.internal.invokers.TestMethodWorker.run(TestMethodWorker.java:128)java.base/java.util.ArrayList.forEach(ArrayList.java:1511)org.testng.TestRunner.privateRun(TestRunner.java:829)org.testng.TestRunner.run(TestRunner.java:602)org.testng.SuiteRunner.runTest(SuiteRunner.java:437)org.testng.SuiteRunner$SuiteWorker.run(SuiteRunner.java:475)org.testng.internal.thread.ThreadUtil.lambda$execute$0(ThreadUtil.java:58)java.base/java.util.concurrent.FutureTask.run(FutureTask.java:317)java.base/java.util.concurrent.ThreadPoolExecutor.runWorker(ThreadPoolExecutor.java:1144)java.base/java.util.concurrent.ThreadPoolExecutor$Worker.run(ThreadPoolExecutor.java:642)java.base/java.lang.Thread.run(Thread.java:1623)
]]>
            </failure>
    </testcase>
            <testcase
                name="testFactorial"
                time="0.003"
                classname="FacturialTest">

            <failure type="java.lang.AssertionError" message="expected [4] but found [2]">
                <![CDATA[java.lang.AssertionError: expected [4] but found [2]
                org.testng.Assert.fail(Assert.java:110)org.testng.Assert.failNotEquals(Assert.java:1577)org.testng.Assert.assertEqualsImpl(Assert.java:149)org.testng.Assert.assertEquals(Assert.java:131)org.testng.Assert.assertEquals(Assert.java:1418)org.testng.Assert.assertEquals(Assert.java:1382)org.testng.Assert.assertEquals(Assert.java:1428)FacturialTest.testFactorial(FacturialTest.java:110)java.base/jdk.internal.reflect.DirectMethodHandleAccessor.invoke(DirectMethodHandleAccessor.java:104)java.base/java.lang.reflect.Method.invoke(Method.java:578)org.testng.internal.invokers.MethodInvocationHelper.invokeMethod(MethodInvocationHelper.java:139)org.testng.internal.invokers.TestInvoker.invokeMethod(TestInvoker.java:677)org.testng.internal.invokers.TestInvoker.invokeTestMethod(TestInvoker.java:221)org.testng.internal.invokers.MethodRunner.runInSequence(MethodRunner.java:50)org.testng.internal.invokers.TestInvoker$MethodInvocationAgent.invoke(TestInvoker.java:969)org.testng.internal.invokers.TestInvoker.invokeTestMethods(TestInvoker.java:194)org.testng.internal.invokers.TestMethodWorker.invokeTestMethods(TestMethodWorker.java:148)org.testng.internal.invokers.TestMethodWorker.run(TestMethodWorker.java:128)java.base/java.util.ArrayList.forEach(ArrayList.java:1511)org.testng.TestRunner.privateRun(TestRunner.java:829)org.testng.TestRunner.run(TestRunner.java:602)org.testng.SuiteRunner.runTest(SuiteRunner.java:437)org.testng.SuiteRunner$SuiteWorker.run(SuiteRunner.java:475)org.testng.internal.thread.ThreadUtil.lambda$execute$0(ThreadUtil.java:58)java.base/java.util.concurrent.FutureTask.run(FutureTask.java:317)java.base/java.util.concurrent.ThreadPoolExecutor.runWorker(ThreadPoolExecutor.java:1144)java.base/java.util.concurrent.ThreadPoolExecutor$Worker.run(ThreadPoolExecutor.java:642)java.base/java.lang.Thread.run(Thread.java:1623)
]]>
            </failure>
    </testcase>
            <testcase
                name="testFactorial"
                time="0.001"
                classname="FacturialTest">

            <failure type="java.lang.AssertionError" message="expected [4] but found [2]">
                <![CDATA[java.lang.AssertionError: expected [4] but found [2]
                org.testng.Assert.fail(Assert.java:110)org.testng.Assert.failNotEquals(Assert.java:1577)org.testng.Assert.assertEqualsImpl(Assert.java:149)org.testng.Assert.assertEquals(Assert.java:131)org.testng.Assert.assertEquals(Assert.java:1418)org.testng.Assert.assertEquals(Assert.java:1382)org.testng.Assert.assertEquals(Assert.java:1428)FacturialTest.testFactorial(FacturialTest.java:110)java.base/jdk.internal.reflect.DirectMethodHandleAccessor.invoke(DirectMethodHandleAccessor.java:104)java.base/java.lang.reflect.Method.invoke(Method.java:578)org.testng.internal.invokers.MethodInvocationHelper.invokeMethod(MethodInvocationHelper.java:139)org.testng.internal.invokers.TestInvoker.invokeMethod(TestInvoker.java:677)org.testng.internal.invokers.TestInvoker.invokeTestMethod(TestInvoker.java:221)org.testng.internal.invokers.MethodRunner.runInSequence(MethodRunner.java:50)org.testng.internal.invokers.TestInvoker$MethodInvocationAgent.invoke(TestInvoker.java:969)org.testng.internal.invokers.TestInvoker.invokeTestMethods(TestInvoker.java:194)org.testng.internal.invokers.TestMethodWorker.invokeTestMethods(TestMethodWorker.java:148)org.testng.internal.invokers.TestMethodWorker.run(TestMethodWorker.java:128)java.base/java.util.ArrayList.forEach(ArrayList.java:1511)org.testng.TestRunner.privateRun(TestRunner.java:829)org.testng.TestRunner.run(TestRunner.java:602)org.testng.SuiteRunner.runTest(SuiteRunner.java:437)org.testng.SuiteRunner$SuiteWorker.run(SuiteRunner.java:475)org.testng.internal.thread.ThreadUtil.lambda$execute$0(ThreadUtil.java:58)java.base/java.util.concurrent.FutureTask.run(FutureTask.java:317)java.base/java.util.concurrent.ThreadPoolExecutor.runWorker(ThreadPoolExecutor.java:1144)java.base/java.util.concurrent.ThreadPoolExecutor$Worker.run(ThreadPoolExecutor.java:642)java.base/java.lang.Thread.run(Thread.java:1623)
]]>
            </failure>
    </testcase>
            <testcase
                name="testFactorial"
                time="0.003"
                classname="FacturialTest">

            <failure type="java.lang.AssertionError" message="expected [4] but found [2]">
                <![CDATA[java.lang.AssertionError: expected [4] but found [2]
                org.testng.Assert.fail(Assert.java:110)org.testng.Assert.failNotEquals(Assert.java:1577)org.testng.Assert.assertEqualsImpl(Assert.java:149)org.testng.Assert.assertEquals(Assert.java:131)org.testng.Assert.assertEquals(Assert.java:1418)org.testng.Assert.assertEquals(Assert.java:1382)org.testng.Assert.assertEquals(Assert.java:1428)FacturialTest.testFactorial(FacturialTest.java:110)java.base/jdk.internal.reflect.DirectMethodHandleAccessor.invoke(DirectMethodHandleAccessor.java:104)java.base/java.lang.reflect.Method.invoke(Method.java:578)org.testng.internal.invokers.MethodInvocationHelper.invokeMethod(MethodInvocationHelper.java:139)org.testng.internal.invokers.TestInvoker.invokeMethod(TestInvoker.java:677)org.testng.internal.invokers.TestInvoker.invokeTestMethod(TestInvoker.java:221)org.testng.internal.invokers.MethodRunner.runInSequence(MethodRunner.java:50)org.testng.internal.invokers.TestInvoker$MethodInvocationAgent.invoke(TestInvoker.java:969)org.testng.internal.invokers.TestInvoker.invokeTestMethods(TestInvoker.java:194)org.testng.internal.invokers.TestMethodWorker.invokeTestMethods(TestMethodWorker.java:148)org.testng.internal.invokers.TestMethodWorker.run(TestMethodWorker.java:128)java.base/java.util.ArrayList.forEach(ArrayList.java:1511)org.testng.TestRunner.privateRun(TestRunner.java:829)org.testng.TestRunner.run(TestRunner.java:602)org.testng.SuiteRunner.runTest(SuiteRunner.java:437)org.testng.SuiteRunner$SuiteWorker.run(SuiteRunner.java:475)org.testng.internal.thread.ThreadUtil.lambda$execute$0(ThreadUtil.java:58)java.base/java.util.concurrent.FutureTask.run(FutureTask.java:317)java.base/java.util.concurrent.ThreadPoolExecutor.runWorker(ThreadPoolExecutor.java:1144)java.base/java.util.concurrent.ThreadPoolExecutor$Worker.run(ThreadPoolExecutor.java:642)java.base/java.lang.Thread.run(Thread.java:1623)
]]>
            </failure>
    </testcase>
            <testcase
                name="testFactorial"
                time="0.000"
                classname="FacturialTest">

            <failure type="java.lang.AssertionError" message="expected [4] but found [2]">
                <![CDATA[java.lang.AssertionError: expected [4] but found [2]
                org.testng.Assert.fail(Assert.java:110)org.testng.Assert.failNotEquals(Assert.java:1577)org.testng.Assert.assertEqualsImpl(Assert.java:149)org.testng.Assert.assertEquals(Assert.java:131)org.testng.Assert.assertEquals(Assert.java:1418)org.testng.Assert.assertEquals(Assert.java:1382)org.testng.Assert.assertEquals(Assert.java:1428)FacturialTest.testFactorial(FacturialTest.java:110)java.base/jdk.internal.reflect.DirectMethodHandleAccessor.invoke(DirectMethodHandleAccessor.java:104)java.base/java.lang.reflect.Method.invoke(Method.java:578)org.testng.internal.invokers.MethodInvocationHelper.invokeMethod(MethodInvocationHelper.java:139)org.testng.internal.invokers.TestInvoker.invokeMethod(TestInvoker.java:677)org.testng.internal.invokers.TestInvoker.invokeTestMethod(TestInvoker.java:221)org.testng.internal.invokers.MethodRunner.runInSequence(MethodRunner.java:50)org.testng.internal.invokers.TestInvoker$MethodInvocationAgent.invoke(TestInvoker.java:969)org.testng.internal.invokers.TestInvoker.invokeTestMethods(TestInvoker.java:194)org.testng.internal.invokers.TestMethodWorker.invokeTestMethods(TestMethodWorker.java:148)org.testng.internal.invokers.TestMethodWorker.run(TestMethodWorker.java:128)java.base/java.util.ArrayList.forEach(ArrayList.java:1511)org.testng.TestRunner.privateRun(TestRunner.java:829)org.testng.TestRunner.run(TestRunner.java:602)org.testng.SuiteRunner.runTest(SuiteRunner.java:437)org.testng.SuiteRunner$SuiteWorker.run(SuiteRunner.java:475)org.testng.internal.thread.ThreadUtil.lambda$execute$0(ThreadUtil.java:58)java.base/java.util.concurrent.FutureTask.run(FutureTask.java:317)java.base/java.util.concurrent.ThreadPoolExecutor.runWorker(ThreadPoolExecutor.java:1144)java.base/java.util.concurrent.ThreadPoolExecutor$Worker.run(ThreadPoolExecutor.java:642)java.base/java.lang.Thread.run(Thread.java:1623)
]]>
            </failure>
    </testcase>
            <testcase
                name="testFactorial"
                time="0.003"
                classname="FacturialTest">

            <failure type="java.lang.AssertionError" message="expected [4] but found [2]">
                <![CDATA[java.lang.AssertionError: expected [4] but found [2]
                org.testng.Assert.fail(Assert.java:110)org.testng.Assert.failNotEquals(Assert.java:1577)org.testng.Assert.assertEqualsImpl(Assert.java:149)org.testng.Assert.assertEquals(Assert.java:131)org.testng.Assert.assertEquals(Assert.java:1418)org.testng.Assert.assertEquals(Assert.java:1382)org.testng.Assert.assertEquals(Assert.java:1428)FacturialTest.testFactorial(FacturialTest.java:110)java.base/jdk.internal.reflect.DirectMethodHandleAccessor.invoke(DirectMethodHandleAccessor.java:104)java.base/java.lang.reflect.Method.invoke(Method.java:578)org.testng.internal.invokers.MethodInvocationHelper.invokeMethod(MethodInvocationHelper.java:139)org.testng.internal.invokers.TestInvoker.invokeMethod(TestInvoker.java:677)org.testng.internal.invokers.TestInvoker.invokeTestMethod(TestInvoker.java:221)org.testng.internal.invokers.MethodRunner.runInSequence(MethodRunner.java:50)org.testng.internal.invokers.TestInvoker$MethodInvocationAgent.invoke(TestInvoker.java:969)org.testng.internal.invokers.TestInvoker.invokeTestMethods(TestInvoker.java:194)org.testng.internal.invokers.TestMethodWorker.invokeTestMethods(TestMethodWorker.java:148)org.testng.internal.invokers.TestMethodWorker.run(TestMethodWorker.java:128)java.base/java.util.ArrayList.forEach(ArrayList.java:1511)org.testng.TestRunner.privateRun(TestRunner.java:829)org.testng.TestRunner.run(TestRunner.java:602)org.testng.SuiteRunner.runTest(SuiteRunner.java:437)org.testng.SuiteRunner$SuiteWorker.run(SuiteRunner.java:475)org.testng.internal.thread.ThreadUtil.lambda$execute$0(ThreadUtil.java:58)java.base/java.util.concurrent.FutureTask.run(FutureTask.java:317)java.base/java.util.concurrent.ThreadPoolExecutor.runWorker(ThreadPoolExecutor.java:1144)java.base/java.util.concurrent.ThreadPoolExecutor$Worker.run(ThreadPoolExecutor.java:642)java.base/java.lang.Thread.run(Thread.java:1623)
]]>
            </failure>
    </testcase>
            <testcase
                name="testFactorial"
                time="0.001"
                classname="FacturialTest">

            <failure type="java.lang.AssertionError" message="expected [4] but found [2]">
                <![CDATA[java.lang.AssertionError: expected [4] but found [2]
                org.testng.Assert.fail(Assert.java:110)org.testng.Assert.failNotEquals(Assert.java:1577)org.testng.Assert.assertEqualsImpl(Assert.java:149)org.testng.Assert.assertEquals(Assert.java:131)org.testng.Assert.assertEquals(Assert.java:1418)org.testng.Assert.assertEquals(Assert.java:1382)org.testng.Assert.assertEquals(Assert.java:1428)FacturialTest.testFactorial(FacturialTest.java:110)java.base/jdk.internal.reflect.DirectMethodHandleAccessor.invoke(DirectMethodHandleAccessor.java:104)java.base/java.lang.reflect.Method.invoke(Method.java:578)org.testng.internal.invokers.MethodInvocationHelper.invokeMethod(MethodInvocationHelper.java:139)org.testng.internal.invokers.TestInvoker.invokeMethod(TestInvoker.java:677)org.testng.internal.invokers.TestInvoker.invokeTestMethod(TestInvoker.java:221)org.testng.internal.invokers.MethodRunner.runInSequence(MethodRunner.java:50)org.testng.internal.invokers.TestInvoker$MethodInvocationAgent.invoke(TestInvoker.java:969)org.testng.internal.invokers.TestInvoker.invokeTestMethods(TestInvoker.java:194)org.testng.internal.invokers.TestMethodWorker.invokeTestMethods(TestMethodWorker.java:148)org.testng.internal.invokers.TestMethodWorker.run(TestMethodWorker.java:128)java.base/java.util.ArrayList.forEach(ArrayList.java:1511)org.testng.TestRunner.privateRun(TestRunner.java:829)org.testng.TestRunner.run(TestRunner.java:602)org.testng.SuiteRunner.runTest(SuiteRunner.java:437)org.testng.SuiteRunner$SuiteWorker.run(SuiteRunner.java:475)org.testng.internal.thread.ThreadUtil.lambda$execute$0(ThreadUtil.java:58)java.base/java.util.concurrent.FutureTask.run(FutureTask.java:317)java.base/java.util.concurrent.ThreadPoolExecutor.runWorker(ThreadPoolExecutor.java:1144)java.base/java.util.concurrent.ThreadPoolExecutor$Worker.run(ThreadPoolExecutor.java:642)java.base/java.lang.Thread.run(Thread.java:1623)
]]>
            </failure>
    </testcase>
            <testcase
                name="testFactorial"
                time="0.001"
                classname="FacturialTest">

            <failure type="java.lang.AssertionError" message="expected [4] but found [2]">
                <![CDATA[java.lang.AssertionError: expected [4] but found [2]
                org.testng.Assert.fail(Assert.java:110)org.testng.Assert.failNotEquals(Assert.java:1577)org.testng.Assert.assertEqualsImpl(Assert.java:149)org.testng.Assert.assertEquals(Assert.java:131)org.testng.Assert.assertEquals(Assert.java:1418)org.testng.Assert.assertEquals(Assert.java:1382)org.testng.Assert.assertEquals(Assert.java:1428)FacturialTest.testFactorial(FacturialTest.java:110)java.base/jdk.internal.reflect.DirectMethodHandleAccessor.invoke(DirectMethodHandleAccessor.java:104)java.base/java.lang.reflect.Method.invoke(Method.java:578)org.testng.internal.invokers.MethodInvocationHelper.invokeMethod(MethodInvocationHelper.java:139)org.testng.internal.invokers.TestInvoker.invokeMethod(TestInvoker.java:677)org.testng.internal.invokers.TestInvoker.invokeTestMethod(TestInvoker.java:221)org.testng.internal.invokers.MethodRunner.runInSequence(MethodRunner.java:50)org.testng.internal.invokers.TestInvoker$MethodInvocationAgent.invoke(TestInvoker.java:969)org.testng.internal.invokers.TestInvoker.invokeTestMethods(TestInvoker.java:194)org.testng.internal.invokers.TestMethodWorker.invokeTestMethods(TestMethodWorker.java:148)org.testng.internal.invokers.TestMethodWorker.run(TestMethodWorker.java:128)java.base/java.util.ArrayList.forEach(ArrayList.java:1511)org.testng.TestRunner.privateRun(TestRunner.java:829)org.testng.TestRunner.run(TestRunner.java:602)org.testng.SuiteRunner.runTest(SuiteRunner.java:437)org.testng.SuiteRunner$SuiteWorker.run(SuiteRunner.java:475)org.testng.internal.thread.ThreadUtil.lambda$execute$0(ThreadUtil.java:58)java.base/java.util.concurrent.FutureTask.run(FutureTask.java:317)java.base/java.util.concurrent.ThreadPoolExecutor.runWorker(ThreadPoolExecutor.java:1144)java.base/java.util.concurrent.ThreadPoolExecutor$Worker.run(ThreadPoolExecutor.java:642)java.base/java.lang.Thread.run(Thread.java:1623)
]]>
            </failure>
    </testcase>
            <testcase
                name="testFactorial"
                time="0.002"
                classname="FacturialTest">

            <failure type="java.lang.AssertionError" message="expected [4] but found [2]">
                <![CDATA[java.lang.AssertionError: expected [4] but found [2]
                org.testng.Assert.fail(Assert.java:110)org.testng.Assert.failNotEquals(Assert.java:1577)org.testng.Assert.assertEqualsImpl(Assert.java:149)org.testng.Assert.assertEquals(Assert.java:131)org.testng.Assert.assertEquals(Assert.java:1418)org.testng.Assert.assertEquals(Assert.java:1382)org.testng.Assert.assertEquals(Assert.java:1428)FacturialTest.testFactorial(FacturialTest.java:110)java.base/jdk.internal.reflect.DirectMethodHandleAccessor.invoke(DirectMethodHandleAccessor.java:104)java.base/java.lang.reflect.Method.invoke(Method.java:578)org.testng.internal.invokers.MethodInvocationHelper.invokeMethod(MethodInvocationHelper.java:139)org.testng.internal.invokers.TestInvoker.invokeMethod(TestInvoker.java:677)org.testng.internal.invokers.TestInvoker.invokeTestMethod(TestInvoker.java:221)org.testng.internal.invokers.MethodRunner.runInSequence(MethodRunner.java:50)org.testng.internal.invokers.TestInvoker$MethodInvocationAgent.invoke(TestInvoker.java:969)org.testng.internal.invokers.TestInvoker.invokeTestMethods(TestInvoker.java:194)org.testng.internal.invokers.TestMethodWorker.invokeTestMethods(TestMethodWorker.java:148)org.testng.internal.invokers.TestMethodWorker.run(TestMethodWorker.java:128)java.base/java.util.ArrayList.forEach(ArrayList.java:1511)org.testng.TestRunner.privateRun(TestRunner.java:829)org.testng.TestRunner.run(TestRunner.java:602)org.testng.SuiteRunner.runTest(SuiteRunner.java:437)org.testng.SuiteRunner$SuiteWorker.run(SuiteRunner.java:475)org.testng.internal.thread.ThreadUtil.lambda$execute$0(ThreadUtil.java:58)java.base/java.util.concurrent.FutureTask.run(FutureTask.java:317)java.base/java.util.concurrent.ThreadPoolExecutor.runWorker(ThreadPoolExecutor.java:1144)java.base/java.util.concurrent.ThreadPoolExecutor$Worker.run(ThreadPoolExecutor.java:642)java.base/java.lang.Thread.run(Thread.java:1623)
]]>
            </failure>
    </testcase>
            <testcase
                name="testFactorial"
                time="0.001"
                classname="FacturialTest">

            <failure type="java.lang.AssertionError" message="expected [4] but found [2]">
                <![CDATA[java.lang.AssertionError: expected [4] but found [2]
                org.testng.Assert.fail(Assert.java:110)org.testng.Assert.failNotEquals(Assert.java:1577)org.testng.Assert.assertEqualsImpl(Assert.java:149)org.testng.Assert.assertEquals(Assert.java:131)org.testng.Assert.assertEquals(Assert.java:1418)org.testng.Assert.assertEquals(Assert.java:1382)org.testng.Assert.assertEquals(Assert.java:1428)FacturialTest.testFactorial(FacturialTest.java:110)java.base/jdk.internal.reflect.DirectMethodHandleAccessor.invoke(DirectMethodHandleAccessor.java:104)java.base/java.lang.reflect.Method.invoke(Method.java:578)org.testng.internal.invokers.MethodInvocationHelper.invokeMethod(MethodInvocationHelper.java:139)org.testng.internal.invokers.TestInvoker.invokeMethod(TestInvoker.java:677)org.testng.internal.invokers.TestInvoker.invokeTestMethod(TestInvoker.java:221)org.testng.internal.invokers.MethodRunner.runInSequence(MethodRunner.java:50)org.testng.internal.invokers.TestInvoker$MethodInvocationAgent.invoke(TestInvoker.java:969)org.testng.internal.invokers.TestInvoker.invokeTestMethods(TestInvoker.java:194)org.testng.internal.invokers.TestMethodWorker.invokeTestMethods(TestMethodWorker.java:148)org.testng.internal.invokers.TestMethodWorker.run(TestMethodWorker.java:128)java.base/java.util.ArrayList.forEach(ArrayList.java:1511)org.testng.TestRunner.privateRun(TestRunner.java:829)org.testng.TestRunner.run(TestRunner.java:602)org.testng.SuiteRunner.runTest(SuiteRunner.java:437)org.testng.SuiteRunner$SuiteWorker.run(SuiteRunner.java:475)org.testng.internal.thread.ThreadUtil.lambda$execute$0(ThreadUtil.java:58)java.base/java.util.concurrent.FutureTask.run(FutureTask.java:317)java.base/java.util.concurrent.ThreadPoolExecutor.runWorker(ThreadPoolExecutor.java:1144)java.base/java.util.concurrent.ThreadPoolExecutor$Worker.run(ThreadPoolExecutor.java:642)java.base/java.lang.Thread.run(Thread.java:1623)
]]>
            </failure>
    </testcase>
            <testcase
                name="testFactorial"
                time="0.002"
                classname="FacturialTest">

            <failure type="java.lang.AssertionError" message="expected [4] but found [2]">
                <![CDATA[java.lang.AssertionError: expected [4] but found [2]
                org.testng.Assert.fail(Assert.java:110)org.testng.Assert.failNotEquals(Assert.java:1577)org.testng.Assert.assertEqualsImpl(Assert.java:149)org.testng.Assert.assertEquals(Assert.java:131)org.testng.Assert.assertEquals(Assert.java:1418)org.testng.Assert.assertEquals(Assert.java:1382)org.testng.Assert.assertEquals(Assert.java:1428)FacturialTest.testFactorial(FacturialTest.java:110)java.base/jdk.internal.reflect.DirectMethodHandleAccessor.invoke(DirectMethodHandleAccessor.java:104)java.base/java.lang.reflect.Method.invoke(Method.java:578)org.testng.internal.invokers.MethodInvocationHelper.invokeMethod(MethodInvocationHelper.java:139)org.testng.internal.invokers.TestInvoker.invokeMethod(TestInvoker.java:677)org.testng.internal.invokers.TestInvoker.invokeTestMethod(TestInvoker.java:221)org.testng.internal.invokers.MethodRunner.runInSequence(MethodRunner.java:50)org.testng.internal.invokers.TestInvoker$MethodInvocationAgent.invoke(TestInvoker.java:969)org.testng.internal.invokers.TestInvoker.invokeTestMethods(TestInvoker.java:194)org.testng.internal.invokers.TestMethodWorker.invokeTestMethods(TestMethodWorker.java:148)org.testng.internal.invokers.TestMethodWorker.run(TestMethodWorker.java:128)java.base/java.util.ArrayList.forEach(ArrayList.java:1511)org.testng.TestRunner.privateRun(TestRunner.java:829)org.testng.TestRunner.run(TestRunner.java:602)org.testng.SuiteRunner.runTest(SuiteRunner.java:437)org.testng.SuiteRunner$SuiteWorker.run(SuiteRunner.java:475)org.testng.internal.thread.ThreadUtil.lambda$execute$0(ThreadUtil.java:58)java.base/java.util.concurrent.FutureTask.run(FutureTask.java:317)java.base/java.util.concurrent.ThreadPoolExecutor.runWorker(ThreadPoolExecutor.java:1144)java.base/java.util.concurrent.ThreadPoolExecutor$Worker.run(ThreadPoolExecutor.java:642)java.base/java.lang.Thread.run(Thread.java:1623)
]]>
            </failure>
    </testcase>
            <testcase
                name="testFactorial"
                time="0.004"
                classname="FacturialTest">

            <failure type="java.lang.AssertionError" message="expected [4] but found [2]">
                <![CDATA[java.lang.AssertionError: expected [4] but found [2]
                org.testng.Assert.fail(Assert.java:110)org.testng.Assert.failNotEquals(Assert.java:1577)org.testng.Assert.assertEqualsImpl(Assert.java:149)org.testng.Assert.assertEquals(Assert.java:131)org.testng.Assert.assertEquals(Assert.java:1418)org.testng.Assert.assertEquals(Assert.java:1382)org.testng.Assert.assertEquals(Assert.java:1428)FacturialTest.testFactorial(FacturialTest.java:110)java.base/jdk.internal.reflect.DirectMethodHandleAccessor.invoke(DirectMethodHandleAccessor.java:104)java.base/java.lang.reflect.Method.invoke(Method.java:578)org.testng.internal.invokers.MethodInvocationHelper.invokeMethod(MethodInvocationHelper.java:139)org.testng.internal.invokers.TestInvoker.invokeMethod(TestInvoker.java:677)org.testng.internal.invokers.TestInvoker.invokeTestMethod(TestInvoker.java:221)org.testng.internal.invokers.MethodRunner.runInSequence(MethodRunner.java:50)org.testng.internal.invokers.TestInvoker$MethodInvocationAgent.invoke(TestInvoker.java:969)org.testng.internal.invokers.TestInvoker.invokeTestMethods(TestInvoker.java:194)org.testng.internal.invokers.TestMethodWorker.invokeTestMethods(TestMethodWorker.java:148)org.testng.internal.invokers.TestMethodWorker.run(TestMethodWorker.java:128)java.base/java.util.ArrayList.forEach(ArrayList.java:1511)org.testng.TestRunner.privateRun(TestRunner.java:829)org.testng.TestRunner.run(TestRunner.java:602)org.testng.SuiteRunner.runTest(SuiteRunner.java:437)org.testng.SuiteRunner$SuiteWorker.run(SuiteRunner.java:475)org.testng.internal.thread.ThreadUtil.lambda$execute$0(ThreadUtil.java:58)java.base/java.util.concurrent.FutureTask.run(FutureTask.java:317)java.base/java.util.concurrent.ThreadPoolExecutor.runWorker(ThreadPoolExecutor.java:1144)java.base/java.util.concurrent.ThreadPoolExecutor$Worker.run(ThreadPoolExecutor.java:642)java.base/java.lang.Thread.run(Thread.java:1623)
]]>
            </failure>
    </testcase>
            <testcase
                name="testFactorial"
                time="0.002"
                classname="FacturialTest">

            <failure type="java.lang.AssertionError" message="expected [4] but found [2]">
                <![CDATA[java.lang.AssertionError: expected [4] but found [2]
                org.testng.Assert.fail(Assert.java:110)org.testng.Assert.failNotEquals(Assert.java:1577)org.testng.Assert.assertEqualsImpl(Assert.java:149)org.testng.Assert.assertEquals(Assert.java:131)org.testng.Assert.assertEquals(Assert.java:1418)org.testng.Assert.assertEquals(Assert.java:1382)org.testng.Assert.assertEquals(Assert.java:1428)FacturialTest.testFactorial(FacturialTest.java:110)java.base/jdk.internal.reflect.DirectMethodHandleAccessor.invoke(DirectMethodHandleAccessor.java:104)java.base/java.lang.reflect.Method.invoke(Method.java:578)org.testng.internal.invokers.MethodInvocationHelper.invokeMethod(MethodInvocationHelper.java:139)org.testng.internal.invokers.TestInvoker.invokeMethod(TestInvoker.java:677)org.testng.internal.invokers.TestInvoker.invokeTestMethod(TestInvoker.java:221)org.testng.internal.invokers.MethodRunner.runInSequence(MethodRunner.java:50)org.testng.internal.invokers.TestInvoker$MethodInvocationAgent.invoke(TestInvoker.java:969)org.testng.internal.invokers.TestInvoker.invokeTestMethods(TestInvoker.java:194)org.testng.internal.invokers.TestMethodWorker.invokeTestMethods(TestMethodWorker.java:148)org.testng.internal.invokers.TestMethodWorker.run(TestMethodWorker.java:128)java.base/java.util.ArrayList.forEach(ArrayList.java:1511)org.testng.TestRunner.privateRun(TestRunner.java:829)org.testng.TestRunner.run(TestRunner.java:602)org.testng.SuiteRunner.runTest(SuiteRunner.java:437)org.testng.SuiteRunner$SuiteWorker.run(SuiteRunner.java:475)org.testng.internal.thread.ThreadUtil.lambda$execute$0(ThreadUtil.java:58)java.base/java.util.concurrent.FutureTask.run(FutureTask.java:317)java.base/java.util.concurrent.ThreadPoolExecutor.runWorker(ThreadPoolExecutor.java:1144)java.base/java.util.concurrent.ThreadPoolExecutor$Worker.run(ThreadPoolExecutor.java:642)java.base/java.lang.Thread.run(Thread.java:1623)
]]>
            </failure>
    </testcase>
            <testcase
                name="testFactorial"
                time="0.002"
                classname="FacturialTest">

            <failure type="java.lang.AssertionError" message="expected [4] but found [2]">
                <![CDATA[java.lang.AssertionError: expected [4] but found [2]
                org.testng.Assert.fail(Assert.java:110)org.testng.Assert.failNotEquals(Assert.java:1577)org.testng.Assert.assertEqualsImpl(Assert.java:149)org.testng.Assert.assertEquals(Assert.java:131)org.testng.Assert.assertEquals(Assert.java:1418)org.testng.Assert.assertEquals(Assert.java:1382)org.testng.Assert.assertEquals(Assert.java:1428)FacturialTest.testFactorial(FacturialTest.java:110)java.base/jdk.internal.reflect.DirectMethodHandleAccessor.invoke(DirectMethodHandleAccessor.java:104)java.base/java.lang.reflect.Method.invoke(Method.java:578)org.testng.internal.invokers.MethodInvocationHelper.invokeMethod(MethodInvocationHelper.java:139)org.testng.internal.invokers.TestInvoker.invokeMethod(TestInvoker.java:677)org.testng.internal.invokers.TestInvoker.invokeTestMethod(TestInvoker.java:221)org.testng.internal.invokers.MethodRunner.runInSequence(MethodRunner.java:50)org.testng.internal.invokers.TestInvoker$MethodInvocationAgent.invoke(TestInvoker.java:969)org.testng.internal.invokers.TestInvoker.invokeTestMethods(TestInvoker.java:194)org.testng.internal.invokers.TestMethodWorker.invokeTestMethods(TestMethodWorker.java:148)org.testng.internal.invokers.TestMethodWorker.run(TestMethodWorker.java:128)java.base/java.util.ArrayList.forEach(ArrayList.java:1511)org.testng.TestRunner.privateRun(TestRunner.java:829)org.testng.TestRunner.run(TestRunner.java:602)org.testng.SuiteRunner.runTest(SuiteRunner.java:437)org.testng.SuiteRunner$SuiteWorker.run(SuiteRunner.java:475)org.testng.internal.thread.ThreadUtil.lambda$execute$0(ThreadUtil.java:58)java.base/java.util.concurrent.FutureTask.run(FutureTask.java:317)java.base/java.util.concurrent.ThreadPoolExecutor.runWorker(ThreadPoolExecutor.java:1144)java.base/java.util.concurrent.ThreadPoolExecutor$Worker.run(ThreadPoolExecutor.java:642)java.base/java.lang.Thread.run(Thread.java:1623)
]]>
            </failure>
    </testcase>
            <testcase
                name="testFactorial"
                time="0.002"
                classname="FacturialTest">

            <failure type="java.lang.AssertionError" message="expected [4] but found [2]">
                <![CDATA[java.lang.AssertionError: expected [4] but found [2]
                org.testng.Assert.fail(Assert.java:110)org.testng.Assert.failNotEquals(Assert.java:1577)org.testng.Assert.assertEqualsImpl(Assert.java:149)org.testng.Assert.assertEquals(Assert.java:131)org.testng.Assert.assertEquals(Assert.java:1418)org.testng.Assert.assertEquals(Assert.java:1382)org.testng.Assert.assertEquals(Assert.java:1428)FacturialTest.testFactorial(FacturialTest.java:110)java.base/jdk.internal.reflect.DirectMethodHandleAccessor.invoke(DirectMethodHandleAccessor.java:104)java.base/java.lang.reflect.Method.invoke(Method.java:578)org.testng.internal.invokers.MethodInvocationHelper.invokeMethod(MethodInvocationHelper.java:139)org.testng.internal.invokers.TestInvoker.invokeMethod(TestInvoker.java:677)org.testng.internal.invokers.TestInvoker.invokeTestMethod(TestInvoker.java:221)org.testng.internal.invokers.MethodRunner.runInSequence(MethodRunner.java:50)org.testng.internal.invokers.TestInvoker$MethodInvocationAgent.invoke(TestInvoker.java:969)org.testng.internal.invokers.TestInvoker.invokeTestMethods(TestInvoker.java:194)org.testng.internal.invokers.TestMethodWorker.invokeTestMethods(TestMethodWorker.java:148)org.testng.internal.invokers.TestMethodWorker.run(TestMethodWorker.java:128)java.base/java.util.ArrayList.forEach(ArrayList.java:1511)org.testng.TestRunner.privateRun(TestRunner.java:829)org.testng.TestRunner.run(TestRunner.java:602)org.testng.SuiteRunner.runTest(SuiteRunner.java:437)org.testng.SuiteRunner$SuiteWorker.run(SuiteRunner.java:475)org.testng.internal.thread.ThreadUtil.lambda$execute$0(ThreadUtil.java:58)java.base/java.util.concurrent.FutureTask.run(FutureTask.java:317)java.base/java.util.concurrent.ThreadPoolExecutor.runWorker(ThreadPoolExecutor.java:1144)java.base/java.util.concurrent.ThreadPoolExecutor$Worker.run(ThreadPoolExecutor.java:642)java.base/java.lang.Thread.run(Thread.java:1623)
]]>
            </failure>
    </testcase>
            <testcase
                name="testFactorial"
                time="0.002"
                classname="FacturialTest">

            <failure type="java.lang.AssertionError" message="expected [4] but found [2]">
                <![CDATA[java.lang.AssertionError: expected [4] but found [2]
                org.testng.Assert.fail(Assert.java:110)org.testng.Assert.failNotEquals(Assert.java:1577)org.testng.Assert.assertEqualsImpl(Assert.java:149)org.testng.Assert.assertEquals(Assert.java:131)org.testng.Assert.assertEquals(Assert.java:1418)org.testng.Assert.assertEquals(Assert.java:1382)org.testng.Assert.assertEquals(Assert.java:1428)FacturialTest.testFactorial(FacturialTest.java:110)java.base/jdk.internal.reflect.DirectMethodHandleAccessor.invoke(DirectMethodHandleAccessor.java:104)java.base/java.lang.reflect.Method.invoke(Method.java:578)org.testng.internal.invokers.MethodInvocationHelper.invokeMethod(MethodInvocationHelper.java:139)org.testng.internal.invokers.TestInvoker.invokeMethod(TestInvoker.java:677)org.testng.internal.invokers.TestInvoker.invokeTestMethod(TestInvoker.java:221)org.testng.internal.invokers.MethodRunner.runInSequence(MethodRunner.java:50)org.testng.internal.invokers.TestInvoker$MethodInvocationAgent.invoke(TestInvoker.java:969)org.testng.internal.invokers.TestInvoker.invokeTestMethods(TestInvoker.java:194)org.testng.internal.invokers.TestMethodWorker.invokeTestMethods(TestMethodWorker.java:148)org.testng.internal.invokers.TestMethodWorker.run(TestMethodWorker.java:128)java.base/java.util.ArrayList.forEach(ArrayList.java:1511)org.testng.TestRunner.privateRun(TestRunner.java:829)org.testng.TestRunner.run(TestRunner.java:602)org.testng.SuiteRunner.runTest(SuiteRunner.java:437)org.testng.SuiteRunner$SuiteWorker.run(SuiteRunner.java:475)org.testng.internal.thread.ThreadUtil.lambda$execute$0(ThreadUtil.java:58)java.base/java.util.concurrent.FutureTask.run(FutureTask.java:317)java.base/java.util.concurrent.ThreadPoolExecutor.runWorker(ThreadPoolExecutor.java:1144)java.base/java.util.concurrent.ThreadPoolExecutor$Worker.run(ThreadPoolExecutor.java:642)java.base/java.lang.Thread.run(Thread.java:1623)
]]>
            </failure>
    </testcase>
            <testcase
                name="testFactorial"
                time="0.001"
                classname="FacturialTest">

            <failure type="java.lang.AssertionError" message="expected [4] but found [2]">
                <![CDATA[java.lang.AssertionError: expected [4] but found [2]
                org.testng.Assert.fail(Assert.java:110)org.testng.Assert.failNotEquals(Assert.java:1577)org.testng.Assert.assertEqualsImpl(Assert.java:149)org.testng.Assert.assertEquals(Assert.java:131)org.testng.Assert.assertEquals(Assert.java:1418)org.testng.Assert.assertEquals(Assert.java:1382)org.testng.Assert.assertEquals(Assert.java:1428)FacturialTest.testFactorial(FacturialTest.java:110)java.base/jdk.internal.reflect.DirectMethodHandleAccessor.invoke(DirectMethodHandleAccessor.java:104)java.base/java.lang.reflect.Method.invoke(Method.java:578)org.testng.internal.invokers.MethodInvocationHelper.invokeMethod(MethodInvocationHelper.java:139)org.testng.internal.invokers.TestInvoker.invokeMethod(TestInvoker.java:677)org.testng.internal.invokers.TestInvoker.invokeTestMethod(TestInvoker.java:221)org.testng.internal.invokers.MethodRunner.runInSequence(MethodRunner.java:50)org.testng.internal.invokers.TestInvoker$MethodInvocationAgent.invoke(TestInvoker.java:969)org.testng.internal.invokers.TestInvoker.invokeTestMethods(TestInvoker.java:194)org.testng.internal.invokers.TestMethodWorker.invokeTestMethods(TestMethodWorker.java:148)org.testng.internal.invokers.TestMethodWorker.run(TestMethodWorker.java:128)java.base/java.util.ArrayList.forEach(ArrayList.java:1511)org.testng.TestRunner.privateRun(TestRunner.java:829)org.testng.TestRunner.run(TestRunner.java:602)org.testng.SuiteRunner.runTest(SuiteRunner.java:437)org.testng.SuiteRunner$SuiteWorker.run(SuiteRunner.java:475)org.testng.internal.thread.ThreadUtil.lambda$execute$0(ThreadUtil.java:58)java.base/java.util.concurrent.FutureTask.run(FutureTask.java:317)java.base/java.util.concurrent.ThreadPoolExecutor.runWorker(ThreadPoolExecutor.java:1144)java.base/java.util.concurrent.ThreadPoolExecutor$Worker.run(ThreadPoolExecutor.java:642)java.base/java.lang.Thread.run(Thread.java:1623)
]]>
            </failure>
    </testcase>
            <testcase
                name="testFactorial"
                time="0.001"
                classname="FacturialTest">

            <failure type="java.lang.AssertionError" message="expected [4] but found [2]">
                <![CDATA[java.lang.AssertionError: expected [4] but found [2]
                org.testng.Assert.fail(Assert.java:110)org.testng.Assert.failNotEquals(Assert.java:1577)org.testng.Assert.assertEqualsImpl(Assert.java:149)org.testng.Assert.assertEquals(Assert.java:131)org.testng.Assert.assertEquals(Assert.java:1418)org.testng.Assert.assertEquals(Assert.java:1382)org.testng.Assert.assertEquals(Assert.java:1428)FacturialTest.testFactorial(FacturialTest.java:110)java.base/jdk.internal.reflect.DirectMethodHandleAccessor.invoke(DirectMethodHandleAccessor.java:104)java.base/java.lang.reflect.Method.invoke(Method.java:578)org.testng.internal.invokers.MethodInvocationHelper.invokeMethod(MethodInvocationHelper.java:139)org.testng.internal.invokers.TestInvoker.invokeMethod(TestInvoker.java:677)org.testng.internal.invokers.TestInvoker.invokeTestMethod(TestInvoker.java:221)org.testng.internal.invokers.MethodRunner.runInSequence(MethodRunner.java:50)org.testng.internal.invokers.TestInvoker$MethodInvocationAgent.invoke(TestInvoker.java:969)org.testng.internal.invokers.TestInvoker.invokeTestMethods(TestInvoker.java:194)org.testng.internal.invokers.TestMethodWorker.invokeTestMethods(TestMethodWorker.java:148)org.testng.internal.invokers.TestMethodWorker.run(TestMethodWorker.java:128)java.base/java.util.ArrayList.forEach(ArrayList.java:1511)org.testng.TestRunner.privateRun(TestRunner.java:829)org.testng.TestRunner.run(TestRunner.java:602)org.testng.SuiteRunner.runTest(SuiteRunner.java:437)org.testng.SuiteRunner$SuiteWorker.run(SuiteRunner.java:475)org.testng.internal.thread.ThreadUtil.lambda$execute$0(ThreadUtil.java:58)java.base/java.util.concurrent.FutureTask.run(FutureTask.java:317)java.base/java.util.concurrent.ThreadPoolExecutor.runWorker(ThreadPoolExecutor.java:1144)java.base/java.util.concurrent.ThreadPoolExecutor$Worker.run(ThreadPoolExecutor.java:642)java.base/java.lang.Thread.run(Thread.java:1623)
]]>
            </failure>
    </testcase>
            <testcase
                name="testFactorial"
                time="0.002"
                classname="FacturialTest">

            <failure type="java.lang.AssertionError" message="expected [4] but found [2]">
                <![CDATA[java.lang.AssertionError: expected [4] but found [2]
                org.testng.Assert.fail(Assert.java:110)org.testng.Assert.failNotEquals(Assert.java:1577)org.testng.Assert.assertEqualsImpl(Assert.java:149)org.testng.Assert.assertEquals(Assert.java:131)org.testng.Assert.assertEquals(Assert.java:1418)org.testng.Assert.assertEquals(Assert.java:1382)org.testng.Assert.assertEquals(Assert.java:1428)FacturialTest.testFactorial(FacturialTest.java:110)java.base/jdk.internal.reflect.DirectMethodHandleAccessor.invoke(DirectMethodHandleAccessor.java:104)java.base/java.lang.reflect.Method.invoke(Method.java:578)org.testng.internal.invokers.MethodInvocationHelper.invokeMethod(MethodInvocationHelper.java:139)org.testng.internal.invokers.TestInvoker.invokeMethod(TestInvoker.java:677)org.testng.internal.invokers.TestInvoker.invokeTestMethod(TestInvoker.java:221)org.testng.internal.invokers.MethodRunner.runInSequence(MethodRunner.java:50)org.testng.internal.invokers.TestInvoker$MethodInvocationAgent.invoke(TestInvoker.java:969)org.testng.internal.invokers.TestInvoker.invokeTestMethods(TestInvoker.java:194)org.testng.internal.invokers.TestMethodWorker.invokeTestMethods(TestMethodWorker.java:148)org.testng.internal.invokers.TestMethodWorker.run(TestMethodWorker.java:128)java.base/java.util.ArrayList.forEach(ArrayList.java:1511)org.testng.TestRunner.privateRun(TestRunner.java:829)org.testng.TestRunner.run(TestRunner.java:602)org.testng.SuiteRunner.runTest(SuiteRunner.java:437)org.testng.SuiteRunner$SuiteWorker.run(SuiteRunner.java:475)org.testng.internal.thread.ThreadUtil.lambda$execute$0(ThreadUtil.java:58)java.base/java.util.concurrent.FutureTask.run(FutureTask.java:317)java.base/java.util.concurrent.ThreadPoolExecutor.runWorker(ThreadPoolExecutor.java:1144)java.base/java.util.concurrent.ThreadPoolExecutor$Worker.run(ThreadPoolExecutor.java:642)java.base/java.lang.Thread.run(Thread.java:1623)
]]>
            </failure>
    </testcase>
            <testcase
                name="testFactorial"
                time="0.005"
                classname="FacturialTest">

            <failure type="java.lang.AssertionError" message="expected [4] but found [2]">
                <![CDATA[java.lang.AssertionError: expected [4] but found [2]
                org.testng.Assert.fail(Assert.java:110)org.testng.Assert.failNotEquals(Assert.java:1577)org.testng.Assert.assertEqualsImpl(Assert.java:149)org.testng.Assert.assertEquals(Assert.java:131)org.testng.Assert.assertEquals(Assert.java:1418)org.testng.Assert.assertEquals(Assert.java:1382)org.testng.Assert.assertEquals(Assert.java:1428)FacturialTest.testFactorial(FacturialTest.java:110)java.base/jdk.internal.reflect.DirectMethodHandleAccessor.invoke(DirectMethodHandleAccessor.java:104)java.base/java.lang.reflect.Method.invoke(Method.java:578)org.testng.internal.invokers.MethodInvocationHelper.invokeMethod(MethodInvocationHelper.java:139)org.testng.internal.invokers.TestInvoker.invokeMethod(TestInvoker.java:677)org.testng.internal.invokers.TestInvoker.invokeTestMethod(TestInvoker.java:221)org.testng.internal.invokers.MethodRunner.runInSequence(MethodRunner.java:50)org.testng.internal.invokers.TestInvoker$MethodInvocationAgent.invoke(TestInvoker.java:969)org.testng.internal.invokers.TestInvoker.invokeTestMethods(TestInvoker.java:194)org.testng.internal.invokers.TestMethodWorker.invokeTestMethods(TestMethodWorker.java:148)org.testng.internal.invokers.TestMethodWorker.run(TestMethodWorker.java:128)java.base/java.util.ArrayList.forEach(ArrayList.java:1511)org.testng.TestRunner.privateRun(TestRunner.java:829)org.testng.TestRunner.run(TestRunner.java:602)org.testng.SuiteRunner.runTest(SuiteRunner.java:437)org.testng.SuiteRunner$SuiteWorker.run(SuiteRunner.java:475)org.testng.internal.thread.ThreadUtil.lambda$execute$0(ThreadUtil.java:58)java.base/java.util.concurrent.FutureTask.run(FutureTask.java:317)java.base/java.util.concurrent.ThreadPoolExecutor.runWorker(ThreadPoolExecutor.java:1144)java.base/java.util.concurrent.ThreadPoolExecutor$Worker.run(ThreadPoolExecutor.java:642)java.base/java.lang.Thread.run(Thread.java:1623)
]]>
            </failure>
    </testcase>
            <testcase
                name="testFactorial"
                time="0.001"
                classname="FacturialTest">

            <failure type="java.lang.AssertionError" message="expected [4] but found [2]">
                <![CDATA[java.lang.AssertionError: expected [4] but found [2]
                org.testng.Assert.fail(Assert.java:110)org.testng.Assert.failNotEquals(Assert.java:1577)org.testng.Assert.assertEqualsImpl(Assert.java:149)org.testng.Assert.assertEquals(Assert.java:131)org.testng.Assert.assertEquals(Assert.java:1418)org.testng.Assert.assertEquals(Assert.java:1382)org.testng.Assert.assertEquals(Assert.java:1428)FacturialTest.testFactorial(FacturialTest.java:110)java.base/jdk.internal.reflect.DirectMethodHandleAccessor.invoke(DirectMethodHandleAccessor.java:104)java.base/java.lang.reflect.Method.invoke(Method.java:578)org.testng.internal.invokers.MethodInvocationHelper.invokeMethod(MethodInvocationHelper.java:139)org.testng.internal.invokers.TestInvoker.invokeMethod(TestInvoker.java:677)org.testng.internal.invokers.TestInvoker.invokeTestMethod(TestInvoker.java:221)org.testng.internal.invokers.MethodRunner.runInSequence(MethodRunner.java:50)org.testng.internal.invokers.TestInvoker$MethodInvocationAgent.invoke(TestInvoker.java:969)org.testng.internal.invokers.TestInvoker.invokeTestMethods(TestInvoker.java:194)org.testng.internal.invokers.TestMethodWorker.invokeTestMethods(TestMethodWorker.java:148)org.testng.internal.invokers.TestMethodWorker.run(TestMethodWorker.java:128)java.base/java.util.ArrayList.forEach(ArrayList.java:1511)org.testng.TestRunner.privateRun(TestRunner.java:829)org.testng.TestRunner.run(TestRunner.java:602)org.testng.SuiteRunner.runTest(SuiteRunner.java:437)org.testng.SuiteRunner$SuiteWorker.run(SuiteRunner.java:475)org.testng.internal.thread.ThreadUtil.lambda$execute$0(ThreadUtil.java:58)java.base/java.util.concurrent.FutureTask.run(FutureTask.java:317)java.base/java.util.concurrent.ThreadPoolExecutor.runWorker(ThreadPoolExecutor.java:1144)java.base/java.util.concurrent.ThreadPoolExecutor$Worker.run(ThreadPoolExecutor.java:642)java.base/java.lang.Thread.run(Thread.java:1623)
]]>
            </failure>
    </testcase>
            <testcase
                name="testFactorial"
                time="0.002"
                classname="FacturialTest">

            <failure type="java.lang.AssertionError" message="expected [4] but found [2]">
                <![CDATA[java.lang.AssertionError: expected [4] but found [2]
                org.testng.Assert.fail(Assert.java:110)org.testng.Assert.failNotEquals(Assert.java:1577)org.testng.Assert.assertEqualsImpl(Assert.java:149)org.testng.Assert.assertEquals(Assert.java:131)org.testng.Assert.assertEquals(Assert.java:1418)org.testng.Assert.assertEquals(Assert.java:1382)org.testng.Assert.assertEquals(Assert.java:1428)FacturialTest.testFactorial(FacturialTest.java:110)java.base/jdk.internal.reflect.DirectMethodHandleAccessor.invoke(DirectMethodHandleAccessor.java:104)java.base/java.lang.reflect.Method.invoke(Method.java:578)org.testng.internal.invokers.MethodInvocationHelper.invokeMethod(MethodInvocationHelper.java:139)org.testng.internal.invokers.TestInvoker.invokeMethod(TestInvoker.java:677)org.testng.internal.invokers.TestInvoker.invokeTestMethod(TestInvoker.java:221)org.testng.internal.invokers.MethodRunner.runInSequence(MethodRunner.java:50)org.testng.internal.invokers.TestInvoker$MethodInvocationAgent.invoke(TestInvoker.java:969)org.testng.internal.invokers.TestInvoker.invokeTestMethods(TestInvoker.java:194)org.testng.internal.invokers.TestMethodWorker.invokeTestMethods(TestMethodWorker.java:148)org.testng.internal.invokers.TestMethodWorker.run(TestMethodWorker.java:128)java.base/java.util.ArrayList.forEach(ArrayList.java:1511)org.testng.TestRunner.privateRun(TestRunner.java:829)org.testng.TestRunner.run(TestRunner.java:602)org.testng.SuiteRunner.runTest(SuiteRunner.java:437)org.testng.SuiteRunner$SuiteWorker.run(SuiteRunner.java:475)org.testng.internal.thread.ThreadUtil.lambda$execute$0(ThreadUtil.java:58)java.base/java.util.concurrent.FutureTask.run(FutureTask.java:317)java.base/java.util.concurrent.ThreadPoolExecutor.runWorker(ThreadPoolExecutor.java:1144)java.base/java.util.concurrent.ThreadPoolExecutor$Worker.run(ThreadPoolExecutor.java:642)java.base/java.lang.Thread.run(Thread.java:1623)
]]>
            </failure>
    </testcase>
            <testcase
                name="testFactorial"
                time="0.001"
                classname="FacturialTest">

            <failure type="java.lang.AssertionError" message="expected [4] but found [2]">
                <![CDATA[java.lang.AssertionError: expected [4] but found [2]
                org.testng.Assert.fail(Assert.java:110)org.testng.Assert.failNotEquals(Assert.java:1577)org.testng.Assert.assertEqualsImpl(Assert.java:149)org.testng.Assert.assertEquals(Assert.java:131)org.testng.Assert.assertEquals(Assert.java:1418)org.testng.Assert.assertEquals(Assert.java:1382)org.testng.Assert.assertEquals(Assert.java:1428)FacturialTest.testFactorial(FacturialTest.java:110)java.base/jdk.internal.reflect.DirectMethodHandleAccessor.invoke(DirectMethodHandleAccessor.java:104)java.base/java.lang.reflect.Method.invoke(Method.java:578)org.testng.internal.invokers.MethodInvocationHelper.invokeMethod(MethodInvocationHelper.java:139)org.testng.internal.invokers.TestInvoker.invokeMethod(TestInvoker.java:677)org.testng.internal.invokers.TestInvoker.invokeTestMethod(TestInvoker.java:221)org.testng.internal.invokers.MethodRunner.runInSequence(MethodRunner.java:50)org.testng.internal.invokers.TestInvoker$MethodInvocationAgent.invoke(TestInvoker.java:969)org.testng.internal.invokers.TestInvoker.invokeTestMethods(TestInvoker.java:194)org.testng.internal.invokers.TestMethodWorker.invokeTestMethods(TestMethodWorker.java:148)org.testng.internal.invokers.TestMethodWorker.run(TestMethodWorker.java:128)java.base/java.util.ArrayList.forEach(ArrayList.java:1511)org.testng.TestRunner.privateRun(TestRunner.java:829)org.testng.TestRunner.run(TestRunner.java:602)org.testng.SuiteRunner.runTest(SuiteRunner.java:437)org.testng.SuiteRunner$SuiteWorker.run(SuiteRunner.java:475)org.testng.internal.thread.ThreadUtil.lambda$execute$0(ThreadUtil.java:58)java.base/java.util.concurrent.FutureTask.run(FutureTask.java:317)java.base/java.util.concurrent.ThreadPoolExecutor.runWorker(ThreadPoolExecutor.java:1144)java.base/java.util.concurrent.ThreadPoolExecutor$Worker.run(ThreadPoolExecutor.java:642)java.base/java.lang.Thread.run(Thread.java:1623)
]]>
            </failure>
    </testcase>
            <testcase
                name="testFactorial"
                time="0.001"
                classname="FacturialTest">

            <failure type="java.lang.AssertionError" message="expected [4] but found [2]">
                <![CDATA[java.lang.AssertionError: expected [4] but found [2]
                org.testng.Assert.fail(Assert.java:110)org.testng.Assert.failNotEquals(Assert.java:1577)org.testng.Assert.assertEqualsImpl(Assert.java:149)org.testng.Assert.assertEquals(Assert.java:131)org.testng.Assert.assertEquals(Assert.java:1418)org.testng.Assert.assertEquals(Assert.java:1382)org.testng.Assert.assertEquals(Assert.java:1428)FacturialTest.testFactorial(FacturialTest.java:110)java.base/jdk.internal.reflect.DirectMethodHandleAccessor.invoke(DirectMethodHandleAccessor.java:104)java.base/java.lang.reflect.Method.invoke(Method.java:578)org.testng.internal.invokers.MethodInvocationHelper.invokeMethod(MethodInvocationHelper.java:139)org.testng.internal.invokers.TestInvoker.invokeMethod(TestInvoker.java:677)org.testng.internal.invokers.TestInvoker.invokeTestMethod(TestInvoker.java:221)org.testng.internal.invokers.MethodRunner.runInSequence(MethodRunner.java:50)org.testng.internal.invokers.TestInvoker$MethodInvocationAgent.invoke(TestInvoker.java:969)org.testng.internal.invokers.TestInvoker.invokeTestMethods(TestInvoker.java:194)org.testng.internal.invokers.TestMethodWorker.invokeTestMethods(TestMethodWorker.java:148)org.testng.internal.invokers.TestMethodWorker.run(TestMethodWorker.java:128)java.base/java.util.ArrayList.forEach(ArrayList.java:1511)org.testng.TestRunner.privateRun(TestRunner.java:829)org.testng.TestRunner.run(TestRunner.java:602)org.testng.SuiteRunner.runTest(SuiteRunner.java:437)org.testng.SuiteRunner$SuiteWorker.run(SuiteRunner.java:475)org.testng.internal.thread.ThreadUtil.lambda$execute$0(ThreadUtil.java:58)java.base/java.util.concurrent.FutureTask.run(FutureTask.java:317)java.base/java.util.concurrent.ThreadPoolExecutor.runWorker(ThreadPoolExecutor.java:1144)java.base/java.util.concurrent.ThreadPoolExecutor$Worker.run(ThreadPoolExecutor.java:642)java.base/java.lang.Thread.run(Thread.java:1623)
]]>
            </failure>
    </testcase>
            <testcase
                name="testFactorial"
                time="0.001"
                classname="FacturialTest">

            <failure type="java.lang.AssertionError" message="expected [4] but found [2]">
                <![CDATA[java.lang.AssertionError: expected [4] but found [2]
                org.testng.Assert.fail(Assert.java:110)org.testng.Assert.failNotEquals(Assert.java:1577)org.testng.Assert.assertEqualsImpl(Assert.java:149)org.testng.Assert.assertEquals(Assert.java:131)org.testng.Assert.assertEquals(Assert.java:1418)org.testng.Assert.assertEquals(Assert.java:1382)org.testng.Assert.assertEquals(Assert.java:1428)FacturialTest.testFactorial(FacturialTest.java:110)java.base/jdk.internal.reflect.DirectMethodHandleAccessor.invoke(DirectMethodHandleAccessor.java:104)java.base/java.lang.reflect.Method.invoke(Method.java:578)org.testng.internal.invokers.MethodInvocationHelper.invokeMethod(MethodInvocationHelper.java:139)org.testng.internal.invokers.TestInvoker.invokeMethod(TestInvoker.java:677)org.testng.internal.invokers.TestInvoker.invokeTestMethod(TestInvoker.java:221)org.testng.internal.invokers.MethodRunner.runInSequence(MethodRunner.java:50)org.testng.internal.invokers.TestInvoker$MethodInvocationAgent.invoke(TestInvoker.java:969)org.testng.internal.invokers.TestInvoker.invokeTestMethods(TestInvoker.java:194)org.testng.internal.invokers.TestMethodWorker.invokeTestMethods(TestMethodWorker.java:148)org.testng.internal.invokers.TestMethodWorker.run(TestMethodWorker.java:128)java.base/java.util.ArrayList.forEach(ArrayList.java:1511)org.testng.TestRunner.privateRun(TestRunner.java:829)org.testng.TestRunner.run(TestRunner.java:602)org.testng.SuiteRunner.runTest(SuiteRunner.java:437)org.testng.SuiteRunner$SuiteWorker.run(SuiteRunner.java:475)org.testng.internal.thread.ThreadUtil.lambda$execute$0(ThreadUtil.java:58)java.base/java.util.concurrent.FutureTask.run(FutureTask.java:317)java.base/java.util.concurrent.ThreadPoolExecutor.runWorker(ThreadPoolExecutor.java:1144)java.base/java.util.concurrent.ThreadPoolExecutor$Worker.run(ThreadPoolExecutor.java:642)java.base/java.lang.Thread.run(Thread.java:1623)
]]>
            </failure>
    </testcase>
            <testcase
                name="testFactorial"
                time="0.001"
                classname="FacturialTest">

            <failure type="java.lang.AssertionError" message="expected [4] but found [2]">
                <![CDATA[java.lang.AssertionError: expected [4] but found [2]
                org.testng.Assert.fail(Assert.java:110)org.testng.Assert.failNotEquals(Assert.java:1577)org.testng.Assert.assertEqualsImpl(Assert.java:149)org.testng.Assert.assertEquals(Assert.java:131)org.testng.Assert.assertEquals(Assert.java:1418)org.testng.Assert.assertEquals(Assert.java:1382)org.testng.Assert.assertEquals(Assert.java:1428)FacturialTest.testFactorial(FacturialTest.java:110)java.base/jdk.internal.reflect.DirectMethodHandleAccessor.invoke(DirectMethodHandleAccessor.java:104)java.base/java.lang.reflect.Method.invoke(Method.java:578)org.testng.internal.invokers.MethodInvocationHelper.invokeMethod(MethodInvocationHelper.java:139)org.testng.internal.invokers.TestInvoker.invokeMethod(TestInvoker.java:677)org.testng.internal.invokers.TestInvoker.invokeTestMethod(TestInvoker.java:221)org.testng.internal.invokers.MethodRunner.runInSequence(MethodRunner.java:50)org.testng.internal.invokers.TestInvoker$MethodInvocationAgent.invoke(TestInvoker.java:969)org.testng.internal.invokers.TestInvoker.invokeTestMethods(TestInvoker.java:194)org.testng.internal.invokers.TestMethodWorker.invokeTestMethods(TestMethodWorker.java:148)org.testng.internal.invokers.TestMethodWorker.run(TestMethodWorker.java:128)java.base/java.util.ArrayList.forEach(ArrayList.java:1511)org.testng.TestRunner.privateRun(TestRunner.java:829)org.testng.TestRunner.run(TestRunner.java:602)org.testng.SuiteRunner.runTest(SuiteRunner.java:437)org.testng.SuiteRunner$SuiteWorker.run(SuiteRunner.java:475)org.testng.internal.thread.ThreadUtil.lambda$execute$0(ThreadUtil.java:58)java.base/java.util.concurrent.FutureTask.run(FutureTask.java:317)java.base/java.util.concurrent.ThreadPoolExecutor.runWorker(ThreadPoolExecutor.java:1144)java.base/java.util.concurrent.ThreadPoolExecutor$Worker.run(ThreadPoolExecutor.java:642)java.base/java.lang.Thread.run(Thread.java:1623)
]]>
            </failure>
    </testcase>
            <testcase
                name="testFactorial"
                time="0.001"
                classname="FacturialTest">

            <failure type="java.lang.AssertionError" message="expected [4] but found [2]">
                <![CDATA[java.lang.AssertionError: expected [4] but found [2]
                org.testng.Assert.fail(Assert.java:110)org.testng.Assert.failNotEquals(Assert.java:1577)org.testng.Assert.assertEqualsImpl(Assert.java:149)org.testng.Assert.assertEquals(Assert.java:131)org.testng.Assert.assertEquals(Assert.java:1418)org.testng.Assert.assertEquals(Assert.java:1382)org.testng.Assert.assertEquals(Assert.java:1428)FacturialTest.testFactorial(FacturialTest.java:110)java.base/jdk.internal.reflect.DirectMethodHandleAccessor.invoke(DirectMethodHandleAccessor.java:104)java.base/java.lang.reflect.Method.invoke(Method.java:578)org.testng.internal.invokers.MethodInvocationHelper.invokeMethod(MethodInvocationHelper.java:139)org.testng.internal.invokers.TestInvoker.invokeMethod(TestInvoker.java:677)org.testng.internal.invokers.TestInvoker.invokeTestMethod(TestInvoker.java:221)org.testng.internal.invokers.MethodRunner.runInSequence(MethodRunner.java:50)org.testng.internal.invokers.TestInvoker$MethodInvocationAgent.invoke(TestInvoker.java:969)org.testng.internal.invokers.TestInvoker.invokeTestMethods(TestInvoker.java:194)org.testng.internal.invokers.TestMethodWorker.invokeTestMethods(TestMethodWorker.java:148)org.testng.internal.invokers.TestMethodWorker.run(TestMethodWorker.java:128)java.base/java.util.ArrayList.forEach(ArrayList.java:1511)org.testng.TestRunner.privateRun(TestRunner.java:829)org.testng.TestRunner.run(TestRunner.java:602)org.testng.SuiteRunner.runTest(SuiteRunner.java:437)org.testng.SuiteRunner$SuiteWorker.run(SuiteRunner.java:475)org.testng.internal.thread.ThreadUtil.lambda$execute$0(ThreadUtil.java:58)java.base/java.util.concurrent.FutureTask.run(FutureTask.java:317)java.base/java.util.concurrent.ThreadPoolExecutor.runWorker(ThreadPoolExecutor.java:1144)java.base/java.util.concurrent.ThreadPoolExecutor$Worker.run(ThreadPoolExecutor.java:642)java.base/java.lang.Thread.run(Thread.java:1623)
]]>
            </failure>
    </testcase>
            <testcase
                name="testFactorial"
                time="0.001"
                classname="FacturialTest">

            <failure type="java.lang.AssertionError" message="expected [4] but found [2]">
                <![CDATA[java.lang.AssertionError: expected [4] but found [2]
                org.testng.Assert.fail(Assert.java:110)org.testng.Assert.failNotEquals(Assert.java:1577)org.testng.Assert.assertEqualsImpl(Assert.java:149)org.testng.Assert.assertEquals(Assert.java:131)org.testng.Assert.assertEquals(Assert.java:1418)org.testng.Assert.assertEquals(Assert.java:1382)org.testng.Assert.assertEquals(Assert.java:1428)FacturialTest.testFactorial(FacturialTest.java:110)java.base/jdk.internal.reflect.DirectMethodHandleAccessor.invoke(DirectMethodHandleAccessor.java:104)java.base/java.lang.reflect.Method.invoke(Method.java:578)org.testng.internal.invokers.MethodInvocationHelper.invokeMethod(MethodInvocationHelper.java:139)org.testng.internal.invokers.TestInvoker.invokeMethod(TestInvoker.java:677)org.testng.internal.invokers.TestInvoker.invokeTestMethod(TestInvoker.java:221)org.testng.internal.invokers.MethodRunner.runInSequence(MethodRunner.java:50)org.testng.internal.invokers.TestInvoker$MethodInvocationAgent.invoke(TestInvoker.java:969)org.testng.internal.invokers.TestInvoker.invokeTestMethods(TestInvoker.java:194)org.testng.internal.invokers.TestMethodWorker.invokeTestMethods(TestMethodWorker.java:148)org.testng.internal.invokers.TestMethodWorker.run(TestMethodWorker.java:128)java.base/java.util.ArrayList.forEach(ArrayList.java:1511)org.testng.TestRunner.privateRun(TestRunner.java:829)org.testng.TestRunner.run(TestRunner.java:602)org.testng.SuiteRunner.runTest(SuiteRunner.java:437)org.testng.SuiteRunner$SuiteWorker.run(SuiteRunner.java:475)org.testng.internal.thread.ThreadUtil.lambda$execute$0(ThreadUtil.java:58)java.base/java.util.concurrent.FutureTask.run(FutureTask.java:317)java.base/java.util.concurrent.ThreadPoolExecutor.runWorker(ThreadPoolExecutor.java:1144)java.base/java.util.concurrent.ThreadPoolExecutor$Worker.run(ThreadPoolExecutor.java:642)java.base/java.lang.Thread.run(Thread.java:1623)
]]>
            </failure>
    </testcase>
            <testcase
                name="testFactorial"
                time="0.001"
                classname="FacturialTest">

            <failure type="java.lang.AssertionError" message="expected [4] but found [2]">
                <![CDATA[java.lang.AssertionError: expected [4] but found [2]
                org.testng.Assert.fail(Assert.java:110)org.testng.Assert.failNotEquals(Assert.java:1577)org.testng.Assert.assertEqualsImpl(Assert.java:149)org.testng.Assert.assertEquals(Assert.java:131)org.testng.Assert.assertEquals(Assert.java:1418)org.testng.Assert.assertEquals(Assert.java:1382)org.testng.Assert.assertEquals(Assert.java:1428)FacturialTest.testFactorial(FacturialTest.java:110)java.base/jdk.internal.reflect.DirectMethodHandleAccessor.invoke(DirectMethodHandleAccessor.java:104)java.base/java.lang.reflect.Method.invoke(Method.java:578)org.testng.internal.invokers.MethodInvocationHelper.invokeMethod(MethodInvocationHelper.java:139)org.testng.internal.invokers.TestInvoker.invokeMethod(TestInvoker.java:677)org.testng.internal.invokers.TestInvoker.invokeTestMethod(TestInvoker.java:221)org.testng.internal.invokers.MethodRunner.runInSequence(MethodRunner.java:50)org.testng.internal.invokers.TestInvoker$MethodInvocationAgent.invoke(TestInvoker.java:969)org.testng.internal.invokers.TestInvoker.invokeTestMethods(TestInvoker.java:194)org.testng.internal.invokers.TestMethodWorker.invokeTestMethods(TestMethodWorker.java:148)org.testng.internal.invokers.TestMethodWorker.run(TestMethodWorker.java:128)java.base/java.util.ArrayList.forEach(ArrayList.java:1511)org.testng.TestRunner.privateRun(TestRunner.java:829)org.testng.TestRunner.run(TestRunner.java:602)org.testng.SuiteRunner.runTest(SuiteRunner.java:437)org.testng.SuiteRunner$SuiteWorker.run(SuiteRunner.java:475)org.testng.internal.thread.ThreadUtil.lambda$execute$0(ThreadUtil.java:58)java.base/java.util.concurrent.FutureTask.run(FutureTask.java:317)java.base/java.util.concurrent.ThreadPoolExecutor.runWorker(ThreadPoolExecutor.java:1144)java.base/java.util.concurrent.ThreadPoolExecutor$Worker.run(ThreadPoolExecutor.java:642)java.base/java.lang.Thread.run(Thread.java:1623)
]]>
            </failure>
    </testcase>
            <testcase
                name="testFactorial"
                time="0.001"
                classname="FacturialTest">

            <failure type="java.lang.AssertionError" message="expected [4] but found [2]">
                <![CDATA[java.lang.AssertionError: expected [4] but found [2]
                org.testng.Assert.fail(Assert.java:110)org.testng.Assert.failNotEquals(Assert.java:1577)org.testng.Assert.assertEqualsImpl(Assert.java:149)org.testng.Assert.assertEquals(Assert.java:131)org.testng.Assert.assertEquals(Assert.java:1418)org.testng.Assert.assertEquals(Assert.java:1382)org.testng.Assert.assertEquals(Assert.java:1428)FacturialTest.testFactorial(FacturialTest.java:110)java.base/jdk.internal.reflect.DirectMethodHandleAccessor.invoke(DirectMethodHandleAccessor.java:104)java.base/java.lang.reflect.Method.invoke(Method.java:578)org.testng.internal.invokers.MethodInvocationHelper.invokeMethod(MethodInvocationHelper.java:139)org.testng.internal.invokers.TestInvoker.invokeMethod(TestInvoker.java:677)org.testng.internal.invokers.TestInvoker.invokeTestMethod(TestInvoker.java:221)org.testng.internal.invokers.MethodRunner.runInSequence(MethodRunner.java:50)org.testng.internal.invokers.TestInvoker$MethodInvocationAgent.invoke(TestInvoker.java:969)org.testng.internal.invokers.TestInvoker.invokeTestMethods(TestInvoker.java:194)org.testng.internal.invokers.TestMethodWorker.invokeTestMethods(TestMethodWorker.java:148)org.testng.internal.invokers.TestMethodWorker.run(TestMethodWorker.java:128)java.base/java.util.ArrayList.forEach(ArrayList.java:1511)org.testng.TestRunner.privateRun(TestRunner.java:829)org.testng.TestRunner.run(TestRunner.java:602)org.testng.SuiteRunner.runTest(SuiteRunner.java:437)org.testng.SuiteRunner$SuiteWorker.run(SuiteRunner.java:475)org.testng.internal.thread.ThreadUtil.lambda$execute$0(ThreadUtil.java:58)java.base/java.util.concurrent.FutureTask.run(FutureTask.java:317)java.base/java.util.concurrent.ThreadPoolExecutor.runWorker(ThreadPoolExecutor.java:1144)java.base/java.util.concurrent.ThreadPoolExecutor$Worker.run(ThreadPoolExecutor.java:642)java.base/java.lang.Thread.run(Thread.java:1623)
]]>
            </failure>
    </testcase>
            <testcase
                name="testFactorial"
                time="0.001"
                classname="FacturialTest">

            <failure type="java.lang.AssertionError" message="expected [4] but found [2]">
                <![CDATA[java.lang.AssertionError: expected [4] but found [2]
                org.testng.Assert.fail(Assert.java:110)org.testng.Assert.failNotEquals(Assert.java:1577)org.testng.Assert.assertEqualsImpl(Assert.java:149)org.testng.Assert.assertEquals(Assert.java:131)org.testng.Assert.assertEquals(Assert.java:1418)org.testng.Assert.assertEquals(Assert.java:1382)org.testng.Assert.assertEquals(Assert.java:1428)FacturialTest.testFactorial(FacturialTest.java:110)java.base/jdk.internal.reflect.DirectMethodHandleAccessor.invoke(DirectMethodHandleAccessor.java:104)java.base/java.lang.reflect.Method.invoke(Method.java:578)org.testng.internal.invokers.MethodInvocationHelper.invokeMethod(MethodInvocationHelper.java:139)org.testng.internal.invokers.TestInvoker.invokeMethod(TestInvoker.java:677)org.testng.internal.invokers.TestInvoker.invokeTestMethod(TestInvoker.java:221)org.testng.internal.invokers.MethodRunner.runInSequence(MethodRunner.java:50)org.testng.internal.invokers.TestInvoker$MethodInvocationAgent.invoke(TestInvoker.java:969)org.testng.internal.invokers.TestInvoker.invokeTestMethods(TestInvoker.java:194)org.testng.internal.invokers.TestMethodWorker.invokeTestMethods(TestMethodWorker.java:148)org.testng.internal.invokers.TestMethodWorker.run(TestMethodWorker.java:128)java.base/java.util.ArrayList.forEach(ArrayList.java:1511)org.testng.TestRunner.privateRun(TestRunner.java:829)org.testng.TestRunner.run(TestRunner.java:602)org.testng.SuiteRunner.runTest(SuiteRunner.java:437)org.testng.SuiteRunner$SuiteWorker.run(SuiteRunner.java:475)org.testng.internal.thread.ThreadUtil.lambda$execute$0(ThreadUtil.java:58)java.base/java.util.concurrent.FutureTask.run(FutureTask.java:317)java.base/java.util.concurrent.ThreadPoolExecutor.runWorker(ThreadPoolExecutor.java:1144)java.base/java.util.concurrent.ThreadPoolExecutor$Worker.run(ThreadPoolExecutor.java:642)java.base/java.lang.Thread.run(Thread.java:1623)
]]>
            </failure>
    </testcase>
            <testcase
                name="testFactorial"
                time="0.003"
                classname="FacturialTest">

            <failure type="java.lang.AssertionError" message="expected [4] but found [2]">
                <![CDATA[java.lang.AssertionError: expected [4] but found [2]
                org.testng.Assert.fail(Assert.java:110)org.testng.Assert.failNotEquals(Assert.java:1577)org.testng.Assert.assertEqualsImpl(Assert.java:149)org.testng.Assert.assertEquals(Assert.java:131)org.testng.Assert.assertEquals(Assert.java:1418)org.testng.Assert.assertEquals(Assert.java:1382)org.testng.Assert.assertEquals(Assert.java:1428)FacturialTest.testFactorial(FacturialTest.java:110)java.base/jdk.internal.reflect.DirectMethodHandleAccessor.invoke(DirectMethodHandleAccessor.java:104)java.base/java.lang.reflect.Method.invoke(Method.java:578)org.testng.internal.invokers.MethodInvocationHelper.invokeMethod(MethodInvocationHelper.java:139)org.testng.internal.invokers.TestInvoker.invokeMethod(TestInvoker.java:677)org.testng.internal.invokers.TestInvoker.invokeTestMethod(TestInvoker.java:221)org.testng.internal.invokers.MethodRunner.runInSequence(MethodRunner.java:50)org.testng.internal.invokers.TestInvoker$MethodInvocationAgent.invoke(TestInvoker.java:969)org.testng.internal.invokers.TestInvoker.invokeTestMethods(TestInvoker.java:194)org.testng.internal.invokers.TestMethodWorker.invokeTestMethods(TestMethodWorker.java:148)org.testng.internal.invokers.TestMethodWorker.run(TestMethodWorker.java:128)java.base/java.util.ArrayList.forEach(ArrayList.java:1511)org.testng.TestRunner.privateRun(TestRunner.java:829)org.testng.TestRunner.run(TestRunner.java:602)org.testng.SuiteRunner.runTest(SuiteRunner.java:437)org.testng.SuiteRunner$SuiteWorker.run(SuiteRunner.java:475)org.testng.internal.thread.ThreadUtil.lambda$execute$0(ThreadUtil.java:58)java.base/java.util.concurrent.FutureTask.run(FutureTask.java:317)java.base/java.util.concurrent.ThreadPoolExecutor.runWorker(ThreadPoolExecutor.java:1144)java.base/java.util.concurrent.ThreadPoolExecutor$Worker.run(ThreadPoolExecutor.java:642)java.base/java.lang.Thread.run(Thread.java:1623)
]]>
            </failure>
    </testcase>
            <testcase
                name="testFactorial"
                time="0.002"
                classname="FacturialTest">

            <failure type="java.lang.AssertionError" message="expected [4] but found [2]">
                <![CDATA[java.lang.AssertionError: expected [4] but found [2]
                org.testng.Assert.fail(Assert.java:110)org.testng.Assert.failNotEquals(Assert.java:1577)org.testng.Assert.assertEqualsImpl(Assert.java:149)org.testng.Assert.assertEquals(Assert.java:131)org.testng.Assert.assertEquals(Assert.java:1418)org.testng.Assert.assertEquals(Assert.java:1382)org.testng.Assert.assertEquals(Assert.java:1428)FacturialTest.testFactorial(FacturialTest.java:110)java.base/jdk.internal.reflect.DirectMethodHandleAccessor.invoke(DirectMethodHandleAccessor.java:104)java.base/java.lang.reflect.Method.invoke(Method.java:578)org.testng.internal.invokers.MethodInvocationHelper.invokeMethod(MethodInvocationHelper.java:139)org.testng.internal.invokers.TestInvoker.invokeMethod(TestInvoker.java:677)org.testng.internal.invokers.TestInvoker.invokeTestMethod(TestInvoker.java:221)org.testng.internal.invokers.MethodRunner.runInSequence(MethodRunner.java:50)org.testng.internal.invokers.TestInvoker$MethodInvocationAgent.invoke(TestInvoker.java:969)org.testng.internal.invokers.TestInvoker.invokeTestMethods(TestInvoker.java:194)org.testng.internal.invokers.TestMethodWorker.invokeTestMethods(TestMethodWorker.java:148)org.testng.internal.invokers.TestMethodWorker.run(TestMethodWorker.java:128)java.base/java.util.ArrayList.forEach(ArrayList.java:1511)org.testng.TestRunner.privateRun(TestRunner.java:829)org.testng.TestRunner.run(TestRunner.java:602)org.testng.SuiteRunner.runTest(SuiteRunner.java:437)org.testng.SuiteRunner$SuiteWorker.run(SuiteRunner.java:475)org.testng.internal.thread.ThreadUtil.lambda$execute$0(ThreadUtil.java:58)java.base/java.util.concurrent.FutureTask.run(FutureTask.java:317)java.base/java.util.concurrent.ThreadPoolExecutor.runWorker(ThreadPoolExecutor.java:1144)java.base/java.util.concurrent.ThreadPoolExecutor$Worker.run(ThreadPoolExecutor.java:642)java.base/java.lang.Thread.run(Thread.java:1623)
]]>
            </failure>
    </testcase>
            <testcase
                name="testFactorial"
                time="0.001"
                classname="FacturialTest">

            <failure type="java.lang.AssertionError" message="expected [4] but found [2]">
                <![CDATA[java.lang.AssertionError: expected [4] but found [2]
                org.testng.Assert.fail(Assert.java:110)org.testng.Assert.failNotEquals(Assert.java:1577)org.testng.Assert.assertEqualsImpl(Assert.java:149)org.testng.Assert.assertEquals(Assert.java:131)org.testng.Assert.assertEquals(Assert.java:1418)org.testng.Assert.assertEquals(Assert.java:1382)org.testng.Assert.assertEquals(Assert.java:1428)FacturialTest.testFactorial(FacturialTest.java:110)java.base/jdk.internal.reflect.DirectMethodHandleAccessor.invoke(DirectMethodHandleAccessor.java:104)java.base/java.lang.reflect.Method.invoke(Method.java:578)org.testng.internal.invokers.MethodInvocationHelper.invokeMethod(MethodInvocationHelper.java:139)org.testng.internal.invokers.TestInvoker.invokeMethod(TestInvoker.java:677)org.testng.internal.invokers.TestInvoker.invokeTestMethod(TestInvoker.java:221)org.testng.internal.invokers.MethodRunner.runInSequence(MethodRunner.java:50)org.testng.internal.invokers.TestInvoker$MethodInvocationAgent.invoke(TestInvoker.java:969)org.testng.internal.invokers.TestInvoker.invokeTestMethods(TestInvoker.java:194)org.testng.internal.invokers.TestMethodWorker.invokeTestMethods(TestMethodWorker.java:148)org.testng.internal.invokers.TestMethodWorker.run(TestMethodWorker.java:128)java.base/java.util.ArrayList.forEach(ArrayList.java:1511)org.testng.TestRunner.privateRun(TestRunner.java:829)org.testng.TestRunner.run(TestRunner.java:602)org.testng.SuiteRunner.runTest(SuiteRunner.java:437)org.testng.SuiteRunner$SuiteWorker.run(SuiteRunner.java:475)org.testng.internal.thread.ThreadUtil.lambda$execute$0(ThreadUtil.java:58)java.base/java.util.concurrent.FutureTask.run(FutureTask.java:317)java.base/java.util.concurrent.ThreadPoolExecutor.runWorker(ThreadPoolExecutor.java:1144)java.base/java.util.concurrent.ThreadPoolExecutor$Worker.run(ThreadPoolExecutor.java:642)java.base/java.lang.Thread.run(Thread.java:1623)
]]>
            </failure>
    </testcase>
            <testcase
                name="testFactorial"
                time="0.001"
                classname="FacturialTest">

            <failure type="java.lang.AssertionError" message="expected [4] but found [2]">
                <![CDATA[java.lang.AssertionError: expected [4] but found [2]
                org.testng.Assert.fail(Assert.java:110)org.testng.Assert.failNotEquals(Assert.java:1577)org.testng.Assert.assertEqualsImpl(Assert.java:149)org.testng.Assert.assertEquals(Assert.java:131)org.testng.Assert.assertEquals(Assert.java:1418)org.testng.Assert.assertEquals(Assert.java:1382)org.testng.Assert.assertEquals(Assert.java:1428)FacturialTest.testFactorial(FacturialTest.java:110)java.base/jdk.internal.reflect.DirectMethodHandleAccessor.invoke(DirectMethodHandleAccessor.java:104)java.base/java.lang.reflect.Method.invoke(Method.java:578)org.testng.internal.invokers.MethodInvocationHelper.invokeMethod(MethodInvocationHelper.java:139)org.testng.internal.invokers.TestInvoker.invokeMethod(TestInvoker.java:677)org.testng.internal.invokers.TestInvoker.invokeTestMethod(TestInvoker.java:221)org.testng.internal.invokers.MethodRunner.runInSequence(MethodRunner.java:50)org.testng.internal.invokers.TestInvoker$MethodInvocationAgent.invoke(TestInvoker.java:969)org.testng.internal.invokers.TestInvoker.invokeTestMethods(TestInvoker.java:194)org.testng.internal.invokers.TestMethodWorker.invokeTestMethods(TestMethodWorker.java:148)org.testng.internal.invokers.TestMethodWorker.run(TestMethodWorker.java:128)java.base/java.util.ArrayList.forEach(ArrayList.java:1511)org.testng.TestRunner.privateRun(TestRunner.java:829)org.testng.TestRunner.run(TestRunner.java:602)org.testng.SuiteRunner.runTest(SuiteRunner.java:437)org.testng.SuiteRunner$SuiteWorker.run(SuiteRunner.java:475)org.testng.internal.thread.ThreadUtil.lambda$execute$0(ThreadUtil.java:58)java.base/java.util.concurrent.FutureTask.run(FutureTask.java:317)java.base/java.util.concurrent.ThreadPoolExecutor.runWorker(ThreadPoolExecutor.java:1144)java.base/java.util.concurrent.ThreadPoolExecutor$Worker.run(ThreadPoolExecutor.java:642)java.base/java.lang.Thread.run(Thread.java:1623)
]]>
            </failure>
    </testcase>
            <testcase
                name="testFactorial"
                time="0.002"
                classname="FacturialTest">

            <failure type="java.lang.AssertionError" message="expected [4] but found [2]">
                <![CDATA[java.lang.AssertionError: expected [4] but found [2]
                org.testng.Assert.fail(Assert.java:110)org.testng.Assert.failNotEquals(Assert.java:1577)org.testng.Assert.assertEqualsImpl(Assert.java:149)org.testng.Assert.assertEquals(Assert.java:131)org.testng.Assert.assertEquals(Assert.java:1418)org.testng.Assert.assertEquals(Assert.java:1382)org.testng.Assert.assertEquals(Assert.java:1428)FacturialTest.testFactorial(FacturialTest.java:110)java.base/jdk.internal.reflect.DirectMethodHandleAccessor.invoke(DirectMethodHandleAccessor.java:104)java.base/java.lang.reflect.Method.invoke(Method.java:578)org.testng.internal.invokers.MethodInvocationHelper.invokeMethod(MethodInvocationHelper.java:139)org.testng.internal.invokers.TestInvoker.invokeMethod(TestInvoker.java:677)org.testng.internal.invokers.TestInvoker.invokeTestMethod(TestInvoker.java:221)org.testng.internal.invokers.MethodRunner.runInSequence(MethodRunner.java:50)org.testng.internal.invokers.TestInvoker$MethodInvocationAgent.invoke(TestInvoker.java:969)org.testng.internal.invokers.TestInvoker.invokeTestMethods(TestInvoker.java:194)org.testng.internal.invokers.TestMethodWorker.invokeTestMethods(TestMethodWorker.java:148)org.testng.internal.invokers.TestMethodWorker.run(TestMethodWorker.java:128)java.base/java.util.ArrayList.forEach(ArrayList.java:1511)org.testng.TestRunner.privateRun(TestRunner.java:829)org.testng.TestRunner.run(TestRunner.java:602)org.testng.SuiteRunner.runTest(SuiteRunner.java:437)org.testng.SuiteRunner$SuiteWorker.run(SuiteRunner.java:475)org.testng.internal.thread.ThreadUtil.lambda$execute$0(ThreadUtil.java:58)java.base/java.util.concurrent.FutureTask.run(FutureTask.java:317)java.base/java.util.concurrent.ThreadPoolExecutor.runWorker(ThreadPoolExecutor.java:1144)java.base/java.util.concurrent.ThreadPoolExecutor$Worker.run(ThreadPoolExecutor.java:642)java.base/java.lang.Thread.run(Thread.java:1623)
]]>
            </failure>
    </testcase>
            <testcase
                name="testFactorial"
                time="0.003"
                classname="FacturialTest">

            <failure type="java.lang.AssertionError" message="expected [4] but found [2]">
                <![CDATA[java.lang.AssertionError: expected [4] but found [2]
                org.testng.Assert.fail(Assert.java:110)org.testng.Assert.failNotEquals(Assert.java:1577)org.testng.Assert.assertEqualsImpl(Assert.java:149)org.testng.Assert.assertEquals(Assert.java:131)org.testng.Assert.assertEquals(Assert.java:1418)org.testng.Assert.assertEquals(Assert.java:1382)org.testng.Assert.assertEquals(Assert.java:1428)FacturialTest.testFactorial(FacturialTest.java:110)java.base/jdk.internal.reflect.DirectMethodHandleAccessor.invoke(DirectMethodHandleAccessor.java:104)java.base/java.lang.reflect.Method.invoke(Method.java:578)org.testng.internal.invokers.MethodInvocationHelper.invokeMethod(MethodInvocationHelper.java:139)org.testng.internal.invokers.TestInvoker.invokeMethod(TestInvoker.java:677)org.testng.internal.invokers.TestInvoker.invokeTestMethod(TestInvoker.java:221)org.testng.internal.invokers.MethodRunner.runInSequence(MethodRunner.java:50)org.testng.internal.invokers.TestInvoker$MethodInvocationAgent.invoke(TestInvoker.java:969)org.testng.internal.invokers.TestInvoker.invokeTestMethods(TestInvoker.java:194)org.testng.internal.invokers.TestMethodWorker.invokeTestMethods(TestMethodWorker.java:148)org.testng.internal.invokers.TestMethodWorker.run(TestMethodWorker.java:128)java.base/java.util.ArrayList.forEach(ArrayList.java:1511)org.testng.TestRunner.privateRun(TestRunner.java:829)org.testng.TestRunner.run(TestRunner.java:602)org.testng.SuiteRunner.runTest(SuiteRunner.java:437)org.testng.SuiteRunner$SuiteWorker.run(SuiteRunner.java:475)org.testng.internal.thread.ThreadUtil.lambda$execute$0(ThreadUtil.java:58)java.base/java.util.concurrent.FutureTask.run(FutureTask.java:317)java.base/java.util.concurrent.ThreadPoolExecutor.runWorker(ThreadPoolExecutor.java:1144)java.base/java.util.concurrent.ThreadPoolExecutor$Worker.run(ThreadPoolExecutor.java:642)java.base/java.lang.Thread.run(Thread.java:1623)
]]>
            </failure>
    </testcase>
            <testcase
                name="testFactorial"
                time="0.001"
                classname="FacturialTest">

            <failure type="java.lang.AssertionError" message="expected [4] but found [2]">
                <![CDATA[java.lang.AssertionError: expected [4] but found [2]
                org.testng.Assert.fail(Assert.java:110)org.testng.Assert.failNotEquals(Assert.java:1577)org.testng.Assert.assertEqualsImpl(Assert.java:149)org.testng.Assert.assertEquals(Assert.java:131)org.testng.Assert.assertEquals(Assert.java:1418)org.testng.Assert.assertEquals(Assert.java:1382)org.testng.Assert.assertEquals(Assert.java:1428)FacturialTest.testFactorial(FacturialTest.java:110)java.base/jdk.internal.reflect.DirectMethodHandleAccessor.invoke(DirectMethodHandleAccessor.java:104)java.base/java.lang.reflect.Method.invoke(Method.java:578)org.testng.internal.invokers.MethodInvocationHelper.invokeMethod(MethodInvocationHelper.java:139)org.testng.internal.invokers.TestInvoker.invokeMethod(TestInvoker.java:677)org.testng.internal.invokers.TestInvoker.invokeTestMethod(TestInvoker.java:221)org.testng.internal.invokers.MethodRunner.runInSequence(MethodRunner.java:50)org.testng.internal.invokers.TestInvoker$MethodInvocationAgent.invoke(TestInvoker.java:969)org.testng.internal.invokers.TestInvoker.invokeTestMethods(TestInvoker.java:194)org.testng.internal.invokers.TestMethodWorker.invokeTestMethods(TestMethodWorker.java:148)org.testng.internal.invokers.TestMethodWorker.run(TestMethodWorker.java:128)java.base/java.util.ArrayList.forEach(ArrayList.java:1511)org.testng.TestRunner.privateRun(TestRunner.java:829)org.testng.TestRunner.run(TestRunner.java:602)org.testng.SuiteRunner.runTest(SuiteRunner.java:437)org.testng.SuiteRunner$SuiteWorker.run(SuiteRunner.java:475)org.testng.internal.thread.ThreadUtil.lambda$execute$0(ThreadUtil.java:58)java.base/java.util.concurrent.FutureTask.run(FutureTask.java:317)java.base/java.util.concurrent.ThreadPoolExecutor.runWorker(ThreadPoolExecutor.java:1144)java.base/java.util.concurrent.ThreadPoolExecutor$Worker.run(ThreadPoolExecutor.java:642)java.base/java.lang.Thread.run(Thread.java:1623)
]]>
            </failure>
    </testcase>
            <testcase
                name="testFactorial"
                time="0.001"
                classname="FacturialTest">

            <failure type="java.lang.AssertionError" message="expected [4] but found [2]">
                <![CDATA[java.lang.AssertionError: expected [4] but found [2]
                org.testng.Assert.fail(Assert.java:110)org.testng.Assert.failNotEquals(Assert.java:1577)org.testng.Assert.assertEqualsImpl(Assert.java:149)org.testng.Assert.assertEquals(Assert.java:131)org.testng.Assert.assertEquals(Assert.java:1418)org.testng.Assert.assertEquals(Assert.java:1382)org.testng.Assert.assertEquals(Assert.java:1428)FacturialTest.testFactorial(FacturialTest.java:110)java.base/jdk.internal.reflect.DirectMethodHandleAccessor.invoke(DirectMethodHandleAccessor.java:104)java.base/java.lang.reflect.Method.invoke(Method.java:578)org.testng.internal.invokers.MethodInvocationHelper.invokeMethod(MethodInvocationHelper.java:139)org.testng.internal.invokers.TestInvoker.invokeMethod(TestInvoker.java:677)org.testng.internal.invokers.TestInvoker.invokeTestMethod(TestInvoker.java:221)org.testng.internal.invokers.MethodRunner.runInSequence(MethodRunner.java:50)org.testng.internal.invokers.TestInvoker$MethodInvocationAgent.invoke(TestInvoker.java:969)org.testng.internal.invokers.TestInvoker.invokeTestMethods(TestInvoker.java:194)org.testng.internal.invokers.TestMethodWorker.invokeTestMethods(TestMethodWorker.java:148)org.testng.internal.invokers.TestMethodWorker.run(TestMethodWorker.java:128)java.base/java.util.ArrayList.forEach(ArrayList.java:1511)org.testng.TestRunner.privateRun(TestRunner.java:829)org.testng.TestRunner.run(TestRunner.java:602)org.testng.SuiteRunner.runTest(SuiteRunner.java:437)org.testng.SuiteRunner$SuiteWorker.run(SuiteRunner.java:475)org.testng.internal.thread.ThreadUtil.lambda$execute$0(ThreadUtil.java:58)java.base/java.util.concurrent.FutureTask.run(FutureTask.java:317)java.base/java.util.concurrent.ThreadPoolExecutor.runWorker(ThreadPoolExecutor.java:1144)java.base/java.util.concurrent.ThreadPoolExecutor$Worker.run(ThreadPoolExecutor.java:642)java.base/java.lang.Thread.run(Thread.java:1623)
]]>
            </failure>
    </testcase>
            <testcase
                name="testFactorial"
                time="0.002"
                classname="FacturialTest">

            <failure type="java.lang.AssertionError" message="expected [4] but found [2]">
                <![CDATA[java.lang.AssertionError: expected [4] but found [2]
                org.testng.Assert.fail(Assert.java:110)org.testng.Assert.failNotEquals(Assert.java:1577)org.testng.Assert.assertEqualsImpl(Assert.java:149)org.testng.Assert.assertEquals(Assert.java:131)org.testng.Assert.assertEquals(Assert.java:1418)org.testng.Assert.assertEquals(Assert.java:1382)org.testng.Assert.assertEquals(Assert.java:1428)FacturialTest.testFactorial(FacturialTest.java:110)java.base/jdk.internal.reflect.DirectMethodHandleAccessor.invoke(DirectMethodHandleAccessor.java:104)java.base/java.lang.reflect.Method.invoke(Method.java:578)org.testng.internal.invokers.MethodInvocationHelper.invokeMethod(MethodInvocationHelper.java:139)org.testng.internal.invokers.TestInvoker.invokeMethod(TestInvoker.java:677)org.testng.internal.invokers.TestInvoker.invokeTestMethod(TestInvoker.java:221)org.testng.internal.invokers.MethodRunner.runInSequence(MethodRunner.java:50)org.testng.internal.invokers.TestInvoker$MethodInvocationAgent.invoke(TestInvoker.java:969)org.testng.internal.invokers.TestInvoker.invokeTestMethods(TestInvoker.java:194)org.testng.internal.invokers.TestMethodWorker.invokeTestMethods(TestMethodWorker.java:148)org.testng.internal.invokers.TestMethodWorker.run(TestMethodWorker.java:128)java.base/java.util.ArrayList.forEach(ArrayList.java:1511)org.testng.TestRunner.privateRun(TestRunner.java:829)org.testng.TestRunner.run(TestRunner.java:602)org.testng.SuiteRunner.runTest(SuiteRunner.java:437)org.testng.SuiteRunner$SuiteWorker.run(SuiteRunner.java:475)org.testng.internal.thread.ThreadUtil.lambda$execute$0(ThreadUtil.java:58)java.base/java.util.concurrent.FutureTask.run(FutureTask.java:317)java.base/java.util.concurrent.ThreadPoolExecutor.runWorker(ThreadPoolExecutor.java:1144)java.base/java.util.concurrent.ThreadPoolExecutor$Worker.run(ThreadPoolExecutor.java:642)java.base/java.lang.Thread.run(Thread.java:1623)
]]>
            </failure>
    </testcase>
            <testcase
                name="testFactorial"
                time="0.023"
                classname="FacturialTest">

            <failure type="java.lang.AssertionError" message="expected [4] but found [2]">
                <![CDATA[java.lang.AssertionError: expected [4] but found [2]
                org.testng.Assert.fail(Assert.java:110)org.testng.Assert.failNotEquals(Assert.java:1577)org.testng.Assert.assertEqualsImpl(Assert.java:149)org.testng.Assert.assertEquals(Assert.java:131)org.testng.Assert.assertEquals(Assert.java:1418)org.testng.Assert.assertEquals(Assert.java:1382)org.testng.Assert.assertEquals(Assert.java:1428)FacturialTest.testFactorial(FacturialTest.java:110)java.base/jdk.internal.reflect.DirectMethodHandleAccessor.invoke(DirectMethodHandleAccessor.java:104)java.base/java.lang.reflect.Method.invoke(Method.java:578)org.testng.internal.invokers.MethodInvocationHelper.invokeMethod(MethodInvocationHelper.java:139)org.testng.internal.invokers.TestInvoker.invokeMethod(TestInvoker.java:677)org.testng.internal.invokers.TestInvoker.invokeTestMethod(TestInvoker.java:221)org.testng.internal.invokers.MethodRunner.runInSequence(MethodRunner.java:50)org.testng.internal.invokers.TestInvoker$MethodInvocationAgent.invoke(TestInvoker.java:969)org.testng.internal.invokers.TestInvoker.invokeTestMethods(TestInvoker.java:194)org.testng.internal.invokers.TestMethodWorker.invokeTestMethods(TestMethodWorker.java:148)org.testng.internal.invokers.TestMethodWorker.run(TestMethodWorker.java:128)java.base/java.util.ArrayList.forEach(ArrayList.java:1511)org.testng.TestRunner.privateRun(TestRunner.java:829)org.testng.TestRunner.run(TestRunner.java:602)org.testng.SuiteRunner.runTest(SuiteRunner.java:437)org.testng.SuiteRunner$SuiteWorker.run(SuiteRunner.java:475)org.testng.internal.thread.ThreadUtil.lambda$execute$0(ThreadUtil.java:58)java.base/java.util.concurrent.FutureTask.run(FutureTask.java:317)java.base/java.util.concurrent.ThreadPoolExecutor.runWorker(ThreadPoolExecutor.java:1144)java.base/java.util.concurrent.ThreadPoolExecutor$Worker.run(ThreadPoolExecutor.java:642)java.base/java.lang.Thread.run(Thread.java:1623)
]]>
            </failure>
    </testcase>
            <testcase
                name="testFactorial"
                time="0.001"
                classname="FacturialTest">

            <failure type="java.lang.AssertionError" message="expected [4] but found [2]">
                <![CDATA[java.lang.AssertionError: expected [4] but found [2]
                org.testng.Assert.fail(Assert.java:110)org.testng.Assert.failNotEquals(Assert.java:1577)org.testng.Assert.assertEqualsImpl(Assert.java:149)org.testng.Assert.assertEquals(Assert.java:131)org.testng.Assert.assertEquals(Assert.java:1418)org.testng.Assert.assertEquals(Assert.java:1382)org.testng.Assert.assertEquals(Assert.java:1428)FacturialTest.testFactorial(FacturialTest.java:110)java.base/jdk.internal.reflect.DirectMethodHandleAccessor.invoke(DirectMethodHandleAccessor.java:104)java.base/java.lang.reflect.Method.invoke(Method.java:578)org.testng.internal.invokers.MethodInvocationHelper.invokeMethod(MethodInvocationHelper.java:139)org.testng.internal.invokers.TestInvoker.invokeMethod(TestInvoker.java:677)org.testng.internal.invokers.TestInvoker.invokeTestMethod(TestInvoker.java:221)org.testng.internal.invokers.MethodRunner.runInSequence(MethodRunner.java:50)org.testng.internal.invokers.TestInvoker$MethodInvocationAgent.invoke(TestInvoker.java:969)org.testng.internal.invokers.TestInvoker.invokeTestMethods(TestInvoker.java:194)org.testng.internal.invokers.TestMethodWorker.invokeTestMethods(TestMethodWorker.java:148)org.testng.internal.invokers.TestMethodWorker.run(TestMethodWorker.java:128)java.base/java.util.ArrayList.forEach(ArrayList.java:1511)org.testng.TestRunner.privateRun(TestRunner.java:829)org.testng.TestRunner.run(TestRunner.java:602)org.testng.SuiteRunner.runTest(SuiteRunner.java:437)org.testng.SuiteRunner$SuiteWorker.run(SuiteRunner.java:475)org.testng.internal.thread.ThreadUtil.lambda$execute$0(ThreadUtil.java:58)java.base/java.util.concurrent.FutureTask.run(FutureTask.java:317)java.base/java.util.concurrent.ThreadPoolExecutor.runWorker(ThreadPoolExecutor.java:1144)java.base/java.util.concurrent.ThreadPoolExecutor$Worker.run(ThreadPoolExecutor.java:642)java.base/java.lang.Thread.run(Thread.java:1623)
]]>
            </failure>
    </testcase>
            <testcase
                name="testFactorial"
                time="0.001"
                classname="FacturialTest">

            <failure type="java.lang.AssertionError" message="expected [4] but found [2]">
                <![CDATA[java.lang.AssertionError: expected [4] but found [2]
                org.testng.Assert.fail(Assert.java:110)org.testng.Assert.failNotEquals(Assert.java:1577)org.testng.Assert.assertEqualsImpl(Assert.java:149)org.testng.Assert.assertEquals(Assert.java:131)org.testng.Assert.assertEquals(Assert.java:1418)org.testng.Assert.assertEquals(Assert.java:1382)org.testng.Assert.assertEquals(Assert.java:1428)FacturialTest.testFactorial(FacturialTest.java:110)java.base/jdk.internal.reflect.DirectMethodHandleAccessor.invoke(DirectMethodHandleAccessor.java:104)java.base/java.lang.reflect.Method.invoke(Method.java:578)org.testng.internal.invokers.MethodInvocationHelper.invokeMethod(MethodInvocationHelper.java:139)org.testng.internal.invokers.TestInvoker.invokeMethod(TestInvoker.java:677)org.testng.internal.invokers.TestInvoker.invokeTestMethod(TestInvoker.java:221)org.testng.internal.invokers.MethodRunner.runInSequence(MethodRunner.java:50)org.testng.internal.invokers.TestInvoker$MethodInvocationAgent.invoke(TestInvoker.java:969)org.testng.internal.invokers.TestInvoker.invokeTestMethods(TestInvoker.java:194)org.testng.internal.invokers.TestMethodWorker.invokeTestMethods(TestMethodWorker.java:148)org.testng.internal.invokers.TestMethodWorker.run(TestMethodWorker.java:128)java.base/java.util.ArrayList.forEach(ArrayList.java:1511)org.testng.TestRunner.privateRun(TestRunner.java:829)org.testng.TestRunner.run(TestRunner.java:602)org.testng.SuiteRunner.runTest(SuiteRunner.java:437)org.testng.SuiteRunner$SuiteWorker.run(SuiteRunner.java:475)org.testng.internal.thread.ThreadUtil.lambda$execute$0(ThreadUtil.java:58)java.base/java.util.concurrent.FutureTask.run(FutureTask.java:317)java.base/java.util.concurrent.ThreadPoolExecutor.runWorker(ThreadPoolExecutor.java:1144)java.base/java.util.concurrent.ThreadPoolExecutor$Worker.run(ThreadPoolExecutor.java:642)java.base/java.lang.Thread.run(Thread.java:1623)
]]>
            </failure>
    </testcase>
            <testcase
                name="testFactorial"
                time="0.001"
                classname="FacturialTest">

            <failure type="java.lang.AssertionError" message="expected [4] but found [2]">
                <![CDATA[java.lang.AssertionError: expected [4] but found [2]
                org.testng.Assert.fail(Assert.java:110)org.testng.Assert.failNotEquals(Assert.java:1577)org.testng.Assert.assertEqualsImpl(Assert.java:149)org.testng.Assert.assertEquals(Assert.java:131)org.testng.Assert.assertEquals(Assert.java:1418)org.testng.Assert.assertEquals(Assert.java:1382)org.testng.Assert.assertEquals(Assert.java:1428)FacturialTest.testFactorial(FacturialTest.java:110)java.base/jdk.internal.reflect.DirectMethodHandleAccessor.invoke(DirectMethodHandleAccessor.java:104)java.base/java.lang.reflect.Method.invoke(Method.java:578)org.testng.internal.invokers.MethodInvocationHelper.invokeMethod(MethodInvocationHelper.java:139)org.testng.internal.invokers.TestInvoker.invokeMethod(TestInvoker.java:677)org.testng.internal.invokers.TestInvoker.invokeTestMethod(TestInvoker.java:221)org.testng.internal.invokers.MethodRunner.runInSequence(MethodRunner.java:50)org.testng.internal.invokers.TestInvoker$MethodInvocationAgent.invoke(TestInvoker.java:969)org.testng.internal.invokers.TestInvoker.invokeTestMethods(TestInvoker.java:194)org.testng.internal.invokers.TestMethodWorker.invokeTestMethods(TestMethodWorker.java:148)org.testng.internal.invokers.TestMethodWorker.run(TestMethodWorker.java:128)java.base/java.util.ArrayList.forEach(ArrayList.java:1511)org.testng.TestRunner.privateRun(TestRunner.java:829)org.testng.TestRunner.run(TestRunner.java:602)org.testng.SuiteRunner.runTest(SuiteRunner.java:437)org.testng.SuiteRunner$SuiteWorker.run(SuiteRunner.java:475)org.testng.internal.thread.ThreadUtil.lambda$execute$0(ThreadUtil.java:58)java.base/java.util.concurrent.FutureTask.run(FutureTask.java:317)java.base/java.util.concurrent.ThreadPoolExecutor.runWorker(ThreadPoolExecutor.java:1144)java.base/java.util.concurrent.ThreadPoolExecutor$Worker.run(ThreadPoolExecutor.java:642)java.base/java.lang.Thread.run(Thread.java:1623)
]]>
            </failure>
    </testcase>
            <testcase
                name="testFactorial"
                time="0.001"
                classname="FacturialTest">

            <failure type="java.lang.AssertionError" message="expected [4] but found [2]">
                <![CDATA[java.lang.AssertionError: expected [4] but found [2]
                org.testng.Assert.fail(Assert.java:110)org.testng.Assert.failNotEquals(Assert.java:1577)org.testng.Assert.assertEqualsImpl(Assert.java:149)org.testng.Assert.assertEquals(Assert.java:131)org.testng.Assert.assertEquals(Assert.java:1418)org.testng.Assert.assertEquals(Assert.java:1382)org.testng.Assert.assertEquals(Assert.java:1428)FacturialTest.testFactorial(FacturialTest.java:110)java.base/jdk.internal.reflect.DirectMethodHandleAccessor.invoke(DirectMethodHandleAccessor.java:104)java.base/java.lang.reflect.Method.invoke(Method.java:578)org.testng.internal.invokers.MethodInvocationHelper.invokeMethod(MethodInvocationHelper.java:139)org.testng.internal.invokers.TestInvoker.invokeMethod(TestInvoker.java:677)org.testng.internal.invokers.TestInvoker.invokeTestMethod(TestInvoker.java:221)org.testng.internal.invokers.MethodRunner.runInSequence(MethodRunner.java:50)org.testng.internal.invokers.TestInvoker$MethodInvocationAgent.invoke(TestInvoker.java:969)org.testng.internal.invokers.TestInvoker.invokeTestMethods(TestInvoker.java:194)org.testng.internal.invokers.TestMethodWorker.invokeTestMethods(TestMethodWorker.java:148)org.testng.internal.invokers.TestMethodWorker.run(TestMethodWorker.java:128)java.base/java.util.ArrayList.forEach(ArrayList.java:1511)org.testng.TestRunner.privateRun(TestRunner.java:829)org.testng.TestRunner.run(TestRunner.java:602)org.testng.SuiteRunner.runTest(SuiteRunner.java:437)org.testng.SuiteRunner$SuiteWorker.run(SuiteRunner.java:475)org.testng.internal.thread.ThreadUtil.lambda$execute$0(ThreadUtil.java:58)java.base/java.util.concurrent.FutureTask.run(FutureTask.java:317)java.base/java.util.concurrent.ThreadPoolExecutor.runWorker(ThreadPoolExecutor.java:1144)java.base/java.util.concurrent.ThreadPoolExecutor$Worker.run(ThreadPoolExecutor.java:642)java.base/java.lang.Thread.run(Thread.java:1623)
]]>
            </failure>
    </testcase>
            <testcase
                name="testFactorial"
                time="0.001"
                classname="FacturialTest">

            <failure type="java.lang.AssertionError" message="expected [4] but found [2]">
                <![CDATA[java.lang.AssertionError: expected [4] but found [2]
                org.testng.Assert.fail(Assert.java:110)org.testng.Assert.failNotEquals(Assert.java:1577)org.testng.Assert.assertEqualsImpl(Assert.java:149)org.testng.Assert.assertEquals(Assert.java:131)org.testng.Assert.assertEquals(Assert.java:1418)org.testng.Assert.assertEquals(Assert.java:1382)org.testng.Assert.assertEquals(Assert.java:1428)FacturialTest.testFactorial(FacturialTest.java:110)java.base/jdk.internal.reflect.DirectMethodHandleAccessor.invoke(DirectMethodHandleAccessor.java:104)java.base/java.lang.reflect.Method.invoke(Method.java:578)org.testng.internal.invokers.MethodInvocationHelper.invokeMethod(MethodInvocationHelper.java:139)org.testng.internal.invokers.TestInvoker.invokeMethod(TestInvoker.java:677)org.testng.internal.invokers.TestInvoker.invokeTestMethod(TestInvoker.java:221)org.testng.internal.invokers.MethodRunner.runInSequence(MethodRunner.java:50)org.testng.internal.invokers.TestInvoker$MethodInvocationAgent.invoke(TestInvoker.java:969)org.testng.internal.invokers.TestInvoker.invokeTestMethods(TestInvoker.java:194)org.testng.internal.invokers.TestMethodWorker.invokeTestMethods(TestMethodWorker.java:148)org.testng.internal.invokers.TestMethodWorker.run(TestMethodWorker.java:128)java.base/java.util.ArrayList.forEach(ArrayList.java:1511)org.testng.TestRunner.privateRun(TestRunner.java:829)org.testng.TestRunner.run(TestRunner.java:602)org.testng.SuiteRunner.runTest(SuiteRunner.java:437)org.testng.SuiteRunner$SuiteWorker.run(SuiteRunner.java:475)org.testng.internal.thread.ThreadUtil.lambda$execute$0(ThreadUtil.java:58)java.base/java.util.concurrent.FutureTask.run(FutureTask.java:317)java.base/java.util.concurrent.ThreadPoolExecutor.runWorker(ThreadPoolExecutor.java:1144)java.base/java.util.concurrent.ThreadPoolExecutor$Worker.run(ThreadPoolExecutor.java:642)java.base/java.lang.Thread.run(Thread.java:1623)
]]>
            </failure>
    </testcase>
            <testcase
                name="testFactorial"
                time="0.001"
                classname="FacturialTest">

            <failure type="java.lang.AssertionError" message="expected [4] but found [2]">
                <![CDATA[java.lang.AssertionError: expected [4] but found [2]
                org.testng.Assert.fail(Assert.java:110)org.testng.Assert.failNotEquals(Assert.java:1577)org.testng.Assert.assertEqualsImpl(Assert.java:149)org.testng.Assert.assertEquals(Assert.java:131)org.testng.Assert.assertEquals(Assert.java:1418)org.testng.Assert.assertEquals(Assert.java:1382)org.testng.Assert.assertEquals(Assert.java:1428)FacturialTest.testFactorial(FacturialTest.java:110)java.base/jdk.internal.reflect.DirectMethodHandleAccessor.invoke(DirectMethodHandleAccessor.java:104)java.base/java.lang.reflect.Method.invoke(Method.java:578)org.testng.internal.invokers.MethodInvocationHelper.invokeMethod(MethodInvocationHelper.java:139)org.testng.internal.invokers.TestInvoker.invokeMethod(TestInvoker.java:677)org.testng.internal.invokers.TestInvoker.invokeTestMethod(TestInvoker.java:221)org.testng.internal.invokers.MethodRunner.runInSequence(MethodRunner.java:50)org.testng.internal.invokers.TestInvoker$MethodInvocationAgent.invoke(TestInvoker.java:969)org.testng.internal.invokers.TestInvoker.invokeTestMethods(TestInvoker.java:194)org.testng.internal.invokers.TestMethodWorker.invokeTestMethods(TestMethodWorker.java:148)org.testng.internal.invokers.TestMethodWorker.run(TestMethodWorker.java:128)java.base/java.util.ArrayList.forEach(ArrayList.java:1511)org.testng.TestRunner.privateRun(TestRunner.java:829)org.testng.TestRunner.run(TestRunner.java:602)org.testng.SuiteRunner.runTest(SuiteRunner.java:437)org.testng.SuiteRunner$SuiteWorker.run(SuiteRunner.java:475)org.testng.internal.thread.ThreadUtil.lambda$execute$0(ThreadUtil.java:58)java.base/java.util.concurrent.FutureTask.run(FutureTask.java:317)java.base/java.util.concurrent.ThreadPoolExecutor.runWorker(ThreadPoolExecutor.java:1144)java.base/java.util.concurrent.ThreadPoolExecutor$Worker.run(ThreadPoolExecutor.java:642)java.base/java.lang.Thread.run(Thread.java:1623)
]]>
            </failure>
    </testcase>
            <testcase
                name="testFactorial"
                time="0.001"
                classname="FacturialTest">

            <failure type="java.lang.AssertionError" message="expected [4] but found [2]">
                <![CDATA[java.lang.AssertionError: expected [4] but found [2]
                org.testng.Assert.fail(Assert.java:110)org.testng.Assert.failNotEquals(Assert.java:1577)org.testng.Assert.assertEqualsImpl(Assert.java:149)org.testng.Assert.assertEquals(Assert.java:131)org.testng.Assert.assertEquals(Assert.java:1418)org.testng.Assert.assertEquals(Assert.java:1382)org.testng.Assert.assertEquals(Assert.java:1428)FacturialTest.testFactorial(FacturialTest.java:110)java.base/jdk.internal.reflect.DirectMethodHandleAccessor.invoke(DirectMethodHandleAccessor.java:104)java.base/java.lang.reflect.Method.invoke(Method.java:578)org.testng.internal.invokers.MethodInvocationHelper.invokeMethod(MethodInvocationHelper.java:139)org.testng.internal.invokers.TestInvoker.invokeMethod(TestInvoker.java:677)org.testng.internal.invokers.TestInvoker.invokeTestMethod(TestInvoker.java:221)org.testng.internal.invokers.MethodRunner.runInSequence(MethodRunner.java:50)org.testng.internal.invokers.TestInvoker$MethodInvocationAgent.invoke(TestInvoker.java:969)org.testng.internal.invokers.TestInvoker.invokeTestMethods(TestInvoker.java:194)org.testng.internal.invokers.TestMethodWorker.invokeTestMethods(TestMethodWorker.java:148)org.testng.internal.invokers.TestMethodWorker.run(TestMethodWorker.java:128)java.base/java.util.ArrayList.forEach(ArrayList.java:1511)org.testng.TestRunner.privateRun(TestRunner.java:829)org.testng.TestRunner.run(TestRunner.java:602)org.testng.SuiteRunner.runTest(SuiteRunner.java:437)org.testng.SuiteRunner$SuiteWorker.run(SuiteRunner.java:475)org.testng.internal.thread.ThreadUtil.lambda$execute$0(ThreadUtil.java:58)java.base/java.util.concurrent.FutureTask.run(FutureTask.java:317)java.base/java.util.concurrent.ThreadPoolExecutor.runWorker(ThreadPoolExecutor.java:1144)java.base/java.util.concurrent.ThreadPoolExecutor$Worker.run(ThreadPoolExecutor.java:642)java.base/java.lang.Thread.run(Thread.java:1623)
]]>
            </failure>
    </testcase>
            <testcase
                name="testFactorial"
                time="0.001"
                classname="FacturialTest">

            <failure type="java.lang.AssertionError" message="expected [4] but found [2]">
                <![CDATA[java.lang.AssertionError: expected [4] but found [2]
                org.testng.Assert.fail(Assert.java:110)org.testng.Assert.failNotEquals(Assert.java:1577)org.testng.Assert.assertEqualsImpl(Assert.java:149)org.testng.Assert.assertEquals(Assert.java:131)org.testng.Assert.assertEquals(Assert.java:1418)org.testng.Assert.assertEquals(Assert.java:1382)org.testng.Assert.assertEquals(Assert.java:1428)FacturialTest.testFactorial(FacturialTest.java:110)java.base/jdk.internal.reflect.DirectMethodHandleAccessor.invoke(DirectMethodHandleAccessor.java:104)java.base/java.lang.reflect.Method.invoke(Method.java:578)org.testng.internal.invokers.MethodInvocationHelper.invokeMethod(MethodInvocationHelper.java:139)org.testng.internal.invokers.TestInvoker.invokeMethod(TestInvoker.java:677)org.testng.internal.invokers.TestInvoker.invokeTestMethod(TestInvoker.java:221)org.testng.internal.invokers.MethodRunner.runInSequence(MethodRunner.java:50)org.testng.internal.invokers.TestInvoker$MethodInvocationAgent.invoke(TestInvoker.java:969)org.testng.internal.invokers.TestInvoker.invokeTestMethods(TestInvoker.java:194)org.testng.internal.invokers.TestMethodWorker.invokeTestMethods(TestMethodWorker.java:148)org.testng.internal.invokers.TestMethodWorker.run(TestMethodWorker.java:128)java.base/java.util.ArrayList.forEach(ArrayList.java:1511)org.testng.TestRunner.privateRun(TestRunner.java:829)org.testng.TestRunner.run(TestRunner.java:602)org.testng.SuiteRunner.runTest(SuiteRunner.java:437)org.testng.SuiteRunner$SuiteWorker.run(SuiteRunner.java:475)org.testng.internal.thread.ThreadUtil.lambda$execute$0(ThreadUtil.java:58)java.base/java.util.concurrent.FutureTask.run(FutureTask.java:317)java.base/java.util.concurrent.ThreadPoolExecutor.runWorker(ThreadPoolExecutor.java:1144)java.base/java.util.concurrent.ThreadPoolExecutor$Worker.run(ThreadPoolExecutor.java:642)java.base/java.lang.Thread.run(Thread.java:1623)
]]>
            </failure>
    </testcase>


            <testcase
                name="testFactorial"
                time="0.012"
                classname="FacturialTest">
            </testcase>
            <testcase
                name="testFactorial"
                time="0.097"
                classname="FacturialTest">
            </testcase>
</testsuite>
